Workbook
Name PB: lists!$M$8:$M$11
Name PB_1: lists!$J$3:$J$5
Name PB_2: lists!$J$6:$J$7
Name PB_3: lists!$J$8:$J$10
Name PB_4: lists!$J$11:$J$13

Sheet Raw - F
C1: Date | D1: Course | E1: Code | F1: Jump Type | G1: Type | H1: M/N | J1: Age | K1: Sex | L1: Class | M1: PL | N1: RB | O1: Distance | P1: Distance Category | Q1: RaceValue | R1: Race name | T1: Region | U1: AWT | V1: Rider | W1: SC | X1: Auc | AA1: Age classification | AB1: Sex classification | AC1: Dist rank | AD1: HC inc | AE1: JT inc | AF1: Dist inc | AG1: Sex inc | AH1: Mdn/Nov | AI1: Month inc | AJ1: Class inc | AK1: Region include | AL1: INCLUDE?
A2: =IF(B2="",A1,B2+1) -> 2 | B2: =IF(AND(A1<1,AL2=1),1,IF(AL2=1,A1,"")) -> 1 | C2: 44317 | D2: DONCASTER | E2: Flat | F2: Flat | G2: Hcap | H2: Open | J2: 3yo+ | K2: A | L2: 2 | N2: 86-105 | O2: 6f2y | P2: 6f | Q2: 20000 | R2: DEFENCE HCAP STKS | T2: North | U2: 0 | AA2: =IF(OR(J2="2yo",J2="3yo"),J2,"Other") -> Other | AB2: =IF(K2="F",K2,"A") -> A | AC2: =VLOOKUP(P2,lists!$G:$H,2,FALSE) -> 2 | AD2: =VLOOKUP(G2,lists!$B$2:$C$3,2,FALSE) -> TRUE | AE2: =VLOOKUP(AA2,lists!$B:$C,2,FALSE) -> TRUE | AF2: =IF(AND(AC2>=VLOOKUP(FLAT!$I$1,lists!$G:$H,2,FALSE),AC2<=VLOOKUP(FLAT!$I$2,lists!$G:$H,2,FALSE)),TRUE,FALSE) -> TRUE | AG2: =VLOOKUP(AB2,lists!$B$7:$C$8,2,FALSE) -> TRUE | AH2: =VLOOKUP(IF(H2="","Open",SUBSTITUTE(H2,"/Nov","")),lists!$B$27:$D$29,2,FALSE) -> TRUE | AI2: =IF(FLAT!$I$5="All",TRUE,IF(FLAT!$I$5=TEXT('Raw - F'!C2,"mmm"),TRUE,FALSE)) -> TRUE | AJ2: =VLOOKUP(L2,lists!B:C,2,FALSE) -> TRUE | AK2: =VLOOKUP(T2,lists!$B$23:$D$25,2,FALSE) -> TRUE | AL2: =IF(AND(AD2=TRUE,AE2=TRUE,AF2=TRUE,AG2=TRUE,AH2=TRUE,AI2=TRUE,AJ2=TRUE,AK2=TRUE),1,0) -> 1
A3: =IF(B3="",A2,B3+1) -> 3 | B3: =IF(AND(A2<1,AL3=1),1,IF(AL3=1,A2,"")) -> 2 | C3: 44317 | D3: DONCASTER | E3: Flat | F3: Flat | G3: Hcap | H3: Open | J3: 4yo+ | K3: A | L3: 3 | N3: 71-90 | O3: 6f2y | P3: 6f | Q3: 12000 | R3: DEFENCE HCAP STKS | T3: North | U3: 0 | AA3: =IF(OR(J3="2yo",J3="3yo"),J3,"Other") -> Other | AB3: =IF(K3="F",K3,"A") -> A | AC3: =VLOOKUP(P3,lists!$G:$H,2,FALSE) -> 2 | AD3: =VLOOKUP(G3,lists!$B$2:$C$3,2,FALSE) -> TRUE | AE3: =VLOOKUP(AA3,lists!$B:$C,2,FALSE) -> TRUE | AF3: =IF(AND(AC3>=VLOOKUP(FLAT!$I$1,lists!$G:$H,2,FALSE),AC3<=VLOOKUP(FLAT!$I$2,lists!$G:$H,2,FALSE)),TRUE,FALSE) -> TRUE | AG3: =VLOOKUP(AB3,lists!$B$7:$C$8,2,FALSE) -> TRUE | AH3: =VLOOKUP(IF(H3="","Open",SUBSTITUTE(H3,"/Nov","")),lists!$B$27:$D$29,2,FALSE) -> TRUE | AI3: =IF(FLAT!$I$5="All",TRUE,IF(FLAT!$I$5=TEXT('Raw - F'!C3,"mmm"),TRUE,FALSE)) -> TRUE | AJ3: =VLOOKUP(L3,lists!B:C,2,FALSE) -> TRUE | AK3: =VLOOKUP(T3,lists!$B$23:$D$25,2,FALSE) -> TRUE | AL3: =IF(AND(AD3=TRUE,AE3=TRUE,AF3=TRUE,AG3=TRUE,AH3=TRUE,AI3=TRUE,AJ3=TRUE,AK3=TRUE),1,0) -> 1
A4: =IF(B4="",A3,B4+1) -> 4 | B4: =IF(AND(A3<1,AL4=1),1,IF(AL4=1,A3,"")) -> 3 | C4: 44317 | D4: DONCASTER | E4: Flat | F4: Flat | G4: Hcap | H4: Open | J4: 3yo | K4: A | L4: 3 | N4: 71-90 | O4: 1m | P4: 1m | Q4: 12000 | R4: SKY SPORTS HCAP STKS | T4: North | U4: 0 | AA4: =IF(OR(J4="2yo",J4="3yo"),J4,"Other") -> 3yo | AB4: =IF(K4="F",K4,"A") -> A | AC4: =VLOOKUP(P4,lists!$G:$H,2,FALSE) -> 4 | AD4: =VLOOKUP(G4,lists!$B$2:$C$3,2,FALSE) -> TRUE | AE4: =VLOOKUP(AA4,lists!$B:$C,2,FALSE) -> TRUE | AF4: =IF(AND(AC4>=VLOOKUP(FLAT!$I$1,lists!$G:$H,2,FALSE),AC4<=VLOOKUP(FLAT!$I$2,lists!$G:$H,2,FALSE)),TRUE,FALSE) -> TRUE | AG4: =VLOOKUP(AB4,lists!$B$7:$C$8,2,FALSE) -> TRUE | AH4: =VLOOKUP(IF(H4="","Open",SUBSTITUTE(H4,"/Nov","")),lists!$B$27:$D$29,2,FALSE) -> TRUE | AI4: =IF(FLAT!$I$5="All",TRUE,IF(FLAT!$I$5=TEXT('Raw - F'!C4,"mmm"),TRUE,FALSE)) -> TRUE | AJ4: =VLOOKUP(L4,lists!B:C,2,FALSE) -> TRUE | AK4: =VLOOKUP(T4,lists!$B$23:$D$25,2,FALSE) -> TRUE | AL4: =IF(AND(AD4=TRUE,AE4=TRUE,AF4=TRUE,AG4=TRUE,AH4=TRUE,AI4=TRUE,AJ4=TRUE,AK4=TRUE),1,0) -> 1
A5: =IF(B5="",A4,B5+1) -> 5 | B5: =IF(AND(A4<1,AL5=1),1,IF(AL5=1,A4,"")) -> 4 | C5: 44317 | D5: DONCASTER | E5: Flat | F5: Flat | G5: Hcap | H5: Open | J5: 3yo+ | K5: F | L5: 4 | N5: 66-85 | O5: 1m3f197y | P5: 1m 4f | Q5: 7650 | R5: WATCH SKY HCAP STKS | T5: North | U5: 0 | AA5: =IF(OR(J5="2yo",J5="3yo"),J5,"Other") -> Other | AB5: =IF(K5="F",K5,"A") -> F | AC5: =VLOOKUP(P5,lists!$G:$H,2,FALSE) -> 7 | AD5: =VLOOKUP(G5,lists!$B$2:$C$3,2,FALSE) -> TRUE | AE5: =VLOOKUP(AA5,lists!$B:$C,2,FALSE) -> TRUE | AF5: =IF(AND(AC5>=VLOOKUP(FLAT!$I$1,lists!$G:$H,2,FALSE),AC5<=VLOOKUP(FLAT!$I$2,lists!$G:$H,2,FALSE)),TRUE,FALSE) -> TRUE | AG5: =VLOOKUP(AB5,lists!$B$7:$C$8,2,FALSE) -> TRUE | AH5: =VLOOKUP(IF(H5="","Open",SUBSTITUTE(H5,"/Nov","")),lists!$B$27:$D$29,2,FALSE) -> TRUE | AI5: =IF(FLAT!$I$5="All",TRUE,IF(FLAT!$I$5=TEXT('Raw - F'!C5,"mmm"),TRUE,FALSE)) -> TRUE | AJ5: =VLOOKUP(L5,lists!B:C,2,FALSE) -> TRUE | AK5: =VLOOKUP(T5,lists!$B$23:$D$25,2,FALSE) -> TRUE | AL5: =IF(AND(AD5=TRUE,AE5=TRUE,AF5=TRUE,AG5=TRUE,AH5=TRUE,AI5=TRUE,AJ5=TRUE,AK5=TRUE),1,0) -> 1
A6: =IF(B6="",A5,B6+1) -> 6 | B6: =IF(AND(A5<1,AL6=1),1,IF(AL6=1,A5,"")) -> 5 | C6: 44317 | D6: DONCASTER | E6: Flat | F6: Flat | G6: Hcap | H6: Open | J6: 4yo+ | K6: A | L6: 4 | N6: 66-85 | O6: 2m | P6: 2m+ | Q6: 7650 | R6: DMRC HCAP STKS | S6: C | T6: North | U6: 0 | AA6: =IF(OR(J6="2yo",J6="3yo"),J6,"Other") -> Other | AB6: =IF(K6="F",K6,"A") -> A | AC6: =VLOOKUP(P6,lists!$G:$H,2,FALSE) -> 11 | AD6: =VLOOKUP(G6,lists!$B$2:$C$3,2,FALSE) -> TRUE | AE6: =VLOOKUP(AA6,lists!$B:$C,2,FALSE) -> TRUE | AF6: =IF(AND(AC6>=VLOOKUP(FLAT!$I$1,lists!$G:$H,2,FALSE),AC6<=VLOOKUP(FLAT!$I$2,lists!$G:$H,2,FALSE)),TRUE,FALSE) -> TRUE | AG6: =VLOOKUP(AB6,lists!$B$7:$C$8,2,FALSE) -> TRUE | AH6: =VLOOKUP(IF(H6="","Open",SUBSTITUTE(H6,"/Nov","")),lists!$B$27:$D$29,2,FALSE) -> TRUE | AI6: =IF(FLAT!$I$5="All",TRUE,IF(FLAT!$I$5=TEXT('Raw - F'!C6,"mmm"),TRUE,FALSE)) -> TRUE | AJ6: =VLOOKUP(L6,lists!B:C,2,FALSE) -> TRUE | AK6: =VLOOKUP(T6,lists!$B$23:$D$25,2,FALSE) -> TRUE | AL6: =IF(AND(AD6=TRUE,AE6=TRUE,AF6=TRUE,AG6=TRUE,AH6=TRUE,AI6=TRUE,AJ6=TRUE,AK6=TRUE),1,0) -> 1
A7: =IF(B7="",A6,B7+1) -> 7 | B7: =IF(AND(A6<1,AL7=1),1,IF(AL7=1,A6,"")) -> 6 | C7: 44317 | D7: DONCASTER | E7: Flat | F7: Flat | G7: WFA | H7: Mdn | J7: 2yo | K7: A | L7: 5 | N7: Open | O7: 5f3y | P7: 5f | Q7: 5400 | R7: DMRC EBF NOV STKS | S7: C | T7: North | U7: 0 | Z7: EBF | AA7: =IF(OR(J7="2yo",J7="3yo"),J7,"Other") -> 2yo | AB7: =IF(K7="F",K7,"A") -> A | AC7: =VLOOKUP(P7,lists!$G:$H,2,FALSE) -> 1 | AD7: =VLOOKUP(G7,lists!$B$2:$C$3,2,FALSE) -> TRUE | AE7: =VLOOKUP(AA7,lists!$B:$C,2,FALSE) -> TRUE | AF7: =IF(AND(AC7>=VLOOKUP(FLAT!$I$1,lists!$G:$H,2,FALSE),AC7<=VLOOKUP(FLAT!$I$2,lists!$G:$H,2,FALSE)),TRUE,FALSE) -> TRUE | AG7: =VLOOKUP(AB7,lists!$B$7:$C$8,2,FALSE) -> TRUE | AH7: =VLOOKUP(IF(H7="","Open",SUBSTITUTE(H7,"/Nov","")),lists!$B$27:$D$29,2,FALSE) -> TRUE | AI7: =IF(FLAT!$I$5="All",TRUE,IF(FLAT!$I$5=TEXT('Raw - F'!C7,"mmm"),TRUE,FALSE)) -> TRUE | AJ7: =VLOOKUP(L7,lists!B:C,2,FALSE) -> TRUE | AK7: =VLOOKUP(T7,lists!$B$23:$D$25,2,FALSE) -> TRUE | AL7: =IF(AND(AD7=TRUE,AE7=TRUE,AF7=TRUE,AG7=TRUE,AH7=TRUE,AI7=TRUE,AJ7=TRUE,AK7=TRUE),1,0) -> 1
A8: =IF(B8="",A7,B8+1) -> 8 | B8: =IF(AND(A7<1,AL8=1),1,IF(AL8=1,A7,"")) -> 7 | C8: 44317 | D8: DONCASTER | E8: Flat | F8: Flat | G8: WFA | H8: Nov | J8: 3yo+ | K8: A | L8: 5 | N8: Open | O8: 6f2y | P8: 6f | Q8: 4900 | R8: DEFENCE NOV STKS | T8: North | U8: 0 | AA8: =IF(OR(J8="2yo",J8="3yo"),J8,"Other") -> Other | AB8: =IF(K8="F",K8,"A") -> A | AC8: =VLOOKUP(P8,lists!$G:$H,2,FALSE) -> 2 | AD8: =VLOOKUP(G8,lists!$B$2:$C$3,2,FALSE) -> TRUE | AE8: =VLOOKUP(AA8,lists!$B:$C,2,FALSE) -> TRUE | AF8: =IF(AND(AC8>=VLOOKUP(FLAT!$I$1,lists!$G:$H,2,FALSE),AC8<=VLOOKUP(FLAT!$I$2,lists!$G:$H,2,FALSE)),TRUE,FALSE) -> TRUE | AG8: =VLOOKUP(AB8,lists!$B$7:$C$8,2,FALSE) -> TRUE | AH8: =VLOOKUP(IF(H8="","Open",SUBSTITUTE(H8,"/Nov","")),lists!$B$27:$D$29,2,FALSE) -> TRUE | AI8: =IF(FLAT!$I$5="All",TRUE,IF(FLAT!$I$5=TEXT('Raw - F'!C8,"mmm"),TRUE,FALSE)) -> TRUE | AJ8: =VLOOKUP(L8,lists!B:C,2,FALSE) -> TRUE | AK8: =VLOOKUP(T8,lists!$B$23:$D$25,2,FALSE) -> TRUE | AL8: =IF(AND(AD8=TRUE,AE8=TRUE,AF8=TRUE,AG8=TRUE,AH8=TRUE,AI8=TRUE,AJ8=TRUE,AK8=TRUE),1,0) -> 1
A9: =IF(B9="",A8,B9+1) -> 9 | B9: =IF(AND(A8<1,AL9=1),1,IF(AL9=1,A8,"")) -> 8 | C9: 44317 | D9: GOODWOOD | E9: Flat | F9: Flat | G9: WFA | H9: Open | J9: 3yo+ | K9: F | L9: 1 | M9: 1(Lstd) | N9: Open | O9: 1m | P9: 1m | Q9: 50000 | R9: CONQUEROR STKS | T9: South | U9: 0 | AA9: =IF(OR(J9="2yo",J9="3yo"),J9,"Other") -> Other | AB9: =IF(K9="F",K9,"A") -> F | AC9: =VLOOKUP(P9,lists!$G:$H,2,FALSE) -> 4 | AD9: =VLOOKUP(G9,lists!$B$2:$C$3,2,FALSE) -> TRUE | AE9: =VLOOKUP(AA9,lists!$B:$C,2,FALSE) -> TRUE | AF9: =IF(AND(AC9>=VLOOKUP(FLAT!$I$1,lists!$G:$H,2,FALSE),AC9<=VLOOKUP(FLAT!$I$2,lists!$G:$H,2,FALSE)),TRUE,FALSE) -> TRUE | AG9: =VLOOKUP(AB9,lists!$B$7:$C$8,2,FALSE) -> TRUE | AH9: =VLOOKUP(IF(H9="","Open",SUBSTITUTE(H9,"/Nov","")),lists!$B$27:$D$29,2,FALSE) -> TRUE | AI9: =IF(FLAT!$I$5="All",TRUE,IF(FLAT!$I$5=TEXT('Raw - F'!C9,"mmm"),TRUE,FALSE)) -> TRUE | AJ9: =VLOOKUP(L9,lists!B:C,2,FALSE) -> TRUE | AK9: =VLOOKUP(T9,lists!$B$23:$D$25,2,FALSE) -> TRUE | AL9: =IF(AND(AD9=TRUE,AE9=TRUE,AF9=TRUE,AG9=TRUE,AH9=TRUE,AI9=TRUE,AJ9=TRUE,AK9=TRUE),1,0) -> 1
A10: =IF(B10="",A9,B10+1) -> 10 | B10: =IF(AND(A9<1,AL10=1),1,IF(AL10=1,A9,"")) -> 9 | C10: 44317 | D10: GOODWOOD | E10: Flat | F10: Flat | G10: Hcap | H10: Open | J10: 4yo+ | K10: A | L10: 2 | N10: 81-100 | O10: 7f | P10: 7f | Q10: 50000 | R10: SINGLETON HCAP STKS | T10: South | U10: 0 | AA10: =IF(OR(J10="2yo",J10="3yo"),J10,"Other") -> Other | AB10: =IF(K10="F",K10,"A") -> A | AC10: =VLOOKUP(P10,lists!$G:$H,2,FALSE) -> 3 | AD10: =VLOOKUP(G10,lists!$B$2:$C$3,2,FALSE) -> TRUE | AE10: =VLOOKUP(AA10,lists!$B:$C,2,FALSE) -> TRUE | AF10: =IF(AND(AC10>=VLOOKUP(FLAT!$I$1,lists!$G:$H,2,FALSE),AC10<=VLOOKUP(FLAT!$I$2,lists!$G:$H,2,FALSE)),TRUE,FALSE) -> TRUE | AG10: =VLOOKUP(AB10,lists!$B$7:$C$8,2,FALSE) -> TRUE | AH10: =VLOOKUP(IF(H10="","Open",SUBSTITUTE(H10,"/Nov","")),lists!$B$27:$D$29,2,FALSE) -> TRUE | AI10: =IF(FLAT!$I$5="All",TRUE,IF(FLAT!$I$5=TEXT('Raw - F'!C10,"mmm"),TRUE,FALSE)) -> TRUE | AJ10: =VLOOKUP(L10,lists!B:C,2,FALSE) -> TRUE | AK10: =VLOOKUP(T10,lists!$B$23:$D$25,2,FALSE) -> TRUE | AL10: =IF(AND(AD10=TRUE,AE10=TRUE,AF10=TRUE,AG10=TRUE,AH10=TRUE,AI10=TRUE,AJ10=TRUE,AK10=TRUE),1,0) -> 1
A11: =IF(B11="",A10,B11+1) -> 11 | B11: =IF(AND(A10<1,AL11=1),1,IF(AL11=1,A10,"")) -> 10 | C11: 44317 | D11: GOODWOOD | E11: Flat | F11: Flat | G11: Hcap | H11: Open | J11: 4yo+ | K11: A | L11: 2 | N11: 81-100 | O11: 5f | P11: 5f | Q11: 15000 | R11: FARMER HCAP STKS | T11: South | U11: 0 | AA11: =IF(OR(J11="2yo",J11="3yo"),J11,"Other") -> Other | AB11: =IF(K11="F",K11,"A") -> A | AC11: =VLOOKUP(P11,lists!$G:$H,2,FALSE) -> 1 | AD11: =VLOOKUP(G11,lists!$B$2:$C$3,2,FALSE) -> TRUE | AE11: =VLOOKUP(AA11,lists!$B:$C,2,FALSE) -> TRUE | AF11: =IF(AND(AC11>=VLOOKUP(FLAT!$I$1,lists!$G:$H,2,FALSE),AC11<=VLOOKUP(FLAT!$I$2,lists!$G:$H,2,FALSE)),TRUE,FALSE) -> TRUE | AG11: =VLOOKUP(AB11,lists!$B$7:$C$8,2,FALSE) -> TRUE | AH11: =VLOOKUP(IF(H11="","Open",SUBSTITUTE(H11,"/Nov","")),lists!$B$27:$D$29,2,FALSE) -> TRUE | AI11: =IF(FLAT!$I$5="All",TRUE,IF(FLAT!$I$5=TEXT('Raw - F'!C11,"mmm"),TRUE,FALSE)) -> TRUE | AJ11: =VLOOKUP(L11,lists!B:C,2,FALSE) -> TRUE | AK11: =VLOOKUP(T11,lists!$B$23:$D$25,2,FALSE) -> TRUE | AL11: =IF(AND(AD11=TRUE,AE11=TRUE,AF11=TRUE,AG11=TRUE,AH11=TRUE,AI11=TRUE,AJ11=TRUE,AK11=TRUE),1,0) -> 1
A12: =IF(B12="",A11,B12+1) -> 12 | B12: =IF(AND(A11<1,AL12=1),1,IF(AL12=1,A11,"")) -> 11 | C12: 44317 | D12: GOODWOOD | E12: Flat | F12: Flat | G12: Hcap | H12: Open | J12: 3yo | K12: A | L12: 3 | N12: 71-90 | O12: 7f | P12: 7f | Q12: 11500 | R12: MATERIALS HCAP STKS | T12: South | U12: 0 | AA12: =IF(OR(J12="2yo",J12="3yo"),J12,"Other") -> 3yo | AB12: =IF(K12="F",K12,"A") -> A | AC12: =VLOOKUP(P12,lists!$G:$H,2,FALSE) -> 3 | AD12: =VLOOKUP(G12,lists!$B$2:$C$3,2,FALSE) -> TRUE | AE12: =VLOOKUP(AA12,lists!$B:$C,2,FALSE) -> TRUE | AF12: =IF(AND(AC12>=VLOOKUP(FLAT!$I$1,lists!$G:$H,2,FALSE),AC12<=VLOOKUP(FLAT!$I$2,lists!$G:$H,2,FALSE)),TRUE,FALSE) -> TRUE | AG12: =VLOOKUP(AB12,lists!$B$7:$C$8,2,FALSE) -> TRUE | AH12: =VLOOKUP(IF(H12="","Open",SUBSTITUTE(H12,"/Nov","")),lists!$B$27:$D$29,2,FALSE) -> TRUE | AI12: =IF(FLAT!$I$5="All",TRUE,IF(FLAT!$I$5=TEXT('Raw - F'!C12,"mmm"),TRUE,FALSE)) -> TRUE | AJ12: =VLOOKUP(L12,lists!B:C,2,FALSE) -> TRUE | AK12: =VLOOKUP(T12,lists!$B$23:$D$25,2,FALSE) -> TRUE | AL12: =IF(AND(AD12=TRUE,AE12=TRUE,AF12=TRUE,AG12=TRUE,AH12=TRUE,AI12=TRUE,AJ12=TRUE,AK12=TRUE),1,0) -> 1
A13: =IF(B13="",A12,B13+1) -> 13 | B13: =IF(AND(A12<1,AL13=1),1,IF(AL13=1,A12,"")) -> 12 | C13: 44317 | D13: GOODWOOD | E13: Flat | F13: Flat | G13: WFA | H13: Mdn | J13: 3yo+ | K13: A | L13: 4 | N13: Open | O13: 1m | P13: 1m | Q13: 8000 | R13: ROOF GARDEN MDN STKS | T13: South | U13: 0 | AA13: =IF(OR(J13="2yo",J13="3yo"),J13,"Other") -> Other | AB13: =IF(K13="F",K13,"A") -> A | AC13: =VLOOKUP(P13,lists!$G:$H,2,FALSE) -> 4 | AD13: =VLOOKUP(G13,lists!$B$2:$C$3,2,FALSE) -> TRUE | AE13: =VLOOKUP(AA13,lists!$B:$C,2,FALSE) -> TRUE | AF13: =IF(AND(AC13>=VLOOKUP(FLAT!$I$1,lists!$G:$H,2,FALSE),AC13<=VLOOKUP(FLAT!$I$2,lists!$G:$H,2,FALSE)),TRUE,FALSE) -> TRUE | AG13: =VLOOKUP(AB13,lists!$B$7:$C$8,2,FALSE) -> TRUE | AH13: =VLOOKUP(IF(H13="","Open",SUBSTITUTE(H13,"/Nov","")),lists!$B$27:$D$29,2,FALSE) -> TRUE | AI13: =IF(FLAT!$I$5="All",TRUE,IF(FLAT!$I$5=TEXT('Raw - F'!C13,"mmm"),TRUE,FALSE)) -> TRUE | AJ13: =VLOOKUP(L13,lists!B:C,2,FALSE) -> TRUE | AK13: =VLOOKUP(T13,lists!$B$23:$D$25,2,FALSE) -> TRUE | AL13: =IF(AND(AD13=TRUE,AE13=TRUE,AF13=TRUE,AG13=TRUE,AH13=TRUE,AI13=TRUE,AJ13=TRUE,AK13=TRUE),1,0) -> 1
A14: =IF(B14="",A13,B14+1) -> 14 | B14: =IF(AND(A13<1,AL14=1),1,IF(AL14=1,A13,"")) -> 13 | C14: 44317 | D14: GOODWOOD | E14: Flat | F14: Flat | G14: Hcap | H14: Open | J14: 3yo | K14: A | L14: 5 | N14: 51-70 | O14: 1m1f197y | P14: 1m 2f | Q14: 8000 | R14: LONG VIEW HCAP STKS | T14: South | U14: 0 | AA14: =IF(OR(J14="2yo",J14="3yo"),J14,"Other") -> 3yo | AB14: =IF(K14="F",K14,"A") -> A | AC14: =VLOOKUP(P14,lists!$G:$H,2,FALSE) -> 5 | AD14: =VLOOKUP(G14,lists!$B$2:$C$3,2,FALSE) -> TRUE | AE14: =VLOOKUP(AA14,lists!$B:$C,2,FALSE) -> TRUE | AF14: =IF(AND(AC14>=VLOOKUP(FLAT!$I$1,lists!$G:$H,2,FALSE),AC14<=VLOOKUP(FLAT!$I$2,lists!$G:$H,2,FALSE)),TRUE,FALSE) -> TRUE | AG14: =VLOOKUP(AB14,lists!$B$7:$C$8,2,FALSE) -> TRUE | AH14: =VLOOKUP(IF(H14="","Open",SUBSTITUTE(H14,"/Nov","")),lists!$B$27:$D$29,2,FALSE) -> TRUE | AI14: =IF(FLAT!$I$5="All",TRUE,IF(FLAT!$I$5=TEXT('Raw - F'!C14,"mmm"),TRUE,FALSE)) -> TRUE | AJ14: =VLOOKUP(L14,lists!B:C,2,FALSE) -> TRUE | AK14: =VLOOKUP(T14,lists!$B$23:$D$25,2,FALSE) -> TRUE | AL14: =IF(AND(AD14=TRUE,AE14=TRUE,AF14=TRUE,AG14=TRUE,AH14=TRUE,AI14=TRUE,AJ14=TRUE,AK14=TRUE),1,0) -> 1
A15: =IF(B15="",A14,B15+1) -> 15 | B15: =IF(AND(A14<1,AL15=1),1,IF(AL15=1,A14,"")) -> 14 | C15: 44317 | D15: GOODWOOD | E15: Flat | F15: Flat | G15: Hcap | H15: Open | J15: 4yo+ | K15: A | L15: 5 | N15: 56-75 | O15: 1m6f | P15: 2m+ | Q15: 8000 | R15: DOUBLE TRIGGER HCAP | T15: South | U15: 0 | AA15: =IF(OR(J15="2yo",J15="3yo"),J15,"Other") -> Other | AB15: =IF(K15="F",K15,"A") -> A | AC15: =VLOOKUP(P15,lists!$G:$H,2,FALSE) -> 11 | AD15: =VLOOKUP(G15,lists!$B$2:$C$3,2,FALSE) -> TRUE | AE15: =VLOOKUP(AA15,lists!$B:$C,2,FALSE) -> TRUE | AF15: =IF(AND(AC15>=VLOOKUP(FLAT!$I$1,lists!$G:$H,2,FALSE),AC15<=VLOOKUP(FLAT!$I$2,lists!$G:$H,2,FALSE)),TRUE,FALSE) -> TRUE | AG15: =VLOOKUP(AB15,lists!$B$7:$C$8,2,FALSE) -> TRUE | AH15: =VLOOKUP(IF(H15="","Open",SUBSTITUTE(H15,"/Nov","")),lists!$B$27:$D$29,2,FALSE) -> TRUE | AI15: =IF(FLAT!$I$5="All",TRUE,IF(FLAT!$I$5=TEXT('Raw - F'!C15,"mmm"),TRUE,FALSE)) -> TRUE | AJ15: =VLOOKUP(L15,lists!B:C,2,FALSE) -> TRUE | AK15: =VLOOKUP(T15,lists!$B$23:$D$25,2,FALSE) -> TRUE | AL15: =IF(AND(AD15=TRUE,AE15=TRUE,AF15=TRUE,AG15=TRUE,AH15=TRUE,AI15=TRUE,AJ15=TRUE,AK15=TRUE),1,0) -> 1
A16: =IF(B16="",A15,B16+1) -> 16 | B16: =IF(AND(A15<1,AL16=1),1,IF(AL16=1,A15,"")) -> 15 | C16: 44317 | D16: NEWMARKET | E16: Flat | F16: Flat | G16: WFA | H16: Open | J16: 3yo | K16: C | L16: 1 | M16: 1(G1) | N16: Open | O16: 1m | P16: 1m | Q16: 375000 | R16: 2000 GUINEAS STKS | T16: Midlands | U16: 0 | AA16: =IF(OR(J16="2yo",J16="3yo"),J16,"Other") -> 3yo | AB16: =IF(K16="F",K16,"A") -> A | AC16: =VLOOKUP(P16,lists!$G:$H,2,FALSE) -> 4 | AD16: =VLOOKUP(G16,lists!$B$2:$C$3,2,FALSE) -> TRUE | AE16: =VLOOKUP(AA16,lists!$B:$C,2,FALSE) -> TRUE | AF16: =IF(AND(AC16>=VLOOKUP(FLAT!$I$1,lists!$G:$H,2,FALSE),AC16<=VLOOKUP(FLAT!$I$2,lists!$G:$H,2,FALSE)),TRUE,FALSE) -> TRUE | AG16: =VLOOKUP(AB16,lists!$B$7:$C$8,2,FALSE) -> TRUE | AH16: =VLOOKUP(IF(H16="","Open",SUBSTITUTE(H16,"/Nov","")),lists!$B$27:$D$29,2,FALSE) -> TRUE | AI16: =IF(FLAT!$I$5="All",TRUE,IF(FLAT!$I$5=TEXT('Raw - F'!C16,"mmm"),TRUE,FALSE)) -> TRUE | AJ16: =VLOOKUP(L16,lists!B:C,2,FALSE) -> TRUE | AK16: =VLOOKUP(T16,lists!$B$23:$D$25,2,FALSE) -> TRUE | AL16: =IF(AND(AD16=TRUE,AE16=TRUE,AF16=TRUE,AG16=TRUE,AH16=TRUE,AI16=TRUE,AJ16=TRUE,AK16=TRUE),1,0) -> 1
A17: =IF(B17="",A16,B17+1) -> 17 | B17: =IF(AND(A16<1,AL17=1),1,IF(AL17=1,A16,"")) -> 16 | C17: 44317 | D17: NEWMARKET | E17: Flat | F17: Flat | G17: WFA | H17: Open | J17: 4yo+ | K17: A | L17: 1 | M17: 1(G2) | N17: Open | O17: 1m4f | P17: 1m 4f | Q17: 75000 | R17: JOCKEY CLUB STKS | T17: Midlands | U17: 0 | AA17: =IF(OR(J17="2yo",J17="3yo"),J17,"Other") -> Other | AB17: =IF(K17="F",K17,"A") -> A | AC17: =VLOOKUP(P17,lists!$G:$H,2,FALSE) -> 7 | AD17: =VLOOKUP(G17,lists!$B$2:$C$3,2,FALSE) -> TRUE | AE17: =VLOOKUP(AA17,lists!$B:$C,2,FALSE) -> TRUE | AF17: =IF(AND(AC17>=VLOOKUP(FLAT!$I$1,lists!$G:$H,2,FALSE),AC17<=VLOOKUP(FLAT!$I$2,lists!$G:$H,2,FALSE)),TRUE,FALSE) -> TRUE | AG17: =VLOOKUP(AB17,lists!$B$7:$C$8,2,FALSE) -> TRUE | AH17: =VLOOKUP(IF(H17="","Open",SUBSTITUTE(H17,"/Nov","")),lists!$B$27:$D$29,2,FALSE) -> TRUE | AI17: =IF(FLAT!$I$5="All",TRUE,IF(FLAT!$I$5=TEXT('Raw - F'!C17,"mmm"),TRUE,FALSE)) -> TRUE | AJ17: =VLOOKUP(L17,lists!B:C,2,FALSE) -> TRUE | AK17: =VLOOKUP(T17,lists!$B$23:$D$25,2,FALSE) -> TRUE | AL17: =IF(AND(AD17=TRUE,AE17=TRUE,AF17=TRUE,AG17=TRUE,AH17=TRUE,AI17=TRUE,AJ17=TRUE,AK17=TRUE),1,0) -> 1
A18: =IF(B18="",A17,B18+1) -> 18 | B18: =IF(AND(A17<1,AL18=1),1,IF(AL18=1,A17,"")) -> 17 | C18: 44317 | D18: NEWMARKET | E18: Flat | F18: Flat | G18: WFA | H18: Open | J18: 3yo+ | K18: A | L18: 1 | M18: 1(G3) | N18: Open | O18: 5f | P18: 5f | Q18: 60000 | R18: PALACE HOUSE STKS | T18: Midlands | U18: 0 | AA18: =IF(OR(J18="2yo",J18="3yo"),J18,"Other") -> Other | AB18: =IF(K18="F",K18,"A") -> A | AC18: =VLOOKUP(P18,lists!$G:$H,2,FALSE) -> 1 | AD18: =VLOOKUP(G18,lists!$B$2:$C$3,2,FALSE) -> TRUE | AE18: =VLOOKUP(AA18,lists!$B:$C,2,FALSE) -> TRUE | AF18: =IF(AND(AC18>=VLOOKUP(FLAT!$I$1,lists!$G:$H,2,FALSE),AC18<=VLOOKUP(FLAT!$I$2,lists!$G:$H,2,FALSE)),TRUE,FALSE) -> TRUE | AG18: =VLOOKUP(AB18,lists!$B$7:$C$8,2,FALSE) -> TRUE | AH18: =VLOOKUP(IF(H18="","Open",SUBSTITUTE(H18,"/Nov","")),lists!$B$27:$D$29,2,FALSE) -> TRUE | AI18: =IF(FLAT!$I$5="All",TRUE,IF(FLAT!$I$5=TEXT('Raw - F'!C18,"mmm"),TRUE,FALSE)) -> TRUE | AJ18: =VLOOKUP(L18,lists!B:C,2,FALSE) -> TRUE | AK18: =VLOOKUP(T18,lists!$B$23:$D$25,2,FALSE) -> TRUE | AL18: =IF(AND(AD18=TRUE,AE18=TRUE,AF18=TRUE,AG18=TRUE,AH18=TRUE,AI18=TRUE,AJ18=TRUE,AK18=TRUE),1,0) -> 1
A19: =IF(B19="",A18,B19+1) -> 19 | B19: =IF(AND(A18<1,AL19=1),1,IF(AL19=1,A18,"")) -> 18 | C19: 44317 | D19: NEWMARKET | E19: Flat | F19: Flat | G19: WFA | H19: Open | J19: 3yo | K19: C | L19: 1 | M19: 1(Lstd) | N19: Open | O19: 1m2f | P19: 1m 2f | Q19: 50000 | R19: NEWMARKET STKS | T19: Midlands | U19: 0 | AA19: =IF(OR(J19="2yo",J19="3yo"),J19,"Other") -> 3yo | AB19: =IF(K19="F",K19,"A") -> A | AC19: =VLOOKUP(P19,lists!$G:$H,2,FALSE) -> 5 | AD19: =VLOOKUP(G19,lists!$B$2:$C$3,2,FALSE) -> TRUE | AE19: =VLOOKUP(AA19,lists!$B:$C,2,FALSE) -> TRUE | AF19: =IF(AND(AC19>=VLOOKUP(FLAT!$I$1,lists!$G:$H,2,FALSE),AC19<=VLOOKUP(FLAT!$I$2,lists!$G:$H,2,FALSE)),TRUE,FALSE) -> TRUE | AG19: =VLOOKUP(AB19,lists!$B$7:$C$8,2,FALSE) -> TRUE | AH19: =VLOOKUP(IF(H19="","Open",SUBSTITUTE(H19,"/Nov","")),lists!$B$27:$D$29,2,FALSE) -> TRUE | AI19: =IF(FLAT!$I$5="All",TRUE,IF(FLAT!$I$5=TEXT('Raw - F'!C19,"mmm"),TRUE,FALSE)) -> TRUE | AJ19: =VLOOKUP(L19,lists!B:C,2,FALSE) -> TRUE | AK19: =VLOOKUP(T19,lists!$B$23:$D$25,2,FALSE) -> TRUE | AL19: =IF(AND(AD19=TRUE,AE19=TRUE,AF19=TRUE,AG19=TRUE,AH19=TRUE,AI19=TRUE,AJ19=TRUE,AK19=TRUE),1,0) -> 1
A20: =IF(B20="",A19,B20+1) -> 20 | B20: =IF(AND(A19<1,AL20=1),1,IF(AL20=1,A19,"")) -> 19 | C20: 44317 | D20: NEWMARKET | E20: Flat | F20: Flat | G20: Hcap | H20: Open | J20: 3yo+ | K20: A | L20: 2 | N20: Open | O20: 1m1f | P20: 1m 1f | Q20: 50000 | R20: SUFFOLK HCAP STKS | T20: Midlands | U20: 0 | AA20: =IF(OR(J20="2yo",J20="3yo"),J20,"Other") -> Other | AB20: =IF(K20="F",K20,"A") -> A | AC20: =VLOOKUP(P20,lists!$G:$H,2,FALSE) -> 5 | AD20: =VLOOKUP(G20,lists!$B$2:$C$3,2,FALSE) -> TRUE | AE20: =VLOOKUP(AA20,lists!$B:$C,2,FALSE) -> TRUE | AF20: =IF(AND(AC20>=VLOOKUP(FLAT!$I$1,lists!$G:$H,2,FALSE),AC20<=VLOOKUP(FLAT!$I$2,lists!$G:$H,2,FALSE)),TRUE,FALSE) -> TRUE | AG20: =VLOOKUP(AB20,lists!$B$7:$C$8,2,FALSE) -> TRUE | AH20: =VLOOKUP(IF(H20="","Open",SUBSTITUTE(H20,"/Nov","")),lists!$B$27:$D$29,2,FALSE) -> TRUE | AI20: =IF(FLAT!$I$5="All",TRUE,IF(FLAT!$I$5=TEXT('Raw - F'!C20,"mmm"),TRUE,FALSE)) -> TRUE | AJ20: =VLOOKUP(L20,lists!B:C,2,FALSE) -> TRUE | AK20: =VLOOKUP(T20,lists!$B$23:$D$25,2,FALSE) -> TRUE | AL20: =IF(AND(AD20=TRUE,AE20=TRUE,AF20=TRUE,AG20=TRUE,AH20=TRUE,AI20=TRUE,AJ20=TRUE,AK20=TRUE),1,0) -> 1
A21: =IF(B21="",A20,B21+1) -> 21 | B21: =IF(AND(A20<1,AL21=1),1,IF(AL21=1,A20,"")) -> 20 | C21: 44317 | D21: NEWMARKET | E21: Flat | F21: Flat | G21: Hcap | H21: Open | J21: 4yo+ | K21: A | L21: 2 | N21: Open | O21: 6f | P21: 6f | Q21: 50000 | R21: DISCOVER HCAP STKS | T21: Midlands | U21: 0 | AA21: =IF(OR(J21="2yo",J21="3yo"),J21,"Other") -> Other | AB21: =IF(K21="F",K21,"A") -> A | AC21: =VLOOKUP(P21,lists!$G:$H,2,FALSE) -> 2 | AD21: =VLOOKUP(G21,lists!$B$2:$C$3,2,FALSE) -> TRUE | AE21: =VLOOKUP(AA21,lists!$B:$C,2,FALSE) -> TRUE | AF21: =IF(AND(AC21>=VLOOKUP(FLAT!$I$1,lists!$G:$H,2,FALSE),AC21<=VLOOKUP(FLAT!$I$2,lists!$G:$H,2,FALSE)),TRUE,FALSE) -> TRUE | AG21: =VLOOKUP(AB21,lists!$B$7:$C$8,2,FALSE) -> TRUE | AH21: =VLOOKUP(IF(H21="","Open",SUBSTITUTE(H21,"/Nov","")),lists!$B$27:$D$29,2,FALSE) -> TRUE | AI21: =IF(FLAT!$I$5="All",TRUE,IF(FLAT!$I$5=TEXT('Raw - F'!C21,"mmm"),TRUE,FALSE)) -> TRUE | AJ21: =VLOOKUP(L21,lists!B:C,2,FALSE) -> TRUE | AK21: =VLOOKUP(T21,lists!$B$23:$D$25,2,FALSE) -> TRUE | AL21: =IF(AND(AD21=TRUE,AE21=TRUE,AF21=TRUE,AG21=TRUE,AH21=TRUE,AI21=TRUE,AJ21=TRUE,AK21=TRUE),1,0) -> 1
A22: =IF(B22="",A21,B22+1) -> 22 | B22: =IF(AND(A21<1,AL22=1),1,IF(AL22=1,A21,"")) -> 21 | C22: 44317 | D22: NEWMARKET | E22: Flat | F22: Flat | G22: Hcap | H22: Open | J22: 3yo | K22: A | L22: 2 | N22: 81-100 | O22: 1m | P22: 1m | Q22: 25000 | R22: DISCOVER HCAP STKS | T22: Midlands | U22: 0 | AA22: =IF(OR(J22="2yo",J22="3yo"),J22,"Other") -> 3yo | AB22: =IF(K22="F",K22,"A") -> A | AC22: =VLOOKUP(P22,lists!$G:$H,2,FALSE) -> 4 | AD22: =VLOOKUP(G22,lists!$B$2:$C$3,2,FALSE) -> TRUE | AE22: =VLOOKUP(AA22,lists!$B:$C,2,FALSE) -> TRUE | AF22: =IF(AND(AC22>=VLOOKUP(FLAT!$I$1,lists!$G:$H,2,FALSE),AC22<=VLOOKUP(FLAT!$I$2,lists!$G:$H,2,FALSE)),TRUE,FALSE) -> TRUE | AG22: =VLOOKUP(AB22,lists!$B$7:$C$8,2,FALSE) -> TRUE | AH22: =VLOOKUP(IF(H22="","Open",SUBSTITUTE(H22,"/Nov","")),lists!$B$27:$D$29,2,FALSE) -> TRUE | AI22: =IF(FLAT!$I$5="All",TRUE,IF(FLAT!$I$5=TEXT('Raw - F'!C22,"mmm"),TRUE,FALSE)) -> TRUE | AJ22: =VLOOKUP(L22,lists!B:C,2,FALSE) -> TRUE | AK22: =VLOOKUP(T22,lists!$B$23:$D$25,2,FALSE) -> TRUE | AL22: =IF(AND(AD22=TRUE,AE22=TRUE,AF22=TRUE,AG22=TRUE,AH22=TRUE,AI22=TRUE,AJ22=TRUE,AK22=TRUE),1,0) -> 1
A23: =IF(B23="",A22,B23+1) -> 23 | B23: =IF(AND(A22<1,AL23=1),1,IF(AL23=1,A22,"")) -> 22 | C23: 44317 | D23: NEWMARKET | E23: Flat | F23: Flat | G23: Hcap | H23: Open | J23: 3yo | K23: A | L23: 2 | N23: 81-100 | O23: 6f | P23: 6f | Q23: 25000 | R23: HOME HCAP STKS | T23: Midlands | U23: 0 | AA23: =IF(OR(J23="2yo",J23="3yo"),J23,"Other") -> 3yo | AB23: =IF(K23="F",K23,"A") -> A | AC23: =VLOOKUP(P23,lists!$G:$H,2,FALSE) -> 2 | AD23: =VLOOKUP(G23,lists!$B$2:$C$3,2,FALSE) -> TRUE | AE23: =VLOOKUP(AA23,lists!$B:$C,2,FALSE) -> TRUE | AF23: =IF(AND(AC23>=VLOOKUP(FLAT!$I$1,lists!$G:$H,2,FALSE),AC23<=VLOOKUP(FLAT!$I$2,lists!$G:$H,2,FALSE)),TRUE,FALSE) -> TRUE | AG23: =VLOOKUP(AB23,lists!$B$7:$C$8,2,FALSE) -> TRUE | AH23: =VLOOKUP(IF(H23="","Open",SUBSTITUTE(H23,"/Nov","")),lists!$B$27:$D$29,2,FALSE) -> TRUE | AI23: =IF(FLAT!$I$5="All",TRUE,IF(FLAT!$I$5=TEXT('Raw - F'!C23,"mmm"),TRUE,FALSE)) -> TRUE | AJ23: =VLOOKUP(L23,lists!B:C,2,FALSE) -> TRUE | AK23: =VLOOKUP(T23,lists!$B$23:$D$25,2,FALSE) -> TRUE | AL23: =IF(AND(AD23=TRUE,AE23=TRUE,AF23=TRUE,AG23=TRUE,AH23=TRUE,AI23=TRUE,AJ23=TRUE,AK23=TRUE),1,0) -> 1
A24: =IF(B24="",A23,B24+1) -> 24 | B24: =IF(AND(A23<1,AL24=1),1,IF(AL24=1,A23,"")) -> 23 | C24: 44317 | D24: THIRSK | E24: Flat | F24: Flat | G24: Hcap | H24: Open | J24: 4yo+ | K24: A | L24: 2 | N24: 81-100 | O24: 7f218y | P24: 1m | Q24: 30000 | R24: HUNT CUP HCAP STKS | T24: North | U24: 0 | AA24: =IF(OR(J24="2yo",J24="3yo"),J24,"Other") -> Other | AB24: =IF(K24="F",K24,"A") -> A | AC24: =VLOOKUP(P24,lists!$G:$H,2,FALSE) -> 4 | AD24: =VLOOKUP(G24,lists!$B$2:$C$3,2,FALSE) -> TRUE | AE24: =VLOOKUP(AA24,lists!$B:$C,2,FALSE) -> TRUE | AF24: =IF(AND(AC24>=VLOOKUP(FLAT!$I$1,lists!$G:$H,2,FALSE),AC24<=VLOOKUP(FLAT!$I$2,lists!$G:$H,2,FALSE)),TRUE,FALSE) -> TRUE | AG24: =VLOOKUP(AB24,lists!$B$7:$C$8,2,FALSE) -> TRUE | AH24: =VLOOKUP(IF(H24="","Open",SUBSTITUTE(H24,"/Nov","")),lists!$B$27:$D$29,2,FALSE) -> TRUE | AI24: =IF(FLAT!$I$5="All",TRUE,IF(FLAT!$I$5=TEXT('Raw - F'!C24,"mmm"),TRUE,FALSE)) -> TRUE | AJ24: =VLOOKUP(L24,lists!B:C,2,FALSE) -> TRUE | AK24: =VLOOKUP(T24,lists!$B$23:$D$25,2,FALSE) -> TRUE | AL24: =IF(AND(AD24=TRUE,AE24=TRUE,AF24=TRUE,AG24=TRUE,AH24=TRUE,AI24=TRUE,AJ24=TRUE,AK24=TRUE),1,0) -> 1
A25: =IF(B25="",A24,B25+1) -> 25 | B25: =IF(AND(A24<1,AL25=1),1,IF(AL25=1,A24,"")) -> 24 | C25: 44317 | D25: THIRSK | E25: Flat | F25: Flat | G25: Hcap | H25: Open | J25: 4yo+ | K25: A | L25: 4 | N25: 61-80 | O25: 6f | P25: 6f | Q25: 7650 | R25: GLAMPING HCAP STKS | T25: North | U25: 0 | AA25: =IF(OR(J25="2yo",J25="3yo"),J25,"Other") -> Other | AB25: =IF(K25="F",K25,"A") -> A | AC25: =VLOOKUP(P25,lists!$G:$H,2,FALSE) -> 2 | AD25: =VLOOKUP(G25,lists!$B$2:$C$3,2,FALSE) -> TRUE | AE25: =VLOOKUP(AA25,lists!$B:$C,2,FALSE) -> TRUE | AF25: =IF(AND(AC25>=VLOOKUP(FLAT!$I$1,lists!$G:$H,2,FALSE),AC25<=VLOOKUP(FLAT!$I$2,lists!$G:$H,2,FALSE)),TRUE,FALSE) -> TRUE | AG25: =VLOOKUP(AB25,lists!$B$7:$C$8,2,FALSE) -> TRUE | AH25: =VLOOKUP(IF(H25="","Open",SUBSTITUTE(H25,"/Nov","")),lists!$B$27:$D$29,2,FALSE) -> TRUE | AI25: =IF(FLAT!$I$5="All",TRUE,IF(FLAT!$I$5=TEXT('Raw - F'!C25,"mmm"),TRUE,FALSE)) -> TRUE | AJ25: =VLOOKUP(L25,lists!B:C,2,FALSE) -> TRUE | AK25: =VLOOKUP(T25,lists!$B$23:$D$25,2,FALSE) -> TRUE | AL25: =IF(AND(AD25=TRUE,AE25=TRUE,AF25=TRUE,AG25=TRUE,AH25=TRUE,AI25=TRUE,AJ25=TRUE,AK25=TRUE),1,0) -> 1
A26: =IF(B26="",A25,B26+1) -> 26 | B26: =IF(AND(A25<1,AL26=1),1,IF(AL26=1,A25,"")) -> 25 | C26: 44317 | D26: THIRSK | E26: Flat | F26: Flat | G26: Hcap | H26: Open | J26: 3yo+ | K26: A | L26: 4 | N26: 66-85 | O26: 5f | P26: 5f | Q26: 7650 | R26: FRANKEL HCAP STKS | T26: North | U26: 0 | AA26: =IF(OR(J26="2yo",J26="3yo"),J26,"Other") -> Other | AB26: =IF(K26="F",K26,"A") -> A | AC26: =VLOOKUP(P26,lists!$G:$H,2,FALSE) -> 1 | AD26: =VLOOKUP(G26,lists!$B$2:$C$3,2,FALSE) -> TRUE | AE26: =VLOOKUP(AA26,lists!$B:$C,2,FALSE) -> TRUE | AF26: =IF(AND(AC26>=VLOOKUP(FLAT!$I$1,lists!$G:$H,2,FALSE),AC26<=VLOOKUP(FLAT!$I$2,lists!$G:$H,2,FALSE)),TRUE,FALSE) -> TRUE | AG26: =VLOOKUP(AB26,lists!$B$7:$C$8,2,FALSE) -> TRUE | AH26: =VLOOKUP(IF(H26="","Open",SUBSTITUTE(H26,"/Nov","")),lists!$B$27:$D$29,2,FALSE) -> TRUE | AI26: =IF(FLAT!$I$5="All",TRUE,IF(FLAT!$I$5=TEXT('Raw - F'!C26,"mmm"),TRUE,FALSE)) -> TRUE | AJ26: =VLOOKUP(L26,lists!B:C,2,FALSE) -> TRUE | AK26: =VLOOKUP(T26,lists!$B$23:$D$25,2,FALSE) -> TRUE | AL26: =IF(AND(AD26=TRUE,AE26=TRUE,AF26=TRUE,AG26=TRUE,AH26=TRUE,AI26=TRUE,AJ26=TRUE,AK26=TRUE),1,0) -> 1
A27: =IF(B27="",A26,B27+1) -> 27 | B27: =IF(AND(A26<1,AL27=1),1,IF(AL27=1,A26,"")) -> 26 | C27: 44317 | D27: THIRSK | E27: Flat | F27: Flat | G27: WFA | H27: Mdn | J27: 3yo+ | K27: F | L27: 4 | N27: Open | O27: 7f | P27: 7f | Q27: 7650 | R27: STUDS EBF MDN STKS | T27: North | U27: 0 | Z27: EBF | AA27: =IF(OR(J27="2yo",J27="3yo"),J27,"Other") -> Other | AB27: =IF(K27="F",K27,"A") -> F | AC27: =VLOOKUP(P27,lists!$G:$H,2,FALSE) -> 3 | AD27: =VLOOKUP(G27,lists!$B$2:$C$3,2,FALSE) -> TRUE | AE27: =VLOOKUP(AA27,lists!$B:$C,2,FALSE) -> TRUE | AF27: =IF(AND(AC27>=VLOOKUP(FLAT!$I$1,lists!$G:$H,2,FALSE),AC27<=VLOOKUP(FLAT!$I$2,lists!$G:$H,2,FALSE)),TRUE,FALSE) -> TRUE | AG27: =VLOOKUP(AB27,lists!$B$7:$C$8,2,FALSE) -> TRUE | AH27: =VLOOKUP(IF(H27="","Open",SUBSTITUTE(H27,"/Nov","")),lists!$B$27:$D$29,2,FALSE) -> TRUE | AI27: =IF(FLAT!$I$5="All",TRUE,IF(FLAT!$I$5=TEXT('Raw - F'!C27,"mmm"),TRUE,FALSE)) -> TRUE | AJ27: =VLOOKUP(L27,lists!B:C,2,FALSE) -> TRUE | AK27: =VLOOKUP(T27,lists!$B$23:$D$25,2,FALSE) -> TRUE | AL27: =IF(AND(AD27=TRUE,AE27=TRUE,AF27=TRUE,AG27=TRUE,AH27=TRUE,AI27=TRUE,AJ27=TRUE,AK27=TRUE),1,0) -> 1
A28: =IF(B28="",A27,B28+1) -> 28 | B28: =IF(AND(A27<1,AL28=1),1,IF(AL28=1,A27,"")) -> 27 | C28: 44317 | D28: THIRSK | E28: Flat | F28: Flat | G28: Hcap | H28: Open | J28: 3yo+ | K28: A | L28: 5 | N28: 51-70 | O28: 7f218y | P28: 1m | Q28: 5400 | R28: CLIFF STUD HCAP STKS | T28: North | U28: 0 | AA28: =IF(OR(J28="2yo",J28="3yo"),J28,"Other") -> Other | AB28: =IF(K28="F",K28,"A") -> A | AC28: =VLOOKUP(P28,lists!$G:$H,2,FALSE) -> 4 | AD28: =VLOOKUP(G28,lists!$B$2:$C$3,2,FALSE) -> TRUE | AE28: =VLOOKUP(AA28,lists!$B:$C,2,FALSE) -> TRUE | AF28: =IF(AND(AC28>=VLOOKUP(FLAT!$I$1,lists!$G:$H,2,FALSE),AC28<=VLOOKUP(FLAT!$I$2,lists!$G:$H,2,FALSE)),TRUE,FALSE) -> TRUE | AG28: =VLOOKUP(AB28,lists!$B$7:$C$8,2,FALSE) -> TRUE | AH28: =VLOOKUP(IF(H28="","Open",SUBSTITUTE(H28,"/Nov","")),lists!$B$27:$D$29,2,FALSE) -> TRUE | AI28: =IF(FLAT!$I$5="All",TRUE,IF(FLAT!$I$5=TEXT('Raw - F'!C28,"mmm"),TRUE,FALSE)) -> TRUE | AJ28: =VLOOKUP(L28,lists!B:C,2,FALSE) -> TRUE | AK28: =VLOOKUP(T28,lists!$B$23:$D$25,2,FALSE) -> TRUE | AL28: =IF(AND(AD28=TRUE,AE28=TRUE,AF28=TRUE,AG28=TRUE,AH28=TRUE,AI28=TRUE,AJ28=TRUE,AK28=TRUE),1,0) -> 1
A29: =IF(B29="",A28,B29+1) -> 29 | B29: =IF(AND(A28<1,AL29=1),1,IF(AL29=1,A28,"")) -> 28 | C29: 44317 | D29: THIRSK | E29: Flat | F29: Flat | G29: Hcap | H29: Open | J29: 4yo+ | K29: A | L29: 5 | N29: 51-70 | O29: 1m6f | P29: 1m 6f | Q29: 5400 | R29: CECIL HCAP STKS | T29: North | U29: 0 | AA29: =IF(OR(J29="2yo",J29="3yo"),J29,"Other") -> Other | AB29: =IF(K29="F",K29,"A") -> A | AC29: =VLOOKUP(P29,lists!$G:$H,2,FALSE) -> 9 | AD29: =VLOOKUP(G29,lists!$B$2:$C$3,2,FALSE) -> TRUE | AE29: =VLOOKUP(AA29,lists!$B:$C,2,FALSE) -> TRUE | AF29: =IF(AND(AC29>=VLOOKUP(FLAT!$I$1,lists!$G:$H,2,FALSE),AC29<=VLOOKUP(FLAT!$I$2,lists!$G:$H,2,FALSE)),TRUE,FALSE) -> TRUE | AG29: =VLOOKUP(AB29,lists!$B$7:$C$8,2,FALSE) -> TRUE | AH29: =VLOOKUP(IF(H29="","Open",SUBSTITUTE(H29,"/Nov","")),lists!$B$27:$D$29,2,FALSE) -> TRUE | AI29: =IF(FLAT!$I$5="All",TRUE,IF(FLAT!$I$5=TEXT('Raw - F'!C29,"mmm"),TRUE,FALSE)) -> TRUE | AJ29: =VLOOKUP(L29,lists!B:C,2,FALSE) -> TRUE | AK29: =VLOOKUP(T29,lists!$B$23:$D$25,2,FALSE) -> TRUE | AL29: =IF(AND(AD29=TRUE,AE29=TRUE,AF29=TRUE,AG29=TRUE,AH29=TRUE,AI29=TRUE,AJ29=TRUE,AK29=TRUE),1,0) -> 1
A30: =IF(B30="",A29,B30+1) -> 30 | B30: =IF(AND(A29<1,AL30=1),1,IF(AL30=1,A29,"")) -> 29 | C30: 44317 | D30: THIRSK | E30: Flat | F30: Flat | G30: WFA | H30: Nov | J30: 2yo | K30: A | L30: 5 | N30: Open | O30: 5f | P30: 5f | Q30: 5000 | R30: CLIFF STUD NOV STKS | T30: North | U30: 0 | X30: Rest. | Y30: B | AA30: =IF(OR(J30="2yo",J30="3yo"),J30,"Other") -> 2yo | AB30: =IF(K30="F",K30,"A") -> A | AC30: =VLOOKUP(P30,lists!$G:$H,2,FALSE) -> 1 | AD30: =VLOOKUP(G30,lists!$B$2:$C$3,2,FALSE) -> TRUE | AE30: =VLOOKUP(AA30,lists!$B:$C,2,FALSE) -> TRUE | AF30: =IF(AND(AC30>=VLOOKUP(FLAT!$I$1,lists!$G:$H,2,FALSE),AC30<=VLOOKUP(FLAT!$I$2,lists!$G:$H,2,FALSE)),TRUE,FALSE) -> TRUE | AG30: =VLOOKUP(AB30,lists!$B$7:$C$8,2,FALSE) -> TRUE | AH30: =VLOOKUP(IF(H30="","Open",SUBSTITUTE(H30,"/Nov","")),lists!$B$27:$D$29,2,FALSE) -> TRUE | AI30: =IF(FLAT!$I$5="All",TRUE,IF(FLAT!$I$5=TEXT('Raw - F'!C30,"mmm"),TRUE,FALSE)) -> TRUE | AJ30: =VLOOKUP(L30,lists!B:C,2,FALSE) -> TRUE | AK30: =VLOOKUP(T30,lists!$B$23:$D$25,2,FALSE) -> TRUE | AL30: =IF(AND(AD30=TRUE,AE30=TRUE,AF30=TRUE,AG30=TRUE,AH30=TRUE,AI30=TRUE,AJ30=TRUE,AK30=TRUE),1,0) -> 1
A31: =IF(B31="",A30,B31+1) -> 31 | B31: =IF(AND(A30<1,AL31=1),1,IF(AL31=1,A30,"")) -> 30 | C31: 44318 | D31: HAMILTON PARK | E31: Flat | F31: Flat | G31: WFA | H31: Open | I31: Conditions | J31: 3yo | K31: A | L31: 2 | N31: Open | O31: 5f7y | P31: 5f | Q31: 32000 | R31: TANGERINE TREES EBF STKS | T31: North | U31: 0 | Z31: EBF | AA31: =IF(OR(J31="2yo",J31="3yo"),J31,"Other") -> 3yo | AB31: =IF(K31="F",K31,"A") -> A | AC31: =VLOOKUP(P31,lists!$G:$H,2,FALSE) -> 1 | AD31: =VLOOKUP(G31,lists!$B$2:$C$3,2,FALSE) -> TRUE | AE31: =VLOOKUP(AA31,lists!$B:$C,2,FALSE) -> TRUE | AF31: =IF(AND(AC31>=VLOOKUP(FLAT!$I$1,lists!$G:$H,2,FALSE),AC31<=VLOOKUP(FLAT!$I$2,lists!$G:$H,2,FALSE)),TRUE,FALSE) -> TRUE | AG31: =VLOOKUP(AB31,lists!$B$7:$C$8,2,FALSE) -> TRUE | AH31: =VLOOKUP(IF(H31="","Open",SUBSTITUTE(H31,"/Nov","")),lists!$B$27:$D$29,2,FALSE) -> TRUE | AI31: =IF(FLAT!$I$5="All",TRUE,IF(FLAT!$I$5=TEXT('Raw - F'!C31,"mmm"),TRUE,FALSE)) -> TRUE | AJ31: =VLOOKUP(L31,lists!B:C,2,FALSE) -> TRUE | AK31: =VLOOKUP(T31,lists!$B$23:$D$25,2,FALSE) -> TRUE | AL31: =IF(AND(AD31=TRUE,AE31=TRUE,AF31=TRUE,AG31=TRUE,AH31=TRUE,AI31=TRUE,AJ31=TRUE,AK31=TRUE),1,0) -> 1
A32: =IF(B32="",A31,B32+1) -> 32 | B32: =IF(AND(A31<1,AL32=1),1,IF(AL32=1,A31,"")) -> 31 | C32: 44318 | D32: HAMILTON PARK | E32: Flat | F32: Flat | G32: Hcap | H32: Open | J32: 4yo+ | K32: A | L32: 3 | N32: 76-95 | O32: 1m5f16y | P32: 1m 5f | Q32: 30000 | R32: BUTTONHOOK HCAP STKS | T32: North | U32: 0 | AA32: =IF(OR(J32="2yo",J32="3yo"),J32,"Other") -> Other | AB32: =IF(K32="F",K32,"A") -> A | AC32: =VLOOKUP(P32,lists!$G:$H,2,FALSE) -> 8 | AD32: =VLOOKUP(G32,lists!$B$2:$C$3,2,FALSE) -> TRUE | AE32: =VLOOKUP(AA32,lists!$B:$C,2,FALSE) -> TRUE | AF32: =IF(AND(AC32>=VLOOKUP(FLAT!$I$1,lists!$G:$H,2,FALSE),AC32<=VLOOKUP(FLAT!$I$2,lists!$G:$H,2,FALSE)),TRUE,FALSE) -> TRUE | AG32: =VLOOKUP(AB32,lists!$B$7:$C$8,2,FALSE) -> TRUE | AH32: =VLOOKUP(IF(H32="","Open",SUBSTITUTE(H32,"/Nov","")),lists!$B$27:$D$29,2,FALSE) -> TRUE | AI32: =IF(FLAT!$I$5="All",TRUE,IF(FLAT!$I$5=TEXT('Raw - F'!C32,"mmm"),TRUE,FALSE)) -> TRUE | AJ32: =VLOOKUP(L32,lists!B:C,2,FALSE) -> TRUE | AK32: =VLOOKUP(T32,lists!$B$23:$D$25,2,FALSE) -> TRUE | AL32: =IF(AND(AD32=TRUE,AE32=TRUE,AF32=TRUE,AG32=TRUE,AH32=TRUE,AI32=TRUE,AJ32=TRUE,AK32=TRUE),1,0) -> 1
A33: =IF(B33="",A32,B33+1) -> 33 | B33: =IF(AND(A32<1,AL33=1),1,IF(AL33=1,A32,"")) -> 32 | C33: 44318 | D33: HAMILTON PARK | E33: Flat | F33: Flat | G33: Hcap | H33: Open | J33: 4yo+ | K33: A | L33: 4 | N33: 66-85 | O33: 1m68y | P33: 1m | Q33: 10000 | R33: WINDOW BLINDS HCAP | T33: North | U33: 0 | AA33: =IF(OR(J33="2yo",J33="3yo"),J33,"Other") -> Other | AB33: =IF(K33="F",K33,"A") -> A | AC33: =VLOOKUP(P33,lists!$G:$H,2,FALSE) -> 4 | AD33: =VLOOKUP(G33,lists!$B$2:$C$3,2,FALSE) -> TRUE | AE33: =VLOOKUP(AA33,lists!$B:$C,2,FALSE) -> TRUE | AF33: =IF(AND(AC33>=VLOOKUP(FLAT!$I$1,lists!$G:$H,2,FALSE),AC33<=VLOOKUP(FLAT!$I$2,lists!$G:$H,2,FALSE)),TRUE,FALSE) -> TRUE | AG33: =VLOOKUP(AB33,lists!$B$7:$C$8,2,FALSE) -> TRUE | AH33: =VLOOKUP(IF(H33="","Open",SUBSTITUTE(H33,"/Nov","")),lists!$B$27:$D$29,2,FALSE) -> TRUE | AI33: =IF(FLAT!$I$5="All",TRUE,IF(FLAT!$I$5=TEXT('Raw - F'!C33,"mmm"),TRUE,FALSE)) -> TRUE | AJ33: =VLOOKUP(L33,lists!B:C,2,FALSE) -> TRUE | AK33: =VLOOKUP(T33,lists!$B$23:$D$25,2,FALSE) -> TRUE | AL33: =IF(AND(AD33=TRUE,AE33=TRUE,AF33=TRUE,AG33=TRUE,AH33=TRUE,AI33=TRUE,AJ33=TRUE,AK33=TRUE),1,0) -> 1
A34: =IF(B34="",A33,B34+1) -> 34 | B34: =IF(AND(A33<1,AL34=1),1,IF(AL34=1,A33,"")) -> 33 | C34: 44318 | D34: HAMILTON PARK | E34: Flat | F34: Flat | G34: WFA | H34: Mdn | J34: 3yo+ | K34: A | L34: 5 | N34: Open | O34: 1m68y | P34: 1m | Q34: 7000 | R34: SKY 426 MDN STKS | T34: North | U34: 0 | AA34: =IF(OR(J34="2yo",J34="3yo"),J34,"Other") -> Other | AB34: =IF(K34="F",K34,"A") -> A | AC34: =VLOOKUP(P34,lists!$G:$H,2,FALSE) -> 4 | AD34: =VLOOKUP(G34,lists!$B$2:$C$3,2,FALSE) -> TRUE | AE34: =VLOOKUP(AA34,lists!$B:$C,2,FALSE) -> TRUE | AF34: =IF(AND(AC34>=VLOOKUP(FLAT!$I$1,lists!$G:$H,2,FALSE),AC34<=VLOOKUP(FLAT!$I$2,lists!$G:$H,2,FALSE)),TRUE,FALSE) -> TRUE | AG34: =VLOOKUP(AB34,lists!$B$7:$C$8,2,FALSE) -> TRUE | AH34: =VLOOKUP(IF(H34="","Open",SUBSTITUTE(H34,"/Nov","")),lists!$B$27:$D$29,2,FALSE) -> TRUE | AI34: =IF(FLAT!$I$5="All",TRUE,IF(FLAT!$I$5=TEXT('Raw - F'!C34,"mmm"),TRUE,FALSE)) -> TRUE | AJ34: =VLOOKUP(L34,lists!B:C,2,FALSE) -> TRUE | AK34: =VLOOKUP(T34,lists!$B$23:$D$25,2,FALSE) -> TRUE | AL34: =IF(AND(AD34=TRUE,AE34=TRUE,AF34=TRUE,AG34=TRUE,AH34=TRUE,AI34=TRUE,AJ34=TRUE,AK34=TRUE),1,0) -> 1
A35: =IF(B35="",A34,B35+1) -> 35 | B35: =IF(AND(A34<1,AL35=1),1,IF(AL35=1,A34,"")) -> 34 | C35: 44318 | D35: HAMILTON PARK | E35: Flat | F35: Flat | G35: Hcap | H35: Open | J35: 4yo+ | K35: A | L35: 5 | N35: 51-70 | O35: 5f7y | P35: 5f | Q35: 7000 | R35: TOP CAT HCAP STKS | T35: North | U35: 0 | AA35: =IF(OR(J35="2yo",J35="3yo"),J35,"Other") -> Other | AB35: =IF(K35="F",K35,"A") -> A | AC35: =VLOOKUP(P35,lists!$G:$H,2,FALSE) -> 1 | AD35: =VLOOKUP(G35,lists!$B$2:$C$3,2,FALSE) -> TRUE | AE35: =VLOOKUP(AA35,lists!$B:$C,2,FALSE) -> TRUE | AF35: =IF(AND(AC35>=VLOOKUP(FLAT!$I$1,lists!$G:$H,2,FALSE),AC35<=VLOOKUP(FLAT!$I$2,lists!$G:$H,2,FALSE)),TRUE,FALSE) -> TRUE | AG35: =VLOOKUP(AB35,lists!$B$7:$C$8,2,FALSE) -> TRUE | AH35: =VLOOKUP(IF(H35="","Open",SUBSTITUTE(H35,"/Nov","")),lists!$B$27:$D$29,2,FALSE) -> TRUE | AI35: =IF(FLAT!$I$5="All",TRUE,IF(FLAT!$I$5=TEXT('Raw - F'!C35,"mmm"),TRUE,FALSE)) -> TRUE | AJ35: =VLOOKUP(L35,lists!B:C,2,FALSE) -> TRUE | AK35: =VLOOKUP(T35,lists!$B$23:$D$25,2,FALSE) -> TRUE | AL35: =IF(AND(AD35=TRUE,AE35=TRUE,AF35=TRUE,AG35=TRUE,AH35=TRUE,AI35=TRUE,AJ35=TRUE,AK35=TRUE),1,0) -> 1
A36: =IF(B36="",A35,B36+1) -> 36 | B36: =IF(AND(A35<1,AL36=1),1,IF(AL36=1,A35,"")) -> 35 | C36: 44318 | D36: HAMILTON PARK | E36: Flat | F36: Flat | G36: Hcap | H36: Open | J36: 4yo+ | K36: A | L36: 5 | N36: 51-70 | O36: 6f6y | P36: 6f | Q36: 7000 | R36: RTV PROFITS HCP STKS | T36: North | U36: 0 | AA36: =IF(OR(J36="2yo",J36="3yo"),J36,"Other") -> Other | AB36: =IF(K36="F",K36,"A") -> A | AC36: =VLOOKUP(P36,lists!$G:$H,2,FALSE) -> 2 | AD36: =VLOOKUP(G36,lists!$B$2:$C$3,2,FALSE) -> TRUE | AE36: =VLOOKUP(AA36,lists!$B:$C,2,FALSE) -> TRUE | AF36: =IF(AND(AC36>=VLOOKUP(FLAT!$I$1,lists!$G:$H,2,FALSE),AC36<=VLOOKUP(FLAT!$I$2,lists!$G:$H,2,FALSE)),TRUE,FALSE) -> TRUE | AG36: =VLOOKUP(AB36,lists!$B$7:$C$8,2,FALSE) -> TRUE | AH36: =VLOOKUP(IF(H36="","Open",SUBSTITUTE(H36,"/Nov","")),lists!$B$27:$D$29,2,FALSE) -> TRUE | AI36: =IF(FLAT!$I$5="All",TRUE,IF(FLAT!$I$5=TEXT('Raw - F'!C36,"mmm"),TRUE,FALSE)) -> TRUE | AJ36: =VLOOKUP(L36,lists!B:C,2,FALSE) -> TRUE | AK36: =VLOOKUP(T36,lists!$B$23:$D$25,2,FALSE) -> TRUE | AL36: =IF(AND(AD36=TRUE,AE36=TRUE,AF36=TRUE,AG36=TRUE,AH36=TRUE,AI36=TRUE,AJ36=TRUE,AK36=TRUE),1,0) -> 1
A37: =IF(B37="",A36,B37+1) -> 37 | B37: =IF(AND(A36<1,AL37=1),1,IF(AL37=1,A36,"")) -> 36 | C37: 44318 | D37: HAMILTON PARK | E37: Flat | F37: Flat | G37: Hcap | H37: Open | J37: 4yo+ | K37: A | L37: 5 | N37: 51-70 | O37: 1m3f15y | P37: 1m 3f | Q37: 7000 | R37: TWITTER HCAP STKS | T37: North | U37: 0 | AA37: =IF(OR(J37="2yo",J37="3yo"),J37,"Other") -> Other | AB37: =IF(K37="F",K37,"A") -> A | AC37: =VLOOKUP(P37,lists!$G:$H,2,FALSE) -> 6 | AD37: =VLOOKUP(G37,lists!$B$2:$C$3,2,FALSE) -> TRUE | AE37: =VLOOKUP(AA37,lists!$B:$C,2,FALSE) -> TRUE | AF37: =IF(AND(AC37>=VLOOKUP(FLAT!$I$1,lists!$G:$H,2,FALSE),AC37<=VLOOKUP(FLAT!$I$2,lists!$G:$H,2,FALSE)),TRUE,FALSE) -> TRUE | AG37: =VLOOKUP(AB37,lists!$B$7:$C$8,2,FALSE) -> TRUE | AH37: =VLOOKUP(IF(H37="","Open",SUBSTITUTE(H37,"/Nov","")),lists!$B$27:$D$29,2,FALSE) -> TRUE | AI37: =IF(FLAT!$I$5="All",TRUE,IF(FLAT!$I$5=TEXT('Raw - F'!C37,"mmm"),TRUE,FALSE)) -> TRUE | AJ37: =VLOOKUP(L37,lists!B:C,2,FALSE) -> TRUE | AK37: =VLOOKUP(T37,lists!$B$23:$D$25,2,FALSE) -> TRUE | AL37: =IF(AND(AD37=TRUE,AE37=TRUE,AF37=TRUE,AG37=TRUE,AH37=TRUE,AI37=TRUE,AJ37=TRUE,AK37=TRUE),1,0) -> 1
A38: =IF(B38="",A37,B38+1) -> 38 | B38: =IF(AND(A37<1,AL38=1),1,IF(AL38=1,A37,"")) -> 37 | C38: 44318 | D38: NEWMARKET | E38: Flat | F38: Flat | G38: WFA | H38: Open | J38: 3yo | K38: F | L38: 1 | M38: 1(G1) | N38: Open | O38: 1m | P38: 1m | Q38: 375000 | R38: 1000 GUINEAS STKS | T38: Midlands | U38: 0 | AA38: =IF(OR(J38="2yo",J38="3yo"),J38,"Other") -> 3yo | AB38: =IF(K38="F",K38,"A") -> F | AC38: =VLOOKUP(P38,lists!$G:$H,2,FALSE) -> 4 | AD38: =VLOOKUP(G38,lists!$B$2:$C$3,2,FALSE) -> TRUE | AE38: =VLOOKUP(AA38,lists!$B:$C,2,FALSE) -> TRUE | AF38: =IF(AND(AC38>=VLOOKUP(FLAT!$I$1,lists!$G:$H,2,FALSE),AC38<=VLOOKUP(FLAT!$I$2,lists!$G:$H,2,FALSE)),TRUE,FALSE) -> TRUE | AG38: =VLOOKUP(AB38,lists!$B$7:$C$8,2,FALSE) -> TRUE | AH38: =VLOOKUP(IF(H38="","Open",SUBSTITUTE(H38,"/Nov","")),lists!$B$27:$D$29,2,FALSE) -> TRUE | AI38: =IF(FLAT!$I$5="All",TRUE,IF(FLAT!$I$5=TEXT('Raw - F'!C38,"mmm"),TRUE,FALSE)) -> TRUE | AJ38: =VLOOKUP(L38,lists!B:C,2,FALSE) -> TRUE | AK38: =VLOOKUP(T38,lists!$B$23:$D$25,2,FALSE) -> TRUE | AL38: =IF(AND(AD38=TRUE,AE38=TRUE,AF38=TRUE,AG38=TRUE,AH38=TRUE,AI38=TRUE,AJ38=TRUE,AK38=TRUE),1,0) -> 1
A39: =IF(B39="",A38,B39+1) -> 39 | B39: =IF(AND(A38<1,AL39=1),1,IF(AL39=1,A38,"")) -> 38 | C39: 44318 | D39: NEWMARKET | E39: Flat | F39: Flat | G39: WFA | H39: Open | J39: 4yo+ | K39: F | L39: 1 | M39: 1(G2) | N39: Open | O39: 1m1f | P39: 1m 1f | Q39: 75000 | R39: DAHLIA STKS | T39: Midlands | U39: 0 | AA39: =IF(OR(J39="2yo",J39="3yo"),J39,"Other") -> Other | AB39: =IF(K39="F",K39,"A") -> F | AC39: =VLOOKUP(P39,lists!$G:$H,2,FALSE) -> 5 | AD39: =VLOOKUP(G39,lists!$B$2:$C$3,2,FALSE) -> TRUE | AE39: =VLOOKUP(AA39,lists!$B:$C,2,FALSE) -> TRUE | AF39: =IF(AND(AC39>=VLOOKUP(FLAT!$I$1,lists!$G:$H,2,FALSE),AC39<=VLOOKUP(FLAT!$I$2,lists!$G:$H,2,FALSE)),TRUE,FALSE) -> TRUE | AG39: =VLOOKUP(AB39,lists!$B$7:$C$8,2,FALSE) -> TRUE | AH39: =VLOOKUP(IF(H39="","Open",SUBSTITUTE(H39,"/Nov","")),lists!$B$27:$D$29,2,FALSE) -> TRUE | AI39: =IF(FLAT!$I$5="All",TRUE,IF(FLAT!$I$5=TEXT('Raw - F'!C39,"mmm"),TRUE,FALSE)) -> TRUE | AJ39: =VLOOKUP(L39,lists!B:C,2,FALSE) -> TRUE | AK39: =VLOOKUP(T39,lists!$B$23:$D$25,2,FALSE) -> TRUE | AL39: =IF(AND(AD39=TRUE,AE39=TRUE,AF39=TRUE,AG39=TRUE,AH39=TRUE,AI39=TRUE,AJ39=TRUE,AK39=TRUE),1,0) -> 1
A40: =IF(B40="",A39,B40+1) -> 40 | B40: =IF(AND(A39<1,AL40=1),1,IF(AL40=1,A39,"")) -> 39 | C40: 44318 | D40: NEWMARKET | E40: Flat | F40: Flat | G40: WFA | H40: Open | J40: 3yo | K40: F | L40: 1 | M40: 1(Lstd) | N40: Open | O40: 1m2f | P40: 1m 2f | Q40: 50000 | R40: PRETTY POLLY STKS | T40: Midlands | U40: 0 | AA40: =IF(OR(J40="2yo",J40="3yo"),J40,"Other") -> 3yo | AB40: =IF(K40="F",K40,"A") -> F | AC40: =VLOOKUP(P40,lists!$G:$H,2,FALSE) -> 5 | AD40: =VLOOKUP(G40,lists!$B$2:$C$3,2,FALSE) -> TRUE | AE40: =VLOOKUP(AA40,lists!$B:$C,2,FALSE) -> TRUE | AF40: =IF(AND(AC40>=VLOOKUP(FLAT!$I$1,lists!$G:$H,2,FALSE),AC40<=VLOOKUP(FLAT!$I$2,lists!$G:$H,2,FALSE)),TRUE,FALSE) -> TRUE | AG40: =VLOOKUP(AB40,lists!$B$7:$C$8,2,FALSE) -> TRUE | AH40: =VLOOKUP(IF(H40="","Open",SUBSTITUTE(H40,"/Nov","")),lists!$B$27:$D$29,2,FALSE) -> TRUE | AI40: =IF(FLAT!$I$5="All",TRUE,IF(FLAT!$I$5=TEXT('Raw - F'!C40,"mmm"),TRUE,FALSE)) -> TRUE | AJ40: =VLOOKUP(L40,lists!B:C,2,FALSE) -> TRUE | AK40: =VLOOKUP(T40,lists!$B$23:$D$25,2,FALSE) -> TRUE | AL40: =IF(AND(AD40=TRUE,AE40=TRUE,AF40=TRUE,AG40=TRUE,AH40=TRUE,AI40=TRUE,AJ40=TRUE,AK40=TRUE),1,0) -> 1
...

Sheet Raw - J
C1: Date | D1: Course | E1: Code | F1: Jump Type | G1: Type | H1: M/N | I1: RD | J1: NH Restricted | K1: Age | L1: Sex | M1: Class | N1: PL | O1: RB | P1: Distance | Q1: Distance Category | R1: RaceValue | S1: Race Name | T1: Region | U1: Rider | V1: SC | W1: Auc | X1: AucVal | Y1: Sex classification | Z1: Dist rank | AA1: HC inc | AB1: JT inc | AC1: Dist inc | AD1: Sex inc | AE1: Mdn/Nov | AF1: Month inc | AG1: Class inc | AH1: Region inc | AI1: INCLUDE?
A2: =IF(B2="",A1,B2+1) -> 2 | B2: =IF(AND(A1<1,AI2=1),1,IF(AI2=1,A1,"")) -> 1 | C2: 44317 | D2: HEXHAM | E2: Jump | F2: Hurdle | G2: WFA | H2: Open | K2: 4yo+ | L2: A | M2: 4 | O2: Open | P2: 2m48y | Q2: 2m | R2: 5900 | S2: CAMPBELL SELL HUR | T2: North | V2: S | X2: 0 | Y2: =IF(L2="F",L2,"A") -> A | Z2: =VLOOKUP(Q2,lists!Q:R,2,FALSE) -> 2 | AA2: =VLOOKUP(G2,lists!$B$2:$D$3,3,FALSE) -> TRUE | AB2: =VLOOKUP(F2,lists!$B:$C,2,FALSE) -> TRUE | AC2: =IF(AND(Z2>=VLOOKUP(JUMP!$I$1,lists!$Q:$R,2,FALSE),Z2<=VLOOKUP(JUMP!$I$2,lists!$Q:$R,2,FALSE)),TRUE,FALSE) -> TRUE | AD2: =VLOOKUP(Y2,lists!$B$7:$D$8,3,FALSE) -> TRUE | AE2: =VLOOKUP(SUBSTITUTE(IF(H2="","Open",H2),"Beg","Mdn"),lists!$B$27:$D$29,3,FALSE) -> TRUE | AF2: =IF(JUMP!$I$5="All",TRUE,IF(JUMP!$I$5=TEXT('Raw - J'!C2,"mmm"),TRUE,FALSE)) -> TRUE | AG2: =VLOOKUP(M2,lists!B:D,3,FALSE) -> TRUE | AH2: =VLOOKUP(T2,lists!$B$23:$D$25,3,FALSE) -> TRUE | AI2: =IF(AND(AA2=TRUE,AB2=TRUE,AC2=TRUE,AD2=TRUE,AE2=TRUE,AF2=TRUE,AG2=TRUE,AH2=TRUE),1,0) -> 1
A3: =IF(B3="",A2,B3+1) -> 3 | B3: =IF(AND(A2<1,AI3=1),1,IF(AI3=1,A2,"")) -> 2 | C3: 44317 | D3: HEXHAM | E3: Jump | F3: Hurdle | G3: WFA | H3: Nov | K3: 4yo+ | L3: A | M3: 4 | O3: Open | P3: 2m48y | Q3: 2m | R3: 6200 | S3: B.ROBERTS NOV HUR | T3: North | X3: 0 | Y3: =IF(L3="F",L3,"A") -> A | Z3: =VLOOKUP(Q3,lists!Q:R,2,FALSE) -> 2 | AA3: =VLOOKUP(G3,lists!$B$2:$D$3,3,FALSE) -> TRUE | AB3: =VLOOKUP(F3,lists!$B:$C,2,FALSE) -> TRUE | AC3: =IF(AND(Z3>=VLOOKUP(JUMP!$I$1,lists!$Q:$R,2,FALSE),Z3<=VLOOKUP(JUMP!$I$2,lists!$Q:$R,2,FALSE)),TRUE,FALSE) -> TRUE | AD3: =VLOOKUP(Y3,lists!$B$7:$D$8,3,FALSE) -> TRUE | AE3: =VLOOKUP(SUBSTITUTE(IF(H3="","Open",H3),"Beg","Mdn"),lists!$B$27:$D$29,3,FALSE) -> TRUE | AF3: =IF(JUMP!$I$5="All",TRUE,IF(JUMP!$I$5=TEXT('Raw - J'!C3,"mmm"),TRUE,FALSE)) -> TRUE | AG3: =VLOOKUP(M3,lists!B:D,3,FALSE) -> TRUE | AH3: =VLOOKUP(T3,lists!$B$23:$D$25,3,FALSE) -> TRUE | AI3: =IF(AND(AA3=TRUE,AB3=TRUE,AC3=TRUE,AD3=TRUE,AE3=TRUE,AF3=TRUE,AG3=TRUE,AH3=TRUE),1,0) -> 1
A4: =IF(B4="",A3,B4+1) -> 4 | B4: =IF(AND(A3<1,AI4=1),1,IF(AI4=1,A3,"")) -> 3 | C4: 44317 | D4: HEXHAM | E4: Jump | F4: Chase | G4: Hcap | H4: Open | K4: 5yo+ | L4: A | M4: 5 | O4: 0-100 | P4: 2m4f15y | Q4: 2m 4f | R4: 6500 | S4: HEART HCAP CSE | T4: North | X4: 0 | Y4: =IF(L4="F",L4,"A") -> A | Z4: =VLOOKUP(Q4,lists!Q:R,2,FALSE) -> 3 | AA4: =VLOOKUP(G4,lists!$B$2:$D$3,3,FALSE) -> TRUE | AB4: =VLOOKUP(F4,lists!$B:$C,2,FALSE) -> TRUE | AC4: =IF(AND(Z4>=VLOOKUP(JUMP!$I$1,lists!$Q:$R,2,FALSE),Z4<=VLOOKUP(JUMP!$I$2,lists!$Q:$R,2,FALSE)),TRUE,FALSE) -> TRUE | AD4: =VLOOKUP(Y4,lists!$B$7:$D$8,3,FALSE) -> TRUE | AE4: =VLOOKUP(SUBSTITUTE(IF(H4="","Open",H4),"Beg","Mdn"),lists!$B$27:$D$29,3,FALSE) -> TRUE | AF4: =IF(JUMP!$I$5="All",TRUE,IF(JUMP!$I$5=TEXT('Raw - J'!C4,"mmm"),TRUE,FALSE)) -> TRUE | AG4: =VLOOKUP(M4,lists!B:D,3,FALSE) -> TRUE | AH4: =VLOOKUP(T4,lists!$B$23:$D$25,3,FALSE) -> TRUE | AI4: =IF(AND(AA4=TRUE,AB4=TRUE,AC4=TRUE,AD4=TRUE,AE4=TRUE,AF4=TRUE,AG4=TRUE,AH4=TRUE),1,0) -> 1
A5: =IF(B5="",A4,B5+1) -> 5 | B5: =IF(AND(A4<1,AI5=1),1,IF(AI5=1,A4,"")) -> 4 | C5: 44317 | D5: HEXHAM | E5: Jump | F5: Hurdle | G5: Hcap | H5: Open | K5: 4yo+ | L5: A | M5: 5 | O5: 0-105 | P5: 2m7f63y | Q5: 3m | R5: 6600 | S5: GALLOPS CDL HCP HUR | T5: North | U5: Cond | X5: 0 | Y5: =IF(L5="F",L5,"A") -> A | Z5: =VLOOKUP(Q5,lists!Q:R,2,FALSE) -> 5 | AA5: =VLOOKUP(G5,lists!$B$2:$D$3,3,FALSE) -> TRUE | AB5: =VLOOKUP(F5,lists!$B:$C,2,FALSE) -> TRUE | AC5: =IF(AND(Z5>=VLOOKUP(JUMP!$I$1,lists!$Q:$R,2,FALSE),Z5<=VLOOKUP(JUMP!$I$2,lists!$Q:$R,2,FALSE)),TRUE,FALSE) -> TRUE | AD5: =VLOOKUP(Y5,lists!$B$7:$D$8,3,FALSE) -> TRUE | AE5: =VLOOKUP(SUBSTITUTE(IF(H5="","Open",H5),"Beg","Mdn"),lists!$B$27:$D$29,3,FALSE) -> TRUE | AF5: =IF(JUMP!$I$5="All",TRUE,IF(JUMP!$I$5=TEXT('Raw - J'!C5,"mmm"),TRUE,FALSE)) -> TRUE | AG5: =VLOOKUP(M5,lists!B:D,3,FALSE) -> TRUE | AH5: =VLOOKUP(T5,lists!$B$23:$D$25,3,FALSE) -> TRUE | AI5: =IF(AND(AA5=TRUE,AB5=TRUE,AC5=TRUE,AD5=TRUE,AE5=TRUE,AF5=TRUE,AG5=TRUE,AH5=TRUE),1,0) -> 1
A6: =IF(B6="",A5,B6+1) -> 6 | B6: =IF(AND(A5<1,AI6=1),1,IF(AI6=1,A5,"")) -> 5 | C6: 44317 | D6: HEXHAM | E6: Jump | F6: Chase | G6: WFA | H6: Beg | K6: 5yo+ | L6: A | M6: 4 | O6: Open | P6: 2m4f15y | Q6: 2m 4f | R6: 7200 | S6: CARAVAN BEG CSE | T6: North | X6: 0 | Y6: =IF(L6="F",L6,"A") -> A | Z6: =VLOOKUP(Q6,lists!Q:R,2,FALSE) -> 3 | AA6: =VLOOKUP(G6,lists!$B$2:$D$3,3,FALSE) -> TRUE | AB6: =VLOOKUP(F6,lists!$B:$C,2,FALSE) -> TRUE | AC6: =IF(AND(Z6>=VLOOKUP(JUMP!$I$1,lists!$Q:$R,2,FALSE),Z6<=VLOOKUP(JUMP!$I$2,lists!$Q:$R,2,FALSE)),TRUE,FALSE) -> TRUE | AD6: =VLOOKUP(Y6,lists!$B$7:$D$8,3,FALSE) -> TRUE | AE6: =VLOOKUP(SUBSTITUTE(IF(H6="","Open",H6),"Beg","Mdn"),lists!$B$27:$D$29,3,FALSE) -> TRUE | AF6: =IF(JUMP!$I$5="All",TRUE,IF(JUMP!$I$5=TEXT('Raw - J'!C6,"mmm"),TRUE,FALSE)) -> TRUE | AG6: =VLOOKUP(M6,lists!B:D,3,FALSE) -> TRUE | AH6: =VLOOKUP(T6,lists!$B$23:$D$25,3,FALSE) -> TRUE | AI6: =IF(AND(AA6=TRUE,AB6=TRUE,AC6=TRUE,AD6=TRUE,AE6=TRUE,AF6=TRUE,AG6=TRUE,AH6=TRUE),1,0) -> 1
A7: =IF(B7="",A6,B7+1) -> 7 | B7: =IF(AND(A6<1,AI7=1),1,IF(AI7=1,A6,"")) -> 6 | C7: 44317 | D7: HEXHAM | E7: Jump | F7: Chase | G7: Hcap | H7: Open | K7: 5yo+ | L7: A | M7: 4 | O7: 0-120 | P7: 3m41y | Q7: 3m | R7: 9800 | S7: HEXHAM HCAP CSE | T7: North | X7: 0 | Y7: =IF(L7="F",L7,"A") -> A | Z7: =VLOOKUP(Q7,lists!Q:R,2,FALSE) -> 5 | AA7: =VLOOKUP(G7,lists!$B$2:$D$3,3,FALSE) -> TRUE | AB7: =VLOOKUP(F7,lists!$B:$C,2,FALSE) -> TRUE | AC7: =IF(AND(Z7>=VLOOKUP(JUMP!$I$1,lists!$Q:$R,2,FALSE),Z7<=VLOOKUP(JUMP!$I$2,lists!$Q:$R,2,FALSE)),TRUE,FALSE) -> TRUE | AD7: =VLOOKUP(Y7,lists!$B$7:$D$8,3,FALSE) -> TRUE | AE7: =VLOOKUP(SUBSTITUTE(IF(H7="","Open",H7),"Beg","Mdn"),lists!$B$27:$D$29,3,FALSE) -> TRUE | AF7: =IF(JUMP!$I$5="All",TRUE,IF(JUMP!$I$5=TEXT('Raw - J'!C7,"mmm"),TRUE,FALSE)) -> TRUE | AG7: =VLOOKUP(M7,lists!B:D,3,FALSE) -> TRUE | AH7: =VLOOKUP(T7,lists!$B$23:$D$25,3,FALSE) -> TRUE | AI7: =IF(AND(AA7=TRUE,AB7=TRUE,AC7=TRUE,AD7=TRUE,AE7=TRUE,AF7=TRUE,AG7=TRUE,AH7=TRUE),1,0) -> 1
A8: =IF(B8="",A7,B8+1) -> 8 | B8: =IF(AND(A7<1,AI8=1),1,IF(AI8=1,A7,"")) -> 7 | C8: 44317 | D8: HEXHAM | E8: Jump | F8: Hurdle | G8: Hcap | H8: Open | K8: 4yo+ | L8: A | M8: 3 | O8: 0-130 | P8: 2m48y | Q8: 2m | R8: 10400 | S8: T. DOODY HCAP HUR | T8: North | X8: 0 | Y8: =IF(L8="F",L8,"A") -> A | Z8: =VLOOKUP(Q8,lists!Q:R,2,FALSE) -> 2 | AA8: =VLOOKUP(G8,lists!$B$2:$D$3,3,FALSE) -> TRUE | AB8: =VLOOKUP(F8,lists!$B:$C,2,FALSE) -> TRUE | AC8: =IF(AND(Z8>=VLOOKUP(JUMP!$I$1,lists!$Q:$R,2,FALSE),Z8<=VLOOKUP(JUMP!$I$2,lists!$Q:$R,2,FALSE)),TRUE,FALSE) -> TRUE | AD8: =VLOOKUP(Y8,lists!$B$7:$D$8,3,FALSE) -> TRUE | AE8: =VLOOKUP(SUBSTITUTE(IF(H8="","Open",H8),"Beg","Mdn"),lists!$B$27:$D$29,3,FALSE) -> TRUE | AF8: =IF(JUMP!$I$5="All",TRUE,IF(JUMP!$I$5=TEXT('Raw - J'!C8,"mmm"),TRUE,FALSE)) -> TRUE | AG8: =VLOOKUP(M8,lists!B:D,3,FALSE) -> TRUE | AH8: =VLOOKUP(T8,lists!$B$23:$D$25,3,FALSE) -> TRUE | AI8: =IF(AND(AA8=TRUE,AB8=TRUE,AC8=TRUE,AD8=TRUE,AE8=TRUE,AF8=TRUE,AG8=TRUE,AH8=TRUE),1,0) -> 1
A9: =IF(B9="",A8,B9+1) -> 9 | B9: =IF(AND(A8<1,AI9=1),1,IF(AI9=1,A8,"")) -> 8 | C9: 44317 | D9: UTTOXETER | E9: Jump | F9: Hurdle | G9: Hcap | H9: Nov | K9: 4yo+ | L9: A | M9: 5 | O9: 0-100 | P9: 2m7f70y | Q9: 3m | R9: 4400 | S9: BET365 NOV HCAP HUR | T9: Midlands | X9: 0 | Y9: =IF(L9="F",L9,"A") -> A | Z9: =VLOOKUP(Q9,lists!Q:R,2,FALSE) -> 5 | AA9: =VLOOKUP(G9,lists!$B$2:$D$3,3,FALSE) -> TRUE | AB9: =VLOOKUP(F9,lists!$B:$C,2,FALSE) -> TRUE | AC9: =IF(AND(Z9>=VLOOKUP(JUMP!$I$1,lists!$Q:$R,2,FALSE),Z9<=VLOOKUP(JUMP!$I$2,lists!$Q:$R,2,FALSE)),TRUE,FALSE) -> TRUE | AD9: =VLOOKUP(Y9,lists!$B$7:$D$8,3,FALSE) -> TRUE | AE9: =VLOOKUP(SUBSTITUTE(IF(H9="","Open",H9),"Beg","Mdn"),lists!$B$27:$D$29,3,FALSE) -> TRUE | AF9: =IF(JUMP!$I$5="All",TRUE,IF(JUMP!$I$5=TEXT('Raw - J'!C9,"mmm"),TRUE,FALSE)) -> TRUE | AG9: =VLOOKUP(M9,lists!B:D,3,FALSE) -> TRUE | AH9: =VLOOKUP(T9,lists!$B$23:$D$25,3,FALSE) -> TRUE | AI9: =IF(AND(AA9=TRUE,AB9=TRUE,AC9=TRUE,AD9=TRUE,AE9=TRUE,AF9=TRUE,AG9=TRUE,AH9=TRUE),1,0) -> 1
A10: =IF(B10="",A9,B10+1) -> 10 | B10: =IF(AND(A9<1,AI10=1),1,IF(AI10=1,A9,"")) -> 9 | C10: 44317 | D10: UTTOXETER | E10: Jump | F10: Chase | G10: Hcap | H10: Open | K10: 5yo+ | L10: A | M10: 5 | O10: 0-100 | P10: 3m2y | Q10: 3m | R10: 4700 | S10: BET365 HCAP CSE | T10: Midlands | X10: 0 | Y10: =IF(L10="F",L10,"A") -> A | Z10: =VLOOKUP(Q10,lists!Q:R,2,FALSE) -> 5 | AA10: =VLOOKUP(G10,lists!$B$2:$D$3,3,FALSE) -> TRUE | AB10: =VLOOKUP(F10,lists!$B:$C,2,FALSE) -> TRUE | AC10: =IF(AND(Z10>=VLOOKUP(JUMP!$I$1,lists!$Q:$R,2,FALSE),Z10<=VLOOKUP(JUMP!$I$2,lists!$Q:$R,2,FALSE)),TRUE,FALSE) -> TRUE | AD10: =VLOOKUP(Y10,lists!$B$7:$D$8,3,FALSE) -> TRUE | AE10: =VLOOKUP(SUBSTITUTE(IF(H10="","Open",H10),"Beg","Mdn"),lists!$B$27:$D$29,3,FALSE) -> TRUE | AF10: =IF(JUMP!$I$5="All",TRUE,IF(JUMP!$I$5=TEXT('Raw - J'!C10,"mmm"),TRUE,FALSE)) -> TRUE | AG10: =VLOOKUP(M10,lists!B:D,3,FALSE) -> TRUE | AH10: =VLOOKUP(T10,lists!$B$23:$D$25,3,FALSE) -> TRUE | AI10: =IF(AND(AA10=TRUE,AB10=TRUE,AC10=TRUE,AD10=TRUE,AE10=TRUE,AF10=TRUE,AG10=TRUE,AH10=TRUE),1,0) -> 1
A11: =IF(B11="",A10,B11+1) -> 11 | B11: =IF(AND(A10<1,AI11=1),1,IF(AI11=1,A10,"")) -> 10 | C11: 44317 | D11: UTTOXETER | E11: Jump | F11: Hurdle | G11: WFA | H11: Mdn | J11: NH | K11: 4yo+ | L11: A | M11: 4 | O11: Open | P11: 1m7f168y | Q11: 2m | R11: 5400 | S11: BET365 MDN HUR | T11: Midlands | X11: 0 | Y11: =IF(L11="F",L11,"A") -> A | Z11: =VLOOKUP(Q11,lists!Q:R,2,FALSE) -> 2 | AA11: =VLOOKUP(G11,lists!$B$2:$D$3,3,FALSE) -> TRUE | AB11: =VLOOKUP(F11,lists!$B:$C,2,FALSE) -> TRUE | AC11: =IF(AND(Z11>=VLOOKUP(JUMP!$I$1,lists!$Q:$R,2,FALSE),Z11<=VLOOKUP(JUMP!$I$2,lists!$Q:$R,2,FALSE)),TRUE,FALSE) -> TRUE | AD11: =VLOOKUP(Y11,lists!$B$7:$D$8,3,FALSE) -> TRUE | AE11: =VLOOKUP(SUBSTITUTE(IF(H11="","Open",H11),"Beg","Mdn"),lists!$B$27:$D$29,3,FALSE) -> TRUE | AF11: =IF(JUMP!$I$5="All",TRUE,IF(JUMP!$I$5=TEXT('Raw - J'!C11,"mmm"),TRUE,FALSE)) -> TRUE | AG11: =VLOOKUP(M11,lists!B:D,3,FALSE) -> TRUE | AH11: =VLOOKUP(T11,lists!$B$23:$D$25,3,FALSE) -> TRUE | AI11: =IF(AND(AA11=TRUE,AB11=TRUE,AC11=TRUE,AD11=TRUE,AE11=TRUE,AF11=TRUE,AG11=TRUE,AH11=TRUE),1,0) -> 1
A12: =IF(B12="",A11,B12+1) -> 12 | B12: =IF(AND(A11<1,AI12=1),1,IF(AI12=1,A11,"")) -> 11 | C12: 44317 | D12: UTTOXETER | E12: Jump | F12: Chase | G12: WFA | H12: Beg | K12: 5yo+ | L12: A | M12: 4 | O12: Open | P12: 1m7f214y | Q12: 2m | R12: 6000 | S12: BET365 BEG CSE | T12: Midlands | X12: 0 | Y12: =IF(L12="F",L12,"A") -> A | Z12: =VLOOKUP(Q12,lists!Q:R,2,FALSE) -> 2 | AA12: =VLOOKUP(G12,lists!$B$2:$D$3,3,FALSE) -> TRUE | AB12: =VLOOKUP(F12,lists!$B:$C,2,FALSE) -> TRUE | AC12: =IF(AND(Z12>=VLOOKUP(JUMP!$I$1,lists!$Q:$R,2,FALSE),Z12<=VLOOKUP(JUMP!$I$2,lists!$Q:$R,2,FALSE)),TRUE,FALSE) -> TRUE | AD12: =VLOOKUP(Y12,lists!$B$7:$D$8,3,FALSE) -> TRUE | AE12: =VLOOKUP(SUBSTITUTE(IF(H12="","Open",H12),"Beg","Mdn"),lists!$B$27:$D$29,3,FALSE) -> TRUE | AF12: =IF(JUMP!$I$5="All",TRUE,IF(JUMP!$I$5=TEXT('Raw - J'!C12,"mmm"),TRUE,FALSE)) -> TRUE | AG12: =VLOOKUP(M12,lists!B:D,3,FALSE) -> TRUE | AH12: =VLOOKUP(T12,lists!$B$23:$D$25,3,FALSE) -> TRUE | AI12: =IF(AND(AA12=TRUE,AB12=TRUE,AC12=TRUE,AD12=TRUE,AE12=TRUE,AF12=TRUE,AG12=TRUE,AH12=TRUE),1,0) -> 1
A13: =IF(B13="",A12,B13+1) -> 13 | B13: =IF(AND(A12<1,AI13=1),1,IF(AI13=1,A12,"")) -> 12 | C13: 44317 | D13: UTTOXETER | E13: Jump | F13: Chase | G13: Hcap | H13: Nov | K13: 5yo+ | L13: A | M13: 4 | O13: 0-120 | P13: 2m6f108y | Q13: 2m 6f | R13: 6700 | S13: BET365 NOV HCAP CSE | T13: Midlands | X13: 0 | Y13: =IF(L13="F",L13,"A") -> A | Z13: =VLOOKUP(Q13,lists!Q:R,2,FALSE) -> 4 | AA13: =VLOOKUP(G13,lists!$B$2:$D$3,3,FALSE) -> TRUE | AB13: =VLOOKUP(F13,lists!$B:$C,2,FALSE) -> TRUE | AC13: =IF(AND(Z13>=VLOOKUP(JUMP!$I$1,lists!$Q:$R,2,FALSE),Z13<=VLOOKUP(JUMP!$I$2,lists!$Q:$R,2,FALSE)),TRUE,FALSE) -> TRUE | AD13: =VLOOKUP(Y13,lists!$B$7:$D$8,3,FALSE) -> TRUE | AE13: =VLOOKUP(SUBSTITUTE(IF(H13="","Open",H13),"Beg","Mdn"),lists!$B$27:$D$29,3,FALSE) -> TRUE | AF13: =IF(JUMP!$I$5="All",TRUE,IF(JUMP!$I$5=TEXT('Raw - J'!C13,"mmm"),TRUE,FALSE)) -> TRUE | AG13: =VLOOKUP(M13,lists!B:D,3,FALSE) -> TRUE | AH13: =VLOOKUP(T13,lists!$B$23:$D$25,3,FALSE) -> TRUE | AI13: =IF(AND(AA13=TRUE,AB13=TRUE,AC13=TRUE,AD13=TRUE,AE13=TRUE,AF13=TRUE,AG13=TRUE,AH13=TRUE),1,0) -> 1
A14: =IF(B14="",A13,B14+1) -> 14 | B14: =IF(AND(A13<1,AI14=1),1,IF(AI14=1,A13,"")) -> 13 | C14: 44317 | D14: UTTOXETER | E14: Jump | F14: Hurdle | G14: Hcap | H14: Open | K14: 4yo+ | L14: A | M14: 3 | O14: 0-140 | P14: 2m3f207y | Q14: 2m 4f | R14: 9200 | S14: BET365 HCAP HUR | T14: Midlands | X14: 0 | Y14: =IF(L14="F",L14,"A") -> A | Z14: =VLOOKUP(Q14,lists!Q:R,2,FALSE) -> 3 | AA14: =VLOOKUP(G14,lists!$B$2:$D$3,3,FALSE) -> TRUE | AB14: =VLOOKUP(F14,lists!$B:$C,2,FALSE) -> TRUE | AC14: =IF(AND(Z14>=VLOOKUP(JUMP!$I$1,lists!$Q:$R,2,FALSE),Z14<=VLOOKUP(JUMP!$I$2,lists!$Q:$R,2,FALSE)),TRUE,FALSE) -> TRUE | AD14: =VLOOKUP(Y14,lists!$B$7:$D$8,3,FALSE) -> TRUE | AE14: =VLOOKUP(SUBSTITUTE(IF(H14="","Open",H14),"Beg","Mdn"),lists!$B$27:$D$29,3,FALSE) -> TRUE | AF14: =IF(JUMP!$I$5="All",TRUE,IF(JUMP!$I$5=TEXT('Raw - J'!C14,"mmm"),TRUE,FALSE)) -> TRUE | AG14: =VLOOKUP(M14,lists!B:D,3,FALSE) -> TRUE | AH14: =VLOOKUP(T14,lists!$B$23:$D$25,3,FALSE) -> TRUE | AI14: =IF(AND(AA14=TRUE,AB14=TRUE,AC14=TRUE,AD14=TRUE,AE14=TRUE,AF14=TRUE,AG14=TRUE,AH14=TRUE),1,0) -> 1
A15: =IF(B15="",A14,B15+1) -> 15 | B15: =IF(AND(A14<1,AI15=1),1,IF(AI15=1,A14,"")) -> 14 | C15: 44317 | D15: UTTOXETER | E15: Jump | F15: Chase | G15: Hcap | H15: Open | K15: 5yo+ | L15: A | M15: 2 | O15: Open | P15: 3m2y | Q15: 3m | R15: 35000 | S15: STAFFORDSHIRE CSE | T15: Midlands | X15: 0 | Y15: =IF(L15="F",L15,"A") -> A | Z15: =VLOOKUP(Q15,lists!Q:R,2,FALSE) -> 5 | AA15: =VLOOKUP(G15,lists!$B$2:$D$3,3,FALSE) -> TRUE | AB15: =VLOOKUP(F15,lists!$B:$C,2,FALSE) -> TRUE | AC15: =IF(AND(Z15>=VLOOKUP(JUMP!$I$1,lists!$Q:$R,2,FALSE),Z15<=VLOOKUP(JUMP!$I$2,lists!$Q:$R,2,FALSE)),TRUE,FALSE) -> TRUE | AD15: =VLOOKUP(Y15,lists!$B$7:$D$8,3,FALSE) -> TRUE | AE15: =VLOOKUP(SUBSTITUTE(IF(H15="","Open",H15),"Beg","Mdn"),lists!$B$27:$D$29,3,FALSE) -> TRUE | AF15: =IF(JUMP!$I$5="All",TRUE,IF(JUMP!$I$5=TEXT('Raw - J'!C15,"mmm"),TRUE,FALSE)) -> TRUE | AG15: =VLOOKUP(M15,lists!B:D,3,FALSE) -> TRUE | AH15: =VLOOKUP(T15,lists!$B$23:$D$25,3,FALSE) -> TRUE | AI15: =IF(AND(AA15=TRUE,AB15=TRUE,AC15=TRUE,AD15=TRUE,AE15=TRUE,AF15=TRUE,AG15=TRUE,AH15=TRUE),1,0) -> 1
A16: =IF(B16="",A15,B16+1) -> 16 | B16: =IF(AND(A15<1,AI16=1),1,IF(AI16=1,A15,"")) -> 15 | C16: 44319 | D16: KEMPTON PARK | E16: Jump | F16: Hurdle | G16: Hcap | H16: Open | K16: 4yo+ | L16: A | M16: 4 | O16: 0-120 | P16: 2m5f | Q16: 2m 4f | R16: 5400 | S16: WISE BETTING HCP HUR | T16: South | X16: 0 | Y16: =IF(L16="F",L16,"A") -> A | Z16: =VLOOKUP(Q16,lists!Q:R,2,FALSE) -> 3 | AA16: =VLOOKUP(G16,lists!$B$2:$D$3,3,FALSE) -> TRUE | AB16: =VLOOKUP(F16,lists!$B:$C,2,FALSE) -> TRUE | AC16: =IF(AND(Z16>=VLOOKUP(JUMP!$I$1,lists!$Q:$R,2,FALSE),Z16<=VLOOKUP(JUMP!$I$2,lists!$Q:$R,2,FALSE)),TRUE,FALSE) -> TRUE | AD16: =VLOOKUP(Y16,lists!$B$7:$D$8,3,FALSE) -> TRUE | AE16: =VLOOKUP(SUBSTITUTE(IF(H16="","Open",H16),"Beg","Mdn"),lists!$B$27:$D$29,3,FALSE) -> TRUE | AF16: =IF(JUMP!$I$5="All",TRUE,IF(JUMP!$I$5=TEXT('Raw - J'!C16,"mmm"),TRUE,FALSE)) -> TRUE | AG16: =VLOOKUP(M16,lists!B:D,3,FALSE) -> TRUE | AH16: =VLOOKUP(T16,lists!$B$23:$D$25,3,FALSE) -> TRUE | AI16: =IF(AND(AA16=TRUE,AB16=TRUE,AC16=TRUE,AD16=TRUE,AE16=TRUE,AF16=TRUE,AG16=TRUE,AH16=TRUE),1,0) -> 1
