Workbook

Sheet List
A1: 2024 lu | B1: 2025 lu | C1: Criteria LU | D1: Region LU | E1: Racecourse LU | F1: Overview LU | G1: Date | H1: Weekday | I1: Course | J1: Time | K1: CourseGroup | L1: Region | M1: Code | N1: Surface | O1: Type | P1: pn | Q1: pr | R1: adj_fId | S1: rn | T1: x | U1: Clash | V1: region | W1: Year
A2: =IF(YEAR(G2)=2024,#REF!,"") | B2: =IF(YEAR(G2)=2025,#REF!,"") | C2: =J2&G2 -> Afternoon44927 | D2: =IF('by region'!$C$2="Any","Any",List!V2)&M2&IF('by region'!$I$2="Any","Any",N2)&G2 -> AnyFlatAny44927 | E2: =IF(I2=#REF!,List!G2,"") -> #REF! | F2: =G2&S2 -> #REF! | G2: 44927 | H2: Sunday | I2: Southwell | J2: Afternoon | K2: ARC | L2: Midlands | M2: Flat | N2: AWT | O2: Racecourse/Normal | P2: =IF(J2="Afternoon",1,IF(J2="Evening",2,IF(J2="Floodlit",3,4))) -> 1 | Q2: {=SUMPRODUCT(($G$2:$G$3094=G2)*(P2>$P$2:$P$3094))+1} -> 1 | R2: =(Q2*100000)+#REF! -> #REF! | S2: {=SUMPRODUCT(($G$2:$G$3094=G2)*(R2>$R$2:$R$3094))+1} -> #REF! | T2: =_xlfn.CONCAT(IF(M2="Flat",UPPER(I2),I2)," ",IF(J2="Evening","†",IF(J2="Floodlit","#",""))) -> SOUTHWELL | U2: 0 | V2: North | W2: =YEAR(G2) -> 2023
A3: =IF(YEAR(G3)=2024,#REF!,"") | B3: =IF(YEAR(G3)=2025,#REF!,"") | C3: =J3&G3 -> Afternoon44927 | D3: =IF('by region'!$C$2="Any","Any",List!V3)&M3&IF('by region'!$I$2="Any","Any",N3)&G3 -> AnyJumpAny44927 | E3: =IF(I3=#REF!,List!G3,"") -> #REF! | F3: =G3&S3 -> #REF! | G3: 44927 | H3: Sunday | I3: Catterick Bridge | J3: Afternoon | K3: Independent | L3: North | M3: Jump | N3: Turf | O3: Racecourse/Normal | P3: =IF(J3="Afternoon",1,IF(J3="Evening",2,IF(J3="Floodlit",3,4))) -> 1 | Q3: {=SUMPRODUCT(($G$2:$G$3094=G3)*(P3>$P$2:$P$3094))+1} -> 1 | R3: =(Q3*100000)+#REF! -> #REF! | S3: {=SUMPRODUCT(($G$2:$G$3094=G3)*(R3>$R$2:$R$3094))+1} -> #REF! | T3: =_xlfn.CONCAT(IF(M3="Flat",UPPER(I3),I3)," ",IF(J3="Evening","†",IF(J3="Floodlit","#",""))) -> Catterick Bridge | U3: 0 | V3: NULL | W3: =YEAR(G3) -> 2023
A4: =IF(YEAR(G4)=2024,#REF!,"") | B4: =IF(YEAR(G4)=2025,#REF!,"") | C4: =J4&G4 -> Afternoon44927 | D4: =IF('by region'!$C$2="Any","Any",List!V4)&M4&IF('by region'!$I$2="Any","Any",N4)&G4 -> AnyJumpAny44927 | E4: =IF(I4=#REF!,List!G4,"") -> #REF! | F4: =G4&S4 -> #REF! | G4: 44927 | H4: Sunday | I4: Cheltenham | J4: Afternoon | K4: JCR | L4: Midlands | M4: Jump | N4: Turf | O4: Racecourse/Normal | P4: =IF(J4="Afternoon",1,IF(J4="Evening",2,IF(J4="Floodlit",3,4))) -> 1 | Q4: {=SUMPRODUCT(($G$2:$G$3094=G4)*(P4>$P$2:$P$3094))+1} -> 1 | R4: =(Q4*100000)+#REF! -> #REF! | S4: {=SUMPRODUCT(($G$2:$G$3094=G4)*(R4>$R$2:$R$3094))+1} -> #REF! | T4: =_xlfn.CONCAT(IF(M4="Flat",UPPER(I4),I4)," ",IF(J4="Evening","†",IF(J4="Floodlit","#",""))) -> Cheltenham | U4: 0 | V4: NULL | W4: =YEAR(G4) -> 2023
A5: =IF(YEAR(G5)=2024,#REF!,"") | B5: =IF(YEAR(G5)=2025,#REF!,"") | C5: =J5&G5 -> Afternoon44927 | D5: =IF('by region'!$C$2="Any","Any",List!V5)&M5&IF('by region'!$I$2="Any","Any",N5)&G5 -> AnyJumpAny44927 | E5: =IF(I5=#REF!,List!G5,"") -> #REF! | F5: =G5&S5 -> #REF! | G5: 44927 | H5: Sunday | I5: Exeter | J5: Afternoon | K5: JCR | L5: South | M5: Jump | N5: Turf | O5: Racecourse/Normal | P5: =IF(J5="Afternoon",1,IF(J5="Evening",2,IF(J5="Floodlit",3,4))) -> 1 | Q5: {=SUMPRODUCT(($G$2:$G$3094=G5)*(P5>$P$2:$P$3094))+1} -> 1 | R5: =(Q5*100000)+#REF! -> #REF! | S5: {=SUMPRODUCT(($G$2:$G$3094=G5)*(R5>$R$2:$R$3094))+1} -> #REF! | T5: =_xlfn.CONCAT(IF(M5="Flat",UPPER(I5),I5)," ",IF(J5="Evening","†",IF(J5="Floodlit","#",""))) -> Exeter | U5: 0 | V5: NULL | W5: =YEAR(G5) -> 2023
A6: =IF(YEAR(G6)=2024,#REF!,"") | B6: =IF(YEAR(G6)=2025,#REF!,"") | C6: =J6&G6 -> Afternoon44927 | D6: =IF('by region'!$C$2="Any","Any",List!V6)&M6&IF('by region'!$I$2="Any","Any",N6)&G6 -> AnyJumpAny44927 | E6: =IF(I6=#REF!,List!G6,"") -> #REF! | F6: =G6&S6 -> #REF! | G6: 44927 | H6: Sunday | I6: Fakenham | J6: Afternoon | K6: Independent | L6: Midlands | M6: Jump | N6: Turf | O6: National/BHA | P6: =IF(J6="Afternoon",1,IF(J6="Evening",2,IF(J6="Floodlit",3,4))) -> 1 | Q6: {=SUMPRODUCT(($G$2:$G$3094=G6)*(P6>$P$2:$P$3094))+1} -> 1 | R6: =(Q6*100000)+#REF! -> #REF! | S6: {=SUMPRODUCT(($G$2:$G$3094=G6)*(R6>$R$2:$R$3094))+1} -> #REF! | T6: =_xlfn.CONCAT(IF(M6="Flat",UPPER(I6),I6)," ",IF(J6="Evening","†",IF(J6="Floodlit","#",""))) -> Fakenham | U6: 0 | V6: NULL | W6: =YEAR(G6) -> 2023
A7: =IF(YEAR(G7)=2024,#REF!,"") | B7: =IF(YEAR(G7)=2025,#REF!,"") | C7: =J7&G7 -> Afternoon44927 | D7: =IF('by region'!$C$2="Any","Any",List!V7)&M7&IF('by region'!$I$2="Any","Any",N7)&G7 -> AnyJumpAny44927 | E7: =IF(I7=#REF!,List!G7,"") -> #REF! | F7: =G7&S7 -> #REF! | G7: 44927 | H7: Sunday | I7: Musselburgh | J7: Afternoon | K7: Independent | L7: North | M7: Jump | N7: Turf | O7: National/BHA | P7: =IF(J7="Afternoon",1,IF(J7="Evening",2,IF(J7="Floodlit",3,4))) -> 1 | Q7: {=SUMPRODUCT(($G$2:$G$3094=G7)*(P7>$P$2:$P$3094))+1} -> 1 | R7: =(Q7*100000)+#REF! -> #REF! | S7: {=SUMPRODUCT(($G$2:$G$3094=G7)*(R7>$R$2:$R$3094))+1} -> #REF! | T7: =_xlfn.CONCAT(IF(M7="Flat",UPPER(I7),I7)," ",IF(J7="Evening","†",IF(J7="Floodlit","#",""))) -> Musselburgh | U7: 0 | V7: NULL | W7: =YEAR(G7) -> 2023
A8: =IF(YEAR(G8)=2024,#REF!,"") | B8: =IF(YEAR(G8)=2025,#REF!,"") | C8: =J8&G8 -> Afternoon44928 | D8: =IF('by region'!$C$2="Any","Any",List!V8)&M8&IF('by region'!$I$2="Any","Any",N8)&G8 -> AnyFlatAny44928 | E8: =IF(I8=#REF!,List!G8,"") -> #REF! | F8: =G8&S8 -> #REF! | G8: 44928 | H8: Monday | I8: Lingfield Park | J8: Afternoon | K8: ARC | L8: South | M8: Flat | N8: AWT | O8: National/BHA | P8: =IF(J8="Afternoon",1,IF(J8="Evening",2,IF(J8="Floodlit",3,4))) -> 1 | Q8: {=SUMPRODUCT(($G$2:$G$3094=G8)*(P8>$P$2:$P$3094))+1} -> 1 | R8: =(Q8*100000)+#REF! -> #REF! | S8: {=SUMPRODUCT(($G$2:$G$3094=G8)*(R8>$R$2:$R$3094))+1} -> #REF! | T8: =_xlfn.CONCAT(IF(M8="Flat",UPPER(I8),I8)," ",IF(J8="Evening","†",IF(J8="Floodlit","#",""))) -> LINGFIELD PARK | U8: 0 | V8: NULL | W8: =YEAR(G8) -> 2023
A9: =IF(YEAR(G9)=2024,#REF!,"") | B9: =IF(YEAR(G9)=2025,#REF!,"") | C9: =J9&G9 -> Floodlit44928 | D9: =IF('by region'!$C$2="Any","Any",List!V9)&M9&IF('by region'!$I$2="Any","Any",N9)&G9 -> AnyFlatAny44928 | E9: =IF(I9=#REF!,List!G9,"") -> #REF! | F9: =G9&S9 -> #REF! | G9: 44928 | H9: Monday | I9: Newcastle | J9: Floodlit | K9: ARC | L9: North | M9: Flat | N9: AWT | O9: Racecourse/Normal | P9: =IF(J9="Afternoon",1,IF(J9="Evening",2,IF(J9="Floodlit",3,4))) -> 3 | Q9: {=SUMPRODUCT(($G$2:$G$3094=G9)*(P9>$P$2:$P$3094))+1} -> 4 | R9: =(Q9*100000)+#REF! -> #REF! | S9: {=SUMPRODUCT(($G$2:$G$3094=G9)*(R9>$R$2:$R$3094))+1} -> #REF! | T9: =_xlfn.CONCAT(IF(M9="Flat",UPPER(I9),I9)," ",IF(J9="Evening","†",IF(J9="Floodlit","#",""))) -> NEWCASTLE # | U9: 0 | V9: NULL | W9: =YEAR(G9) -> 2023
A10: =IF(YEAR(G10)=2024,#REF!,"") | B10: =IF(YEAR(G10)=2025,#REF!,"") | C10: =J10&G10 -> Afternoon44928 | D10: =IF('by region'!$C$2="Any","Any",List!V10)&M10&IF('by region'!$I$2="Any","Any",N10)&G10 -> AnyJumpAny44928 | E10: =IF(I10=#REF!,List!G10,"") -> #REF! | F10: =G10&S10 -> #REF! | G10: 44928 | H10: Monday | I10: Ayr | J10: Afternoon | K10: Independent | L10: North | M10: Jump | N10: Turf | O10: Racecourse/Normal | P10: =IF(J10="Afternoon",1,IF(J10="Evening",2,IF(J10="Floodlit",3,4))) -> 1 | Q10: {=SUMPRODUCT(($G$2:$G$3094=G10)*(P10>$P$2:$P$3094))+1} -> 1 | R10: =(Q10*100000)+#REF! -> #REF! | S10: {=SUMPRODUCT(($G$2:$G$3094=G10)*(R10>$R$2:$R$3094))+1} -> #REF! | T10: =_xlfn.CONCAT(IF(M10="Flat",UPPER(I10),I10)," ",IF(J10="Evening","†",IF(J10="Floodlit","#",""))) -> Ayr | U10: 0 | V10: NULL | W10: =YEAR(G10) -> 2023
A11: =IF(YEAR(G11)=2024,#REF!,"") | B11: =IF(YEAR(G11)=2025,#REF!,"") | C11: =J11&G11 -> Afternoon44928 | D11: =IF('by region'!$C$2="Any","Any",List!V11)&M11&IF('by region'!$I$2="Any","Any",N11)&G11 -> AnyJumpAny44928 | E11: =IF(I11=#REF!,List!G11,"") -> #REF! | F11: =G11&S11 -> #REF! | G11: 44928 | H11: Monday | I11: Plumpton | J11: Afternoon | K11: Independent | L11: South | M11: Jump | N11: Turf | O11: Racecourse/Normal | P11: =IF(J11="Afternoon",1,IF(J11="Evening",2,IF(J11="Floodlit",3,4))) -> 1 | Q11: {=SUMPRODUCT(($G$2:$G$3094=G11)*(P11>$P$2:$P$3094))+1} -> 1 | R11: =(Q11*100000)+#REF! -> #REF! | S11: {=SUMPRODUCT(($G$2:$G$3094=G11)*(R11>$R$2:$R$3094))+1} -> #REF! | T11: =_xlfn.CONCAT(IF(M11="Flat",UPPER(I11),I11)," ",IF(J11="Evening","†",IF(J11="Floodlit","#",""))) -> Plumpton | U11: 0 | V11: NULL | W11: =YEAR(G11) -> 2023
A12: =IF(YEAR(G12)=2024,#REF!,"") | B12: =IF(YEAR(G12)=2025,#REF!,"") | C12: =J12&G12 -> Afternoon44929 | D12: =IF('by region'!$C$2="Any","Any",List!V12)&M12&IF('by region'!$I$2="Any","Any",N12)&G12 -> AnyFlatAny44929 | E12: =IF(I12=#REF!,List!G12,"") -> #REF! | F12: =G12&S12 -> #REF! | G12: 44929 | H12: Tuesday | I12: Chelmsford City | J12: Afternoon | K12: Independent | L12: South | M12: Flat | N12: AWT | O12: National/BHA | P12: =IF(J12="Afternoon",1,IF(J12="Evening",2,IF(J12="Floodlit",3,4))) -> 1 | Q12: {=SUMPRODUCT(($G$2:$G$3094=G12)*(P12>$P$2:$P$3094))+1} -> 1 | R12: =(Q12*100000)+#REF! -> #REF! | S12: {=SUMPRODUCT(($G$2:$G$3094=G12)*(R12>$R$2:$R$3094))+1} -> #REF! | T12: =_xlfn.CONCAT(IF(M12="Flat",UPPER(I12),I12)," ",IF(J12="Evening","†",IF(J12="Floodlit","#",""))) -> CHELMSFORD CITY | U12: 0 | V12: NULL | W12: =YEAR(G12) -> 2023
A13: =IF(YEAR(G13)=2024,#REF!,"") | B13: =IF(YEAR(G13)=2025,#REF!,"") | C13: =J13&G13 -> Floodlit44929 | D13: =IF('by region'!$C$2="Any","Any",List!V13)&M13&IF('by region'!$I$2="Any","Any",N13)&G13 -> AnyFlatAny44929 | E13: =IF(I13=#REF!,List!G13,"") -> #REF! | F13: =G13&S13 -> #REF! | G13: 44929 | H13: Tuesday | I13: Wolverhampton | J13: Floodlit | K13: ARC | L13: Midlands | M13: Flat | N13: AWT | O13: National/BHA Floodlit | P13: =IF(J13="Afternoon",1,IF(J13="Evening",2,IF(J13="Floodlit",3,4))) -> 3 | Q13: {=SUMPRODUCT(($G$2:$G$3094=G13)*(P13>$P$2:$P$3094))+1} -> 3 | R13: =(Q13*100000)+#REF! -> #REF! | S13: {=SUMPRODUCT(($G$2:$G$3094=G13)*(R13>$R$2:$R$3094))+1} -> #REF! | T13: =_xlfn.CONCAT(IF(M13="Flat",UPPER(I13),I13)," ",IF(J13="Evening","†",IF(J13="Floodlit","#",""))) -> WOLVERHAMPTON # | U13: 0 | V13: South | W13: =YEAR(G13) -> 2023
... A348: =IF(YEAR(G348)=2024,#REF!,"") | B348: =IF(YEAR(G348)=2025,#REF!,"") | C348: =J348&G348 -> Afternoon45024 | D348: =IF('by region'!$C$2="Any","Any",List!V348)&M348&IF('by region'!$I$2="Any","Any",N348)&G348 -> AnyJumpAny45024 | E348: =IF(I348=#REF!,List!G348,"") -> #REF! | F348: =G348&S348 -> #REF! | G348: 45024 | H348: Saturday | I348: Newton Abbot | J348: Afternoon | K348: Independent | L348: South | M348: Jump | N348: Turf | O348: Racecourse/Normal | P348: =IF(J348="Afternoon",1,IF(J348="Evening",2,IF(J348="Floodlit",3,4))) -> 1 | Q348: {=SUMPRODUCT(($G$2:$G$3094=G348)*(P348>$P$2:$P$3094))+1} -> 1 | R348: =(Q348*100000)+#REF! -> #REF! | S348: {=SUMPRODUCT(($G$2:$G$3094=G348)*(R348>$R$2:$R$3094))+1} -> #REF! | T348: =_xlfn.CONCAT(IF(M348="Flat",UPPER(I348),I348)," ",IF(J348="Evening","†",IF(J348="Floodlit","#",""))) -> Newton Abbot | U348: 0 | V348: South | W348: =YEAR(G348) -> 2023
A349: =IF(YEAR(G349)=2024,#REF!,"") | B349: =IF(YEAR(G349)=2025,#REF!,"") | C349: =J349&G349 -> Afternoon45024 | D349: =IF('by region'!$C$2="Any","Any",List!V349)&M349&IF('by region'!$I$2="Any","Any",N349)&G349 -> AnyFlatAny45024 | F349: =G349&S349 -> #REF! | G349: 45024 | H349: Saturday | I349: Musselburgh | J349: Afternoon | K349: Independent | L349: North | M349: Flat | N349: Turf | O349: National/BHA | P349: =IF(J349="Afternoon",1,IF(J349="Evening",2,IF(J349="Floodlit",3,4))) -> 1 | Q349: {=SUMPRODUCT(($G$2:$G$3094=G349)*(P349>$P$2:$P$3094))+1} -> 1 | R349: =(Q349*100000)+#REF! -> #REF! | S349: {=SUMPRODUCT(($G$2:$G$3094=G349)*(R349>$R$2:$R$3094))+1} -> #REF! | T349: =_xlfn.CONCAT(IF(M349="Flat",UPPER(I349),I349)," ",IF(J349="Evening","†",IF(J349="Floodlit","#",""))) -> MUSSELBURGH | U349: 0 | V349: North | W349: =YEAR(G349) -> 2023
A350: =IF(YEAR(G350)=2024,#REF!,"") | B350: =IF(YEAR(G350)=2025,#REF!,"") | C350: =J350&G350 -> Afternoon45025 | D350: =IF('by region'!$C$2="Any","Any",List!V350)&M350&IF('by region'!$I$2="Any","Any",N350)&G350 -> AnyFlatAny45025 | E350: =IF(I350=#REF!,List!G350,"") -> #REF! | F350: =G350&S350 -> #REF! | G350: 45025 | H350: Sunday | I350: Southwell | J350: Afternoon | K350: ARC | L350: Midlands | M350: Flat | N350: AWT | O350: Racecourse/Normal | P350: =IF(J350="Afternoon",1,IF(J350="Evening",2,IF(J350="Floodlit",3,4))) -> 1 | Q350: {=SUMPRODUCT(($G$2:$G$3094=G350)*(P350>$P$2:$P$3094))+1} -> 1 | R350: =(Q350*100000)+#REF! -> #REF! | S350: {=SUMPRODUCT(($G$2:$G$3094=G350)*(R350>$R$2:$R$3094))+1} -> #REF! | T350: =_xlfn.CONCAT(IF(M350="Flat",UPPER(I350),I350)," ",IF(J350="Evening","†",IF(J350="Floodlit","#",""))) -> SOUTHWELL | U350: 0 | V350: North | W350: =YEAR(G350) -> 2023
A351: =IF(YEAR(G351)=2024,#REF!,"") | B351: =IF(YEAR(G351)=2025,#REF!,"") | C351: =J351&G351 -> Afternoon45025 | D351: =IF('by region'!$C$2="Any","Any",List!V351)&M351&IF('by region'!$I$2="Any","Any",N351)&G351 -> AnyJumpAny45025 | E351: =IF(I351=#REF!,List!G351,"") -> #REF! | F351: =G351&S351 -> #REF! | G351: 45025 | H351: Sunday | I351: Ffos Las | J351: Afternoon | K351: ARC | L351: South | M351: Jump | N351: Turf | O351: Racecourse/Normal | P351: =IF(J351="Afternoon",1,IF(J351="Evening",2,IF(J351="Floodlit",3,4))) -> 1 | Q351: {=SUMPRODUCT(($G$2:$G$3094=G351)*(P351>$P$2:$P$3094))+1} -> 1 | R351: =(Q351*100000)+#REF! -> #REF! | S351: {=SUMPRODUCT(($G$2:$G$3094=G351)*(R351>$R$2:$R$3094))+1} -> #REF! | T351: =_xlfn.CONCAT(IF(M351="Flat",UPPER(I351),I351)," ",IF(J351="Evening","†",IF(J351="Floodlit","#",""))) -> Ffos Las | U351: 0 | V351: Midlands | W351: =YEAR(G351) -> 2023
A352: =IF(YEAR(G352)=2024,#REF!,"") | B352: =IF(YEAR(G352)=2025,#REF!,"") | C352: =J352&G352 -> Afternoon45025 | D352: =IF('by region'!$C$2="Any","Any",List!V352)&M352&IF('by region'!$I$2="Any","Any",N352)&G352 -> AnyJumpAny45025 | E352: =IF(I352=#REF!,List!G352,"") -> #REF! | F352: =G352&S352 -> #REF! | G352: 45025 | H352: Sunday | I352: Market Rasen | J352: Afternoon | K352: JCR | L352: Midlands | M352: Jump | N352: Turf | O352: Racecourse/Normal | P352: =IF(J352="Afternoon",1,IF(J352="Evening",2,IF(J352="Floodlit",3,4))) -> 1 | Q352: {=SUMPRODUCT(($G$2:$G$3094=G352)*(P352>$P$2:$P$3094))+1} -> 1 | R352: =(Q352*100000)+#REF! -> #REF! | S352: {=SUMPRODUCT(($G$2:$G$3094=G352)*(R352>$R$2:$R$3094))+1} -> #REF! | T352: =_xlfn.CONCAT(IF(M352="Flat",UPPER(I352),I352)," ",IF(J352="Evening","†",IF(J352="Floodlit","#",""))) -> Market Rasen | U352: 0 | V352: South | W352: =YEAR(G352) -> 2023
A353: =IF(YEAR(G353)=2024,#REF!,"") | B353: =IF(YEAR(G353)=2025,#REF!,"") | C353: =J353&G353 -> Afternoon45025 | D353: =IF('by region'!$C$2="Any","Any",List!V353)&M353&IF('by region'!$I$2="Any","Any",N353)&G353 -> AnyJumpAny45025 | E353: =IF(I353=#REF!,List!G353,"") -> #REF! | F353: =G353&S353 -> #REF! | G353: 45025 | H353: Sunday | I353: Plumpton | J353: Afternoon | K353: Independent | L353: South | M353: Jump | N353: Turf | O353: Racecourse/Normal | P353: =IF(J353="Afternoon",1,IF(J353="Evening",2,IF(J353="Floodlit",3,4))) -> 1 | Q353: {=SUMPRODUCT(($G$2:$G$3094=G353)*(P353>$P$2:$P$3094))+1} -> 1 | R353: =(Q353*100000)+#REF! -> #REF! | S353: {=SUMPRODUCT(($G$2:$G$3094=G353)*(R353>$R$2:$R$3094))+1} -> #REF! | T353: =_xlfn.CONCAT(IF(M353="Flat",UPPER(I353),I353)," ",IF(J353="Evening","†",IF(J353="Floodlit","#",""))) -> Plumpton | U353: 0 | V353: North | W353: =YEAR(G353) -> 2023
A354: =IF(YEAR(G354)=2024,#REF!,"") | B354: =IF(YEAR(G354)=2025,#REF!,"") | C354: =J354&G354 -> Afternoon45026 | D354: =IF('by region'!$C$2="Any","Any",List!V354)&M354&IF('by region'!$I$2="Any","Any",N354)&G354 -> AnyFlatAny45026 | E354: =IF(I354=#REF!,List!G354,"") -> #REF! | F354: =G354&S354 -> #REF! | G354: 45026 | H354: Monday | I354: Wolverhampton | J354: Afternoon | K354: ARC | L354: Midlands | M354: Flat | N354: AWT | O354: Racecourse/Normal | P354: =IF(J354="Afternoon",1,IF(J354="Evening",2,IF(J354="Floodlit",3,4))) -> 1 | Q354: {=SUMPRODUCT(($G$2:$G$3094=G354)*(P354>$P$2:$P$3094))+1} -> 1 | R354: =(Q354*100000)+#REF! -> #REF! | S354: {=SUMPRODUCT(($G$2:$G$3094=G354)*(R354>$R$2:$R$3094))+1} -> #REF! | T354: =_xlfn.CONCAT(IF(M354="Flat",UPPER(I354),I354)," ",IF(J354="Evening","†",IF(J354="Floodlit","#",""))) -> WOLVERHAMPTON | U354: 0 | V354: Midlands | W354: =YEAR(G354) -> 2023
A355: =IF(YEAR(G355)=2024,#REF!,"") | B355: =IF(YEAR(G355)=2025,#REF!,"") | C355: =J355&G355 -> Afternoon45026 | D355: =IF('by region'!$C$2="Any","Any",List!V355)&M355&IF('by region'!$I$2="Any","Any",N355)&G355 -> AnyFlatAny45026 | E355: =IF(I355=#REF!,List!G355,"") -> #REF! | F355: =G355&S355 -> #REF! | G355: 45026 | H355: Monday | I355: Redcar | J355: Afternoon | K355: Independent | L355: North | M355: Flat | N355: Turf | O355: Racecourse/Normal | P355: =IF(J355="Afternoon",1,IF(J355="Evening",2,IF(J355="Floodlit",3,4))) -> 1 | Q355: {=SUMPRODUCT(($G$2:$G$3094=G355)*(P355>$P$2:$P$3094))+1} -> 1 | R355: =(Q355*100000)+#REF! -> #REF! | S355: {=SUMPRODUCT(($G$2:$G$3094=G355)*(R355>$R$2:$R$3094))+1} -> #REF! | T355: =_xlfn.CONCAT(IF(M355="Flat",UPPER(I355),I355)," ",IF(J355="Evening","†",IF(J355="Floodlit","#",""))) -> REDCAR | U355: 0 | V355: NULL | W355: =YEAR(G355) -> 2023
A356: =IF(YEAR(G356)=2024,#REF!,"") | B356: =IF(YEAR(G356)=2025,#REF!,"") | C356: =J356&G356 -> Afternoon45026 | D356: =IF('by region'!$C$2="Any","Any",List!V356)&M356&IF('by region'!$I$2="Any","Any",N356)&G356 -> AnyJumpAny45026 | E356: =IF(I356=#REF!,List!G356,"") -> #REF! | F356: =G356&S356 -> #REF! | G356: 45026 | H356: Monday | I356: Chepstow | J356: Afternoon | K356: ARC | L356: South | M356: Jump | N356: Turf | O356: Racecourse/Normal | P356: =IF(J356="Afternoon",1,IF(J356="Evening",2,IF(J356="Floodlit",3,4))) -> 1 | Q356: {=SUMPRODUCT(($G$2:$G$3094=G356)*(P356>$P$2:$P$3094))+1} -> 1 | R356: =(Q356*100000)+#REF! -> #REF! | S356: {=SUMPRODUCT(($G$2:$G$3094=G356)*(R356>$R$2:$R$3094))+1} -> #REF! | T356: =_xlfn.CONCAT(IF(M356="Flat",UPPER(I356),I356)," ",IF(J356="Evening","†",IF(J356="Floodlit","#",""))) -> Chepstow | U356: 0 | V356: North | W356: =YEAR(G356) -> 2023
A357: =IF(YEAR(G357)=2024,#REF!,"") | B357: =IF(YEAR(G357)=2025,#REF!,"") | C357: =J357&G357 -> Afternoon45026 | D357: =IF('by region'!$C$2="Any","Any",List!V357)&M357&IF('by region'!$I$2="Any","Any",N357)&G357 -> AnyJumpAny45026 | E357: =IF(I357=#REF!,List!G357,"") -> #REF! | F357: =G357&S357 -> #REF! | G357: 45026 | H357: Monday | I357: Fakenham | J357: Afternoon | K357: Independent | L357: Midlands | M357: Jump | N357: Turf | O357: Racecourse/Normal | P357: =IF(J357="Afternoon",1,IF(J357="Evening",2,IF(J357="Floodlit",3,4))) -> 1 | Q357: {=SUMPRODUCT(($G$2:$G$3094=G357)*(P357>$P$2:$P$3094))+1} -> 1 | R357: =(Q357*100000)+#REF! -> #REF! | S357: {=SUMPRODUCT(($G$2:$G$3094=G357)*(R357>$R$2:$R$3094))+1} -> #REF! | T357: =_xlfn.CONCAT(IF(M357="Flat",UPPER(I357),I357)," ",IF(J357="Evening","†",IF(J357="Floodlit","#",""))) -> Fakenham | U357: 0 | V357: Midlands | W357: =YEAR(G357) -> 2023
A358: =IF(YEAR(G358)=2024,#REF!,"") | B358: =IF(YEAR(G358)=2025,#REF!,"") | C358: =J358&G358 -> Afternoon45026 | D358: =IF('by region'!$C$2="Any","Any",List!V358)&M358&IF('by region'!$I$2="Any","Any",N358)&G358 -> AnyJumpAny45026 | E358: =IF(I358=#REF!,List!G358,"") -> #REF! | F358: =G358&S358 -> #REF! | G358: 45026 | H358: Monday | I358: Huntingdon | J358: Afternoon | K358: JCR | L358: Midlands | M358: Jump | N358: Turf | O358: Racecourse/Normal | P358: =IF(J358="Afternoon",1,IF(J358="Evening",2,IF(J358="Floodlit",3,4))) -> 1 | Q358: {=SUMPRODUCT(($G$2:$G$3094=G358)*(P358>$P$2:$P$3094))+1} -> 1 | R358: =(Q358*100000)+#REF! -> #REF! | S358: {=SUMPRODUCT(($G$2:$G$3094=G358)*(R358>$R$2:$R$3094))+1} -> #REF! | T358: =_xlfn.CONCAT(IF(M358="Flat",UPPER(I358),I358)," ",IF(J358="Evening","†",IF(J358="Floodlit","#",""))) -> Huntingdon | U358: 0 | V358: Midlands | W358: =YEAR(G358) -> 2023
A359: =IF(YEAR(G359)=2024,#REF!,"") | B359: =IF(YEAR(G359)=2025,#REF!,"") | C359: =J359&G359 -> Afternoon45026 | D359: =IF('by region'!$C$2="Any","Any",List!V359)&M359&IF('by region'!$I$2="Any","Any",N359)&G359 -> AnyJumpAny45026 | E359: =IF(I359=#REF!,List!G359,"") -> #REF! | F359: =G359&S359 -> #REF! | G359: 45026 | H359: Monday | I359: Plumpton | J359: Afternoon | K359: Independent | L359: South | M359: Jump | N359: Turf | O359: Racecourse/Normal | P359: =IF(J359="Afternoon",1,IF(J359="Evening",2,IF(J359="Floodlit",3,4))) -> 1 | Q359: {=SUMPRODUCT(($G$2:$G$3094=G359)*(P359>$P$2:$P$3094))+1} -> 1 | R359: =(Q359*100000)+#REF! -> #REF! | S359: {=SUMPRODUCT(($G$2:$G$3094=G359)*(R359>$R$2:$R$3094))+1} -> #REF! | T359: =_xlfn.CONCAT(IF(M359="Flat",UPPER(I359),I359)," ",IF(J359="Evening","†",IF(J359="Floodlit","#",""))) -> Plumpton | U359: 0 | V359: North | W359: =YEAR(G359) -> 2023
A360: =IF(YEAR(G360)=2024,#REF!,"") | B360: =IF(YEAR(G360)=2025,#REF!,"") | C360: =J360&G360 -> Floodlit45027 | D360: =IF('by region'!$C$2="Any","Any",List!V360)&M360&IF('by region'!$I$2="Any","Any",N360)&G360 -> AnyFlatAny45027 | E360: =IF(I360=#REF!,List!G360,"") -> #REF! | F360: =G360&S360 -> #REF! | G360: 45027 | H360: Tuesday | I360: Wolverhampton | J360: Floodlit | K360: ARC | L360: Midlands | M360: Flat | N360: AWT | O360: Racecourse/Normal | P360: =IF(J360="Afternoon",1,IF(J360="Evening",2,IF(J360="Floodlit",3,4))) -> 3 | Q360: {=SUMPRODUCT(($G$2:$G$3094=G360)*(P360>$P$2:$P$3094))+1} -> 3 | R360: =(Q360*100000)+#REF! -> #REF! | S360: {=SUMPRODUCT(($G$2:$G$3094=G360)*(R360>$R$2:$R$3094))+1} -> #REF! | T360: =_xlfn.CONCAT(IF(M360="Flat",UPPER(I360),I360)," ",IF(J360="Evening","†",IF(J360="Floodlit","#",""))) -> WOLVERHAMPTON # | U360: 0 | V360: NULL | W360: =YEAR(G360) -> 2023
A361: =IF(YEAR(G361)=2024,#REF!,"") | B361: =IF(YEAR(G361)=2025,#REF!,"") | C361: =J361&G361 -> Afternoon45027 | D361: =IF('by region'!$C$2="Any","Any",List!V361)&M361&IF('by region'!$I$2="Any","Any",N361)&G361 -> AnyFlatAny45027 | E361: =IF(I361=#REF!,List!G361,"") -> #REF! | F361: =G361&S361 -> #REF! | G361: 45027 | H361: Tuesday | I361: Pontefract | J361: Afternoon | K361: Independent | L361: North | M361: Flat | N361: Turf | O361: Racecourse/Normal | P361: =IF(J361="Afternoon",1,IF(J361="Evening",2,IF(J361="Floodlit",3,4))) -> 1 | Q361: {=SUMPRODUCT(($G$2:$G$3094=G361)*(P361>$P$2:$P$3094))+1} -> 1 | R361: =(Q361*100000)+#REF! -> #REF! | S361: {=SUMPRODUCT(($G$2:$G$3094=G361)*(R361>$R$2:$R$3094))+1} -> #REF! | T361: =_xlfn.CONCAT(IF(M361="Flat",UPPER(I361),I361)," ",IF(J361="Evening","†",IF(J361="Floodlit","#",""))) -> PONTEFRACT | U361: 0 | V361: South | W361: =YEAR(G361) -> 2023
... A970: =IF(YEAR(G970)=2024,#REF!,"") | B970: =IF(YEAR(G970)=2025,#REF!,"") | C970: =J970&G970 -> Evening45159 | D970: =IF('by region'!$C$2="Any","Any",List!V970)&M970&IF('by region'!$I$2="Any","Any",N970)&G970 -> AnyFlatAny45159 | E970: =IF(I970=#REF!,List!G970,"") -> #REF! | F970: =G970&S970 -> #REF! | G970: 45159 | H970: Monday | I970: Windsor | J970: Evening | K970: ARC | L970: South | M970: Flat | N970: Turf | O970: Racecourse/Normal | P970: =IF(J970="Afternoon",1,IF(J970="Evening",2,IF(J970="Floodlit",3,4))) -> 2 | Q970: {=SUMPRODUCT(($G$2:$G$3094=G970)*(P970>$P$2:$P$3094))+1} -> 3 | R970: =(Q970*100000)+#REF! -> #REF! | S970: {=SUMPRODUCT(($G$2:$G$3094=G970)*(R970>$R$2:$R$3094))+1} -> #REF! | T970: =_xlfn.CONCAT(IF(M970="Flat",UPPER(I970),I970)," ",IF(J970="Evening","†",IF(J970="Floodlit","#",""))) -> WINDSOR † | U970: 0 | V970: South | W970: =YEAR(G970) -> 2023
A971: =IF(YEAR(G971)=2024,#REF!,"") | B971: =IF(YEAR(G971)=2025,#REF!,"") | C971: =J971&G971 -> Afternoon45159 | D971: =IF('by region'!$C$2="Any","Any",List!V971)&M971&IF('by region'!$I$2="Any","Any",N971)&G971 -> AnyFlatAny45159 | E971: =IF(I971=#REF!,List!G971,"") -> #REF! | F971: =G971&S971 -> 451592 | G971: 45159 | H971: Monday | I971: Brighton | J971: Afternoon | K971: ARC | L971: South | M971: Flat | N971: Turf | O971: Racecourse/Normal | P971: =IF(J971="Afternoon",1,IF(J971="Evening",2,IF(J971="Floodlit",3,4))) -> 1 | Q971: {=SUMPRODUCT(($G$2:$G$3094=G971)*(P971>$P$2:$P$3094))+1} -> 1 | R971: =(Q971*100000)+#REF! -> #REF! | S971: 2 | T971: =_xlfn.CONCAT(IF(M971="Flat",UPPER(I971),I971)," ",IF(J971="Evening","†",IF(J971="Floodlit","#",""))) -> BRIGHTON | U971: 0 | V971: NULL | W971: =YEAR(G971) -> 2023
A972: =IF(YEAR(G972)=2024,#REF!,"") | B972: =IF(YEAR(G972)=2025,#REF!,"") | C972: =J972&G972 -> Evening45159 | D972: =IF('by region'!$C$2="Any","Any",List!V972)&M972&IF('by region'!$I$2="Any","Any",N972)&G972 -> AnyJumpAny45159 | E972: =IF(I972=#REF!,List!G972,"") -> #REF! | F972: =G972&S972 -> #REF! | G972: 45159 | H972: Monday | I972: Bangor-On-Dee | J972: Evening | K972: Independent | L972: Midlands | M972: Jump | N972: Turf | O972: Racecourse/Normal | P972: =IF(J972="Afternoon",1,IF(J972="Evening",2,IF(J972="Floodlit",3,4))) -> 2 | Q972: {=SUMPRODUCT(($G$2:$G$3094=G972)*(P972>$P$2:$P$3094))+1} -> 3 | R972: =(Q972*100000)+#REF! -> #REF! | S972: {=SUMPRODUCT(($G$2:$G$3094=G972)*(R972>$R$2:$R$3094))+1} -> #REF! | T972: =_xlfn.CONCAT(IF(M972="Flat",UPPER(I972),I972)," ",IF(J972="Evening","†",IF(J972="Floodlit","#",""))) -> Bangor-On-Dee † | U972: 0 | V972: North | W972: =YEAR(G972) -> 2023
A973: =IF(YEAR(G973)=2024,#REF!,"") | B973: =IF(YEAR(G973)=2025,#REF!,"") | C973: =J973&G973 -> Evening45160 | D973: =IF('by region'!$C$2="Any","Any",List!V973)&M973&IF('by region'!$I$2="Any","Any",N973)&G973 -> AnyJumpAny45160 | E973: =IF(I973=#REF!,List!G973,"") -> #REF! | F973: =G973&S973 -> #REF! | G973: 45160 | H973: Tuesday | I973: Worcester | J973: Evening | K973: ARC | L973: Midlands | M973: Jump | N973: Turf | O973: National/BHA | P973: =IF(J973="Afternoon",1,IF(J973="Evening",2,IF(J973="Floodlit",3,4))) -> 2 | Q973: {=SUMPRODUCT(($G$2:$G$3094=G973)*(P973>$P$2:$P$3094))+1} -> 2 | R973: =(Q973*100000)+#REF! -> #REF! | S973: {=SUMPRODUCT(($G$2:$G$3094=G973)*(R973>$R$2:$R$3094))+1} -> #REF! | T973: =_xlfn.CONCAT(IF(M973="Flat",UPPER(I973),I973)," ",IF(J973="Evening","†",IF(J973="Floodlit","#",""))) -> Worcester † | U973: 0 | V973: Midlands | W973: =YEAR(G973) -> 2023
A974: =IF(YEAR(G974)=2024,#REF!,"") | B974: =IF(YEAR(G974)=2025,#REF!,"") | C974: =J974&G974 -> Afternoon45160 | D974: =IF('by region'!$C$2="Any","Any",List!V974)&M974&IF('by region'!$I$2="Any","Any",N974)&G974 -> AnyJumpAny45160 | E974: =IF(I974=#REF!,List!G974,"") -> #REF! | F974: =G974&S974 -> #REF! | G974: 45160 | H974: Tuesday | I974: Newton Abbot | J974: Afternoon | K974: Independent | L974: South | M974: Jump | N974: Turf | O974: Racecourse/Normal | P974: =IF(J974="Afternoon",1,IF(J974="Evening",2,IF(J974="Floodlit",3,4))) -> 1 | Q974: {=SUMPRODUCT(($G$2:$G$3094=G974)*(P974>$P$2:$P$3094))+1} -> 1 | R974: =(Q974*100000)+#REF! -> #REF! | S974: {=SUMPRODUCT(($G$2:$G$3094=G974)*(R974>$R$2:$R$3094))+1} -> #REF! | T974: =_xlfn.CONCAT(IF(M974="Flat",UPPER(I974),I974)," ",IF(J974="Evening","†",IF(J974="Floodlit","#",""))) -> Newton Abbot | U974: 0 | V974: Midlands | W974: =YEAR(G974) -> 2023
A975: =IF(YEAR(G975)=2024,#REF!,"") | B975: =IF(YEAR(G975)=2025,#REF!,"") | C975: =J975&G975 -> Evening45161 | D975: =IF('by region'!$C$2="Any","Any",List!V975)&M975&IF('by region'!$I$2="Any","Any",N975)&G975 -> AnyFlatAny45161 | E975: =IF(I975=#REF!,List!G975,"") -> #REF! | F975: =G975&S975 -> #REF! | G975: 45161 | H975: Wednesday | I975: Kempton Park | J975: Evening | K975: JCR | L975: South | M975: Flat | N975: AWT | O975: Racecourse/Normal | P975: =IF(J975="Afternoon",1,IF(J975="Evening",2,IF(J975="Floodlit",3,4))) -> 2 | Q975: {=SUMPRODUCT(($G$2:$G$3094=G975)*(P975>$P$2:$P$3094))+1} -> 4 | R975: =(Q975*100000)+#REF! -> #REF! | S975: {=SUMPRODUCT(($G$2:$G$3094=G975)*(R975>$R$2:$R$3094))+1} -> #REF! | T975: =_xlfn.CONCAT(IF(M975="Flat",UPPER(I975),I975)," ",IF(J975="Evening","†",IF(J975="Floodlit","#",""))) -> KEMPTON PARK † | U975: 0 | V975: North | W975: =YEAR(G975) -> 2023
A976: =IF(YEAR(G976)=2024,#REF!,"") | B976: =IF(YEAR(G976)=2025,#REF!,"") | C976: =J976&G976 -> Evening45161 | D976: =IF('by region'!$C$2="Any","Any",List!V976)&M976&IF('by region'!$I$2="Any","Any",N976)&G976 -> AnyFlatAny45161 | E976: =IF(I976=#REF!,List!G976,"") -> #REF! | F976: =G976&S976 -> #REF! | G976: 45161 | H976: Wednesday | I976: Leicester | J976: Evening | K976: Independent | L976: Midlands | M976: Flat | N976: Turf | O976: National/BHA | P976: =IF(J976="Afternoon",1,IF(J976="Evening",2,IF(J976="Floodlit",3,4))) -> 2 | Q976: {=SUMPRODUCT(($G$2:$G$3094=G976)*(P976>$P$2:$P$3094))+1} -> 4 | R976: =(Q976*100000)+#REF! -> #REF! | S976: {=SUMPRODUCT(($G$2:$G$3094=G976)*(R976>$R$2:$R$3094))+1} -> #REF! | T976: =_xlfn.CONCAT(IF(M976="Flat",UPPER(I976),I976)," ",IF(J976="Evening","†",IF(J976="Floodlit","#",""))) -> LEICESTER † | U976: 0 | V976: North | W976: =YEAR(G976) -> 2023
A977: =IF(YEAR(G977)=2024,#REF!,"") | B977: =IF(YEAR(G977)=2025,#REF!,"") | C977: =J977&G977 -> Afternoon45161 | D977: =IF('by region'!$C$2="Any","Any",List!V977)&M977&IF('by region'!$I$2="Any","Any",N977)&G977 -> AnyFlatAny45161 | E977: =IF(I977=#REF!,List!G977,"") -> #REF! | F977: =G977&S977 -> #REF! | G977: 45161 | H977: Wednesday | I977: Bath | J977: Afternoon | K977: ARC | L977: South | M977: Flat | N977: Turf | O977: Racecourse/Normal | P977: =IF(J977="Afternoon",1,IF(J977="Evening",2,IF(J977="Floodlit",3,4))) -> 1 | Q977: {=SUMPRODUCT(($G$2:$G$3094=G977)*(P977>$P$2:$P$3094))+1} -> 1 | R977: =(Q977*100000)+#REF! -> #REF! | S977: {=SUMPRODUCT(($G$2:$G$3094=G977)*(R977>$R$2:$R$3094))+1} -> #REF! | T977: =_xlfn.CONCAT(IF(M977="Flat",UPPER(I977),I977)," ",IF(J977="Evening","†",IF(J977="Floodlit","#",""))) -> BATH | U977: 0 | V977: North | W977: =YEAR(G977) -> 2023
A978: =IF(YEAR(G978)=2024,#REF!,"") | B978: =IF(YEAR(G978)=2025,#REF!,"") | C978: =J978&G978 -> Afternoon45161 | D978: =IF('by region'!$C$2="Any","Any",List!V978)&M978&IF('by region'!$I$2="Any","Any",N978)&G978 -> AnyFlatAny45161 | E978: =IF(I978=#REF!,List!G978,"") -> #REF! | F978: =G978&S978 -> #REF! | G978: 45161 | H978: Wednesday | I978: Carlisle | J978: Afternoon | K978: JCR | L978: North | M978: Flat | N978: Turf | O978: Racecourse/Normal | P978: =IF(J978="Afternoon",1,IF(J978="Evening",2,IF(J978="Floodlit",3,4))) -> 1 | Q978: {=SUMPRODUCT(($G$2:$G$3094=G978)*(P978>$P$2:$P$3094))+1} -> 1 | R978: =(Q978*100000)+#REF! -> #REF! | S978: {=SUMPRODUCT(($G$2:$G$3094=G978)*(R978>$R$2:$R$3094))+1} -> #REF! | T978: =_xlfn.CONCAT(IF(M978="Flat",UPPER(I978),I978)," ",IF(J978="Evening","†",IF(J978="Floodlit","#",""))) -> CARLISLE | U978: 0 | V978: Midlands | W978: =YEAR(G978) -> 2023
A979: =IF(YEAR(G979)=2024,#REF!,"") | B979: =IF(YEAR(G979)=2025,#REF!,"") | C979: =J979&G979 -> Afternoon45161 | D979: =IF('by region'!$C$2="Any","Any",List!V979)&M979&IF('by region'!$I$2="Any","Any",N979)&G979 -> AnyFlatAny45161 | E979: =IF(I979=#REF!,List!G979,"") -> #REF! | F979: =G979&S979 -> #REF! | G979: 45161 | H979: Wednesday | I979: York | J979: Afternoon | K979: Independent | L979: North | M979: Flat | N979: Turf | O979: Racecourse/Normal | P979: =IF(J979="Afternoon",1,IF(J979="Evening",2,IF(J979="Floodlit",3,4))) -> 1 | Q979: {=SUMPRODUCT(($G$2:$G$3094=G979)*(P979>$P$2:$P$3094))+1} -> 1 | R979: =(Q979*100000)+#REF! -> #REF! | S979: {=SUMPRODUCT(($G$2:$G$3094=G979)*(R979>$R$2:$R$3094))+1} -> #REF! | T979: =_xlfn.CONCAT(IF(M979="Flat",UPPER(I979),I979)," ",IF(J979="Evening","†",IF(J979="Floodlit","#",""))) -> YORK | U979: 0 | V979: North | W979: =YEAR(G979) -> 2023
A980: =IF(YEAR(G980)=2024,#REF!,"") | B980: =IF(YEAR(G980)=2025,#REF!,"") | C980: =J980&G980 -> Evening45162 | D980: =IF('by region'!$C$2="Any","Any",List!V980)&M980&IF('by region'!$I$2="Any","Any",N980)&G980 -> AnyFlatAny45162 | E980: =IF(I980=#REF!,List!G980,"") -> #REF! | F980: =G980&S980 -> #REF! | G980: 45162 | H980: Thursday | I980: Chelmsford City | J980: Evening | K980: Independent | L980: South | M980: Flat | N980: AWT | O980: Racecourse/Normal | P980: =IF(J980="Afternoon",1,IF(J980="Evening",2,IF(J980="Floodlit",3,4))) -> 2 | Q980: {=SUMPRODUCT(($G$2:$G$3094=G980)*(P980>$P$2:$P$3094))+1} -> 4 | R980: =(Q980*100000)+#REF! -> #REF! | S980: {=SUMPRODUCT(($G$2:$G$3094=G980)*(R980>$R$2:$R$3094))+1} -> #REF! | T980: =_xlfn.CONCAT(IF(M980="Flat",UPPER(I980),I980)," ",IF(J980="Evening","†",IF(J980="Floodlit","#",""))) -> CHELMSFORD CITY † | U980: 0 | V980: South | W980: =YEAR(G980) -> 2023
A981: =IF(YEAR(G981)=2024,#REF!,"") | B981: =IF(YEAR(G981)=2025,#REF!,"") | C981: =J981&G981 -> Afternoon45162 | D981: =IF('by region'!$C$2="Any","Any",List!V981)&M981&IF('by region'!$I$2="Any","Any",N981)&G981 -> AnyFlatAny45162 | E981: =IF(I981=#REF!,List!G981,"") -> #REF! | F981: =G981&S981 -> #REF! | G981: 45162 | H981: Thursday | I981: Chepstow | J981: Afternoon | K981: ARC | L981: South | M981: Flat | N981: Turf | O981: Racecourse/Normal | P981: =IF(J981="Afternoon",1,IF(J981="Evening",2,IF(J981="Floodlit",3,4))) -> 1 | Q981: {=SUMPRODUCT(($G$2:$G$3094=G981)*(P981>$P$2:$P$3094))+1} -> 1 | R981: =(Q981*100000)+#REF! -> #REF! | S981: {=SUMPRODUCT(($G$2:$G$3094=G981)*(R981>$R$2:$R$3094))+1} -> #REF! | T981: =_xlfn.CONCAT(IF(M981="Flat",UPPER(I981),I981)," ",IF(J981="Evening","†",IF(J981="Floodlit","#",""))) -> CHEPSTOW | U981: 0 | V981: North | W981: =YEAR(G981) -> 2023
A982: =IF(YEAR(G982)=2024,#REF!,"") | B982: =IF(YEAR(G982)=2025,#REF!,"") | C982: =J982&G982 -> Afternoon45162 | D982: =IF('by region'!$C$2="Any","Any",List!V982)&M982&IF('by region'!$I$2="Any","Any",N982)&G982 -> AnyFlatAny45162 | E982: =IF(I982=#REF!,List!G982,"") -> #REF! | F982: =G982&S982 -> #REF! | G982: 45162 | H982: Thursday | I982: York | J982: Afternoon | K982: Independent | L982: North | M982: Flat | N982: Turf | O982: Racecourse/Normal | P982: =IF(J982="Afternoon",1,IF(J982="Evening",2,IF(J982="Floodlit",3,4))) -> 1 | Q982: {=SUMPRODUCT(($G$2:$G$3094=G982)*(P982>$P$2:$P$3094))+1} -> 1 | R982: =(Q982*100000)+#REF! -> #REF! | S982: {=SUMPRODUCT(($G$2:$G$3094=G982)*(R982>$R$2:$R$3094))+1} -> #REF! | T982: =_xlfn.CONCAT(IF(M982="Flat",UPPER(I982),I982)," ",IF(J982="Evening","†",IF(J982="Floodlit","#",""))) -> YORK | U982: 0 | V982: North | W982: =YEAR(G982) -> 2023
...

Sheet Turf only
A1: 2024 lu | B1: 2025 lu | C1: Criteria LU | D1: Region LU | E1: Racecourse LU | F1: Overview LU | G1: Date | H1: Weekday | I1: Course | J1: Time | K1: CourseGroup | L1: Region | M1: Code | N1: Surface | O1: Type | P1: pn | Q1: pr | R1: adj_fId | S1: rn | T1: x | U1: Clash | V1: region | W1: Year
A2: =IF(YEAR(G2)=2024,#REF!,"") | B2: =IF(YEAR(G2)=2025,#REF!,"") | C2: =J2&G2 -> Afternoon44927 | D2: =IF('by region'!$C$2="Any","Any",'Turf only'!V2)&M2&IF('by region'!$I$2="Any","Any",N2)&G2 -> AnyJumpAny44927 | E2: =IF(I2=#REF!,'Turf only'!G2,"") -> #REF! | F2: =G2&S2 -> #REF! | G2: 44927 | H2: Sunday | I2: Catterick Bridge | J2: Afternoon | K2: Independent | L2: North | M2: Jump | N2: Turf | O2: Racecourse/Normal | P2: =IF(J2="Afternoon",1,IF(J2="Evening",2,IF(J2="Floodlit",3,4))) -> 1 | Q2: {=SUMPRODUCT(($G$2:$G$2765=G2)*(P2>$P$2:$P$2765))+1} -> 1 | R2: =(Q2*100000)+#REF! -> #REF! | S2: {=SUMPRODUCT(($G$2:$G$2765=G2)*(R2>$R$2:$R$2765))+1} -> #REF! | T2: =_xlfn.CONCAT(IF(M2="Flat",UPPER(I2),I2)," ",IF(J2="Evening","†",IF(J2="Floodlit","#",""))) -> Catterick Bridge | U2: 0 | V2: NULL | W2: =YEAR(G2) -> 2023
A3: =IF(YEAR(G3)=2024,#REF!,"") | B3: =IF(YEAR(G3)=2025,#REF!,"") | C3: =J3&G3 -> Afternoon44927 | D3: =IF('by region'!$C$2="Any","Any",'Turf only'!V3)&M3&IF('by region'!$I$2="Any","Any",N3)&G3 -> AnyJumpAny44927 | E3: =IF(I3=#REF!,'Turf only'!G3,"") -> #REF! | F3: =G3&S3 -> #REF! | G3: 44927 | H3: Sunday | I3: Cheltenham | J3: Afternoon | K3: JCR | L3: Midlands | M3: Jump | N3: Turf | O3: Racecourse/Normal | P3: =IF(J3="Afternoon",1,IF(J3="Evening",2,IF(J3="Floodlit",3,4))) -> 1 | Q3: {=SUMPRODUCT(($G$2:$G$2765=G3)*(P3>$P$2:$P$2765))+1} -> 1 | R3: =(Q3*100000)+#REF! -> #REF! | S3: {=SUMPRODUCT(($G$2:$G$2765=G3)*(R3>$R$2:$R$2765))+1} -> #REF! | T3: =_xlfn.CONCAT(IF(M3="Flat",UPPER(I3),I3)," ",IF(J3="Evening","†",IF(J3="Floodlit","#",""))) -> Cheltenham | U3: 0 | V3: South | W3: =YEAR(G3) -> 2023
A4: =IF(YEAR(G4)=2024,#REF!,"") | B4: =IF(YEAR(G4)=2025,#REF!,"") | C4: =J4&G4 -> Afternoon44927 | D4: =IF('by region'!$C$2="Any","Any",'Turf only'!V4)&M4&IF('by region'!$I$2="Any","Any",N4)&G4 -> AnyJumpAny44927 | E4: =IF(I4=#REF!,'Turf only'!G4,"") -> #REF! | F4: =G4&S4 -> #REF! | G4: 44927 | H4: Sunday | I4: Exeter | J4: Afternoon | K4: JCR | L4: South | M4: Jump | N4: Turf | O4: Racecourse/Normal | P4: =IF(J4="Afternoon",1,IF(J4="Evening",2,IF(J4="Floodlit",3,4))) -> 1 | Q4: {=SUMPRODUCT(($G$2:$G$2765=G4)*(P4>$P$2:$P$2765))+1} -> 1 | R4: =(Q4*100000)+#REF! -> #REF! | S4: {=SUMPRODUCT(($G$2:$G$2765=G4)*(R4>$R$2:$R$2765))+1} -> #REF! | T4: =_xlfn.CONCAT(IF(M4="Flat",UPPER(I4),I4)," ",IF(J4="Evening","†",IF(J4="Floodlit","#",""))) -> Exeter | U4: 0 | V4: Midlands | W4: =YEAR(G4) -> 2023
A5: =IF(YEAR(G5)=2024,#REF!,"") | B5: =IF(YEAR(G5)=2025,#REF!,"") | C5: =J5&G5 -> Afternoon44927 | D5: =IF('by region'!$C$2="Any","Any",'Turf only'!V5)&M5&IF('by region'!$I$2="Any","Any",N5)&G5 -> AnyJumpAny44927 | E5: =IF(I5=#REF!,'Turf only'!G5,"") -> #REF! | F5: =G5&S5 -> #REF! | G5: 44927 | H5: Sunday | I5: Fakenham | J5: Afternoon | K5: Independent | L5: Midlands | M5: Jump | N5: Turf | O5: National/BHA | P5: =IF(J5="Afternoon",1,IF(J5="Evening",2,IF(J5="Floodlit",3,4))) -> 1 | Q5: {=SUMPRODUCT(($G$2:$G$2765=G5)*(P5>$P$2:$P$2765))+1} -> 1 | R5: =(Q5*100000)+#REF! -> #REF! | S5: {=SUMPRODUCT(($G$2:$G$2765=G5)*(R5>$R$2:$R$2765))+1} -> #REF! | T5: =_xlfn.CONCAT(IF(M5="Flat",UPPER(I5),I5)," ",IF(J5="Evening","†",IF(J5="Floodlit","#",""))) -> Fakenham | U5: 0 | V5: North | W5: =YEAR(G5) -> 2023
A6: =IF(YEAR(G6)=2024,#REF!,"") | B6: =IF(YEAR(G6)=2025,#REF!,"") | C6: =J6&G6 -> Afternoon44927 | D6: =IF('by region'!$C$2="Any","Any",'Turf only'!V6)&M6&IF('by region'!$I$2="Any","Any",N6)&G6 -> AnyJumpAny44927 | E6: =IF(I6=#REF!,'Turf only'!G6,"") -> #REF! | F6: =G6&S6 -> #REF! | G6: 44927 | H6: Sunday | I6: Musselburgh | J6: Afternoon | K6: Independent | L6: North | M6: Jump | N6: Turf | O6: National/BHA | P6: =IF(J6="Afternoon",1,IF(J6="Evening",2,IF(J6="Floodlit",3,4))) -> 1 | Q6: {=SUMPRODUCT(($G$2:$G$2765=G6)*(P6>$P$2:$P$2765))+1} -> 1 | R6: =(Q6*100000)+#REF! -> #REF! | S6: {=SUMPRODUCT(($G$2:$G$2765=G6)*(R6>$R$2:$R$2765))+1} -> #REF! | T6: =_xlfn.CONCAT(IF(M6="Flat",UPPER(I6),I6)," ",IF(J6="Evening","†",IF(J6="Floodlit","#",""))) -> Musselburgh | U6: 0 | V6: NULL | W6: =YEAR(G6) -> 2023
A7: =IF(YEAR(G7)=2024,#REF!,"") | B7: =IF(YEAR(G7)=2025,#REF!,"") | C7: =J7&G7 -> Afternoon44928 | D7: =IF('by region'!$C$2="Any","Any",'Turf only'!V7)&M7&IF('by region'!$I$2="Any","Any",N7)&G7 -> AnyJumpAny44928 | E7: =IF(I7=#REF!,'Turf only'!G7,"") -> #REF! | F7: =G7&S7 -> #REF! | G7: 44928 | H7: Monday | I7: Ayr | J7: Afternoon | K7: Independent | L7: North | M7: Jump | N7: Turf | O7: Racecourse/Normal | P7: =IF(J7="Afternoon",1,IF(J7="Evening",2,IF(J7="Floodlit",3,4))) -> 1 | Q7: {=SUMPRODUCT(($G$2:$G$2765=G7)*(P7>$P$2:$P$2765))+1} -> 1 | R7: =(Q7*100000)+#REF! -> #REF! | S7: {=SUMPRODUCT(($G$2:$G$2765=G7)*(R7>$R$2:$R$2765))+1} -> #REF! | T7: =_xlfn.CONCAT(IF(M7="Flat",UPPER(I7),I7)," ",IF(J7="Evening","†",IF(J7="Floodlit","#",""))) -> Ayr | U7: 0 | V7: South | W7: =YEAR(G7) -> 2023
A8: =IF(YEAR(G8)=2024,#REF!,"") | B8: =IF(YEAR(G8)=2025,#REF!,"") | C8: =J8&G8 -> Afternoon44928 | D8: =IF('by region'!$C$2="Any","Any",'Turf only'!V8)&M8&IF('by region'!$I$2="Any","Any",N8)&G8 -> AnyJumpAny44928 | E8: =IF(I8=#REF!,'Turf only'!G8,"") -> #REF! | F8: =G8&S8 -> #REF! | G8: 44928 | H8: Monday | I8: Plumpton | J8: Afternoon | K8: Independent | L8: South | M8: Jump | N8: Turf | O8: Racecourse/Normal | P8: =IF(J8="Afternoon",1,IF(J8="Evening",2,IF(J8="Floodlit",3,4))) -> 1 | Q8: {=SUMPRODUCT(($G$2:$G$2765=G8)*(P8>$P$2:$P$2765))+1} -> 1 | R8: =(Q8*100000)+#REF! -> #REF! | S8: {=SUMPRODUCT(($G$2:$G$2765=G8)*(R8>$R$2:$R$2765))+1} -> #REF! | T8: =_xlfn.CONCAT(IF(M8="Flat",UPPER(I8),I8)," ",IF(J8="Evening","†",IF(J8="Floodlit","#",""))) -> Plumpton | U8: 1 | V8: North | W8: =YEAR(G8) -> 2023
A9: =IF(YEAR(G9)=2024,#REF!,"") | B9: =IF(YEAR(G9)=2025,#REF!,"") | C9: =J9&G9 -> Afternoon44929 | D9: =IF('by region'!$C$2="Any","Any",'Turf only'!V9)&M9&IF('by region'!$I$2="Any","Any",N9)&G9 -> AnyJumpAny44929 | E9: =IF(I9=#REF!,'Turf only'!G9,"") -> #REF! | F9: =G9&S9 -> #REF! | G9: 44929 | H9: Tuesday | I9: Musselburgh | J9: Afternoon | K9: Independent | L9: North | M9: Jump | N9: Turf | O9: National/BHA | P9: =IF(J9="Afternoon",1,IF(J9="Evening",2,IF(J9="Floodlit",3,4))) -> 1 | Q9: {=SUMPRODUCT(($G$2:$G$2765=G9)*(P9>$P$2:$P$2765))+1} -> 1 | R9: =(Q9*100000)+#REF! -> #REF! | S9: {=SUMPRODUCT(($G$2:$G$2765=G9)*(R9>$R$2:$R$2765))+1} -> #REF! | T9: =_xlfn.CONCAT(IF(M9="Flat",UPPER(I9),I9)," ",IF(J9="Evening","†",IF(J9="Floodlit","#",""))) -> Musselburgh | U9: 1 | V9: North | W9: =YEAR(G9) -> 2023
A10: =IF(YEAR(G10)=2024,#REF!,"") | B10: =IF(YEAR(G10)=2025,#REF!,"") | C10: =J10&G10 -> Afternoon44930 | D10: =IF('by region'!$C$2="Any","Any",'Turf only'!V10)&M10&IF('by region'!$I$2="Any","Any",N10)&G10 -> AnyJumpAny44930 | E10: =IF(I10=#REF!,'Turf only'!G10,"") -> #REF! | F10: =G10&S10 -> #REF! | G10: 44930 | H10: Wednesday | I10: Hereford | J10: Afternoon | K10: ARC | L10: Midlands | M10: Jump | N10: Turf | O10: Racecourse/Normal | P10: =IF(J10="Afternoon",1,IF(J10="Evening",2,IF(J10="Floodlit",3,4))) -> 1 | Q10: {=SUMPRODUCT(($G$2:$G$2765=G10)*(P10>$P$2:$P$2765))+1} -> 1 | R10: =(Q10*100000)+#REF! -> #REF! | S10: {=SUMPRODUCT(($G$2:$G$2765=G10)*(R10>$R$2:$R$2765))+1} -> #REF! | T10: =_xlfn.CONCAT(IF(M10="Flat",UPPER(I10),I10)," ",IF(J10="Evening","†",IF(J10="Floodlit","#",""))) -> Hereford | U10: 0 | V10: South | W10: =YEAR(G10) -> 2023
A11: =IF(YEAR(G11)=2024,#REF!,"") | B11: =IF(YEAR(G11)=2025,#REF!,"") | C11: =J11&G11 -> Afternoon44931 | D11: =IF('by region'!$C$2="Any","Any",'Turf only'!V11)&M11&IF('by region'!$I$2="Any","Any",N11)&G11 -> AnyJumpAny44931 | E11: =IF(I11=#REF!,'Turf only'!G11,"") -> #REF! | F11: =G11&S11 -> #REF! | G11: 44931 | H11: Thursday | I11: Ffos Las | J11: Afternoon | K11: ARC | L11: South | M11: Jump | N11: Turf | O11: National/BHA | P11: =IF(J11="Afternoon",1,IF(J11="Evening",2,IF(J11="Floodlit",3,4))) -> 1 | Q11: {=SUMPRODUCT(($G$2:$G$2765=G11)*(P11>$P$2:$P$2765))+1} -> 1 | R11: =(Q11*100000)+#REF! -> #REF! | S11: {=SUMPRODUCT(($G$2:$G$2765=G11)*(R11>$R$2:$R$2765))+1} -> #REF! | T11: =_xlfn.CONCAT(IF(M11="Flat",UPPER(I11),I11)," ",IF(J11="Evening","†",IF(J11="Floodlit","#",""))) -> Ffos Las | U11: 0 | V11: South | W11: =YEAR(G11) -> 2023
A12: =IF(YEAR(G12)=2024,#REF!,"") | B12: =IF(YEAR(G12)=2025,#REF!,"") | C12: =J12&G12 -> Afternoon44932 | D12: =IF('by region'!$C$2="Any","Any",'Turf only'!V12)&M12&IF('by region'!$I$2="Any","Any",N12)&G12 -> AnyJumpAny44932 | E12: =IF(I12=#REF!,'Turf only'!G12,"") -> #REF! | F12: =G12&S12 -> #REF! | G12: 44932 | H12: Friday | I12: Ludlow | J12: Afternoon | K12: Independent | L12: Midlands | M12: Jump | N12: Turf | O12: National/BHA | P12: =IF(J12="Afternoon",1,IF(J12="Evening",2,IF(J12="Floodlit",3,4))) -> 1 | Q12: {=SUMPRODUCT(($G$2:$G$2765=G12)*(P12>$P$2:$P$2765))+1} -> 1 | R12: =(Q12*100000)+#REF! -> #REF! | S12: {=SUMPRODUCT(($G$2:$G$2765=G12)*(R12>$R$2:$R$2765))+1} -> #REF! | T12: =_xlfn.CONCAT(IF(M12="Flat",UPPER(I12),I12)," ",IF(J12="Evening","†",IF(J12="Floodlit","#",""))) -> Ludlow | U12: 0 | V12: South | W12: =YEAR(G12) -> 2023
A13: =IF(YEAR(G13)=2024,#REF!,"") | B13: =IF(YEAR(G13)=2025,#REF!,"") | C13: =J13&G13 -> Afternoon44933 | D13: =IF('by region'!$C$2="Any","Any",'Turf only'!V13)&M13&IF('by region'!$I$2="Any","Any",N13)&G13 -> AnyJumpAny44933 | E13: =IF(I13=#REF!,'Turf only'!G13,"") -> #REF! | F13: =G13&S13 -> #REF! | G13: 44933 | H13: Saturday | I13: Newcastle | J13: Afternoon | K13: ARC | L13: North | M13: Jump | N13: Turf | O13: Racecourse/Normal | P13: =IF(J13="Afternoon",1,IF(J13="Evening",2,IF(J13="Floodlit",3,4))) -> 1 | Q13: {=SUMPRODUCT(($G$2:$G$2765=G13)*(P13>$P$2:$P$2765))+1} -> 1 | R13: =(Q13*100000)+#REF! -> #REF! | S13: {=SUMPRODUCT(($G$2:$G$2765=G13)*(R13>$R$2:$R$2765))+1} -> #REF! | T13: =_xlfn.CONCAT(IF(M13="Flat",UPPER(I13),I13)," ",IF(J13="Evening","†",IF(J13="Floodlit","#",""))) -> Newcastle | U13: 0 | V13: Midlands | W13: =YEAR(G13) -> 2023
... A19: =IF(YEAR(G19)=2024,#REF!,"") | B19: =IF(YEAR(G19)=2025,#REF!,"") | C19: =J19&G19 -> Afternoon44936 | D19: =IF('by region'!$C$2="Any","Any",'Turf only'!V19)&M19&IF('by region'!$I$2="Any","Any",N19)&G19 -> AnyJumpAny44936 | E19: =IF(I19=#REF!,'Turf only'!G19,"") -> #REF! | F19: =G19&S19 -> #REF! | G19: 44936 | H19: Tuesday | I19: Doncaster | J19: Afternoon | K19: ARC | L19: North | M19: Jump | N19: Turf | O19: National/BHA | P19: =IF(J19="Afternoon",1,IF(J19="Evening",2,IF(J19="Floodlit",3,4))) -> 1 | Q19: {=SUMPRODUCT(($G$2:$G$2765=G19)*(P19>$P$2:$P$2765))+1} -> 1 | R19: =(Q19*100000)+#REF! -> #REF! | S19: {=SUMPRODUCT(($G$2:$G$2765=G19)*(R19>$R$2:$R$2765))+1} -> #REF! | T19: =_xlfn.CONCAT(IF(M19="Flat",UPPER(I19),I19)," ",IF(J19="Evening","†",IF(J19="Floodlit","#",""))) -> Doncaster | U19: 0 | V19: South | W19: =YEAR(G19) -> 2023
A20: =IF(YEAR(G20)=2024,#REF!,"") | B20: =IF(YEAR(G20)=2025,#REF!,"") | C20: =J20&G20 -> Afternoon44936 | D20: =IF('by region'!$C$2="Any","Any",'Turf only'!V20)&M20&IF('by region'!$I$2="Any","Any",N20)&G20 -> AnyJumpAny44936 | F20: =G20&S20 -> #REF! | G20: 44936 | H20: Tuesday | I20: Exeter | J20: Afternoon | K20: JCR | L20: South | M20: Jump | N20: Turf | O20: National/BHA | P20: =IF(J20="Afternoon",1,IF(J20="Evening",2,IF(J20="Floodlit",3,4))) -> 1 | Q20: {=SUMPRODUCT(($G$2:$G$2765=G20)*(P20>$P$2:$P$2765))+1} -> 1 | R20: =(Q20*100000)+#REF! -> #REF! | S20: {=SUMPRODUCT(($G$2:$G$2765=G20)*(R20>$R$2:$R$2765))+1} -> #REF! | T20: =_xlfn.CONCAT(IF(M20="Flat",UPPER(I20),I20)," ",IF(J20="Evening","†",IF(J20="Floodlit","#",""))) -> Exeter | U20: 0 | V20: North | W20: =YEAR(G20) -> 2023
A21: =IF(YEAR(G21)=2024,#REF!,"") | B21: =IF(YEAR(G21)=2025,#REF!,"") | C21: =J21&G21 -> Afternoon44937 | D21: =IF('by region'!$C$2="Any","Any",'Turf only'!V21)&M21&IF('by region'!$I$2="Any","Any",N21)&G21 -> AnyJumpAny44937 | E21: =IF(I21=#REF!,'Turf only'!G21,"") -> #REF! | F21: =G21&S21 -> #REF! | G21: 44937 | H21: Wednesday | I21: Leicester | J21: Afternoon | K21: Independent | L21: Midlands | M21: Jump | N21: Turf | O21: Racecourse/Normal | P21: =IF(J21="Afternoon",1,IF(J21="Evening",2,IF(J21="Floodlit",3,4))) -> 1 | Q21: {=SUMPRODUCT(($G$2:$G$2765=G21)*(P21>$P$2:$P$2765))+1} -> 1 | R21: =(Q21*100000)+#REF! -> #REF! | S21: {=SUMPRODUCT(($G$2:$G$2765=G21)*(R21>$R$2:$R$2765))+1} -> #REF! | T21: =_xlfn.CONCAT(IF(M21="Flat",UPPER(I21),I21)," ",IF(J21="Evening","†",IF(J21="Floodlit","#",""))) -> Leicester | U21: 0 | V21: North | W21: =YEAR(G21) -> 2023
A22: =IF(YEAR(G22)=2024,#REF!,"") | B22: =IF(YEAR(G22)=2025,#REF!,"") | C22: =J22&G22 -> Afternoon44938 | D22: =IF('by region'!$C$2="Any","Any",'Turf only'!V22)&M22&IF('by region'!$I$2="Any","Any",N22)&G22 -> AnyJumpAny44938 | E22: =IF(I22=#REF!,'Turf only'!G22,"") -> #REF! | F22: =G22&S22 -> #REF! | G22: 44938 | H22: Thursday | I22: Bangor-On-Dee | J22: Afternoon | K22: Independent | L22: Midlands | M22: Jump | N22: Turf | O22: National/BHA | P22: =IF(J22="Afternoon",1,IF(J22="Evening",2,IF(J22="Floodlit",3,4))) -> 1 | Q22: {=SUMPRODUCT(($G$2:$G$2765=G22)*(P22>$P$2:$P$2765))+1} -> 1 | R22: =(Q22*100000)+#REF! -> #REF! | S22: {=SUMPRODUCT(($G$2:$G$2765=G22)*(R22>$R$2:$R$2765))+1} -> #REF! | T22: =_xlfn.CONCAT(IF(M22="Flat",UPPER(I22),I22)," ",IF(J22="Evening","†",IF(J22="Floodlit","#",""))) -> Bangor-On-Dee | U22: 0 | V22: Midlands | W22: =YEAR(G22) -> 2023
A23: =IF(YEAR(G23)=2024,#REF!,"") | B23: =IF(YEAR(G23)=2025,#REF!,"") | C23: =J23&G23 -> Afternoon44938 | D23: =IF('by region'!$C$2="Any","Any",'Turf only'!V23)&M23&IF('by region'!$I$2="Any","Any",N23)&G23 -> AnyJumpAny44938 | E23: =IF(I23=#REF!,'Turf only'!G23,"") -> #REF! | F23: =G23&S23 -> #REF! | G23: 44938 | H23: Thursday | I23: Catterick Bridge | J23: Afternoon | K23: Independent | L23: North | M23: Jump | N23: Turf | O23: Racecourse/Normal | P23: =IF(J23="Afternoon",1,IF(J23="Evening",2,IF(J23="Floodlit",3,4))) -> 1 | Q23: {=SUMPRODUCT(($G$2:$G$2765=G23)*(P23>$P$2:$P$2765))+1} -> 1 | R23: =(Q23*100000)+#REF! -> #REF! | S23: {=SUMPRODUCT(($G$2:$G$2765=G23)*(R23>$R$2:$R$2765))+1} -> #REF! | T23: =_xlfn.CONCAT(IF(M23="Flat",UPPER(I23),I23)," ",IF(J23="Evening","†",IF(J23="Floodlit","#",""))) -> Catterick Bridge | U23: 0 | V23: South | W23: =YEAR(G23) -> 2023
A24: =IF(YEAR(G24)=2024,#REF!,"") | B24: =IF(YEAR(G24)=2025,#REF!,"") | C24: =J24&G24 -> Afternoon44939 | D24: =IF('by region'!$C$2="Any","Any",'Turf only'!V24)&M24&IF('by region'!$I$2="Any","Any",N24)&G24 -> AnyJumpAny44939 | E24: =IF(I24=#REF!,'Turf only'!G24,"") -> #REF! | F24: =G24&S24 -> #REF! | G24: 44939 | H24: Friday | I24: Huntingdon | J24: Afternoon | K24: JCR | L24: Midlands | M24: Jump | N24: Turf | O24: Racecourse/Normal | P24: =IF(J24="Afternoon",1,IF(J24="Evening",2,IF(J24="Floodlit",3,4))) -> 1 | Q24: {=SUMPRODUCT(($G$2:$G$2765=G24)*(P24>$P$2:$P$2765))+1} -> 1 | R24: =(Q24*100000)+#REF! -> #REF! | S24: {=SUMPRODUCT(($G$2:$G$2765=G24)*(R24>$R$2:$R$2765))+1} -> #REF! | T24: =_xlfn.CONCAT(IF(M24="Flat",UPPER(I24),I24)," ",IF(J24="Evening","†",IF(J24="Floodlit","#",""))) -> Huntingdon | U24: 0 | V24: North | W24: =YEAR(G24) -> 2023
A25: =IF(YEAR(G25)=2024,#REF!,"") | B25: =IF(YEAR(G25)=2025,#REF!,"") | C25: =J25&G25 -> Afternoon44939 | D25: =IF('by region'!$C$2="Any","Any",'Turf only'!V25)&M25&IF('by region'!$I$2="Any","Any",N25)&G25 -> AnyJumpAny44939 | E25: =IF(I25=#REF!,'Turf only'!G25,"") -> #REF! | F25: =G25&S25 -> #REF! | G25: 44939 | H25: Friday | I25: Sedgefield | J25: Afternoon | K25: ARC | L25: North | M25: Jump | N25: Turf | O25: National/BHA | P25: =IF(J25="Afternoon",1,IF(J25="Evening",2,IF(J25="Floodlit",3,4))) -> 1 | Q25: {=SUMPRODUCT(($G$2:$G$2765=G25)*(P25>$P$2:$P$2765))+1} -> 1 | R25: =(Q25*100000)+#REF! -> #REF! | S25: {=SUMPRODUCT(($G$2:$G$2765=G25)*(R25>$R$2:$R$2765))+1} -> #REF! | T25: =_xlfn.CONCAT(IF(M25="Flat",UPPER(I25),I25)," ",IF(J25="Evening","†",IF(J25="Floodlit","#",""))) -> Sedgefield | U25: 0 | V25: Midlands | W25: =YEAR(G25) -> 2023
A26: =IF(YEAR(G26)=2024,#REF!,"") | B26: =IF(YEAR(G26)=2025,#REF!,"") | C26: =J26&G26 -> Afternoon44940 | D26: =IF('by region'!$C$2="Any","Any",'Turf only'!V26)&M26&IF('by region'!$I$2="Any","Any",N26)&G26 -> AnyJumpAny44940 | E26: =IF(I26=#REF!,'Turf only'!G26,"") -> #REF! | F26: =G26&S26 -> #REF! | G26: 44940 | H26: Saturday | I26: Kempton Park | J26: Afternoon | K26: JCR | L26: South | M26: Jump | N26: Turf | O26: Racecourse/Normal | P26: =IF(J26="Afternoon",1,IF(J26="Evening",2,IF(J26="Floodlit",3,4))) -> 1 | Q26: {=SUMPRODUCT(($G$2:$G$2765=G26)*(P26>$P$2:$P$2765))+1} -> 1 | R26: =(Q26*100000)+#REF! -> #REF! | S26: {=SUMPRODUCT(($G$2:$G$2765=G26)*(R26>$R$2:$R$2765))+1} -> #REF! | T26: =_xlfn.CONCAT(IF(M26="Flat",UPPER(I26),I26)," ",IF(J26="Evening","†",IF(J26="Floodlit","#",""))) -> Kempton Park | U26: 0 | V26: NULL | W26: =YEAR(G26) -> 2023
A27: =IF(YEAR(G27)=2024,#REF!,"") | B27: =IF(YEAR(G27)=2025,#REF!,"") | C27: =J27&G27 -> Afternoon44940 | D27: =IF('by region'!$C$2="Any","Any",'Turf only'!V27)&M27&IF('by region'!$I$2="Any","Any",N27)&G27 -> AnyJumpAny44940 | E27: =IF(I27=#REF!,'Turf only'!G27,"") -> #REF! | F27: =G27&S27 -> #REF! | G27: 44940 | H27: Saturday | I27: Warwick | J27: Afternoon | K27: JCR | L27: Midlands | M27: Jump | N27: Turf | O27: Racecourse/Normal | P27: =IF(J27="Afternoon",1,IF(J27="Evening",2,IF(J27="Floodlit",3,4))) -> 1 | Q27: {=SUMPRODUCT(($G$2:$G$2765=G27)*(P27>$P$2:$P$2765))+1} -> 1 | R27: =(Q27*100000)+#REF! -> #REF! | S27: {=SUMPRODUCT(($G$2:$G$2765=G27)*(R27>$R$2:$R$2765))+1} -> #REF! | T27: =_xlfn.CONCAT(IF(M27="Flat",UPPER(I27),I27)," ",IF(J27="Evening","†",IF(J27="Floodlit","#",""))) -> Warwick | U27: 0 | V27: North | W27: =YEAR(G27) -> 2023
A28: =IF(YEAR(G28)=2024,#REF!,"") | B28: =IF(YEAR(G28)=2025,#REF!,"") | C28: =J28&G28 -> Afternoon44940 | D28: =IF('by region'!$C$2="Any","Any",'Turf only'!V28)&M28&IF('by region'!$I$2="Any","Any",N28)&G28 -> AnyJumpAny44940 | E28: =IF(I28=#REF!,'Turf only'!G28,"") -> #REF! | F28: =G28&S28 -> #REF! | G28: 44940 | H28: Saturday | I28: Wetherby | J28: Afternoon | K28: Independent | L28: North | M28: Jump | N28: Turf | O28: Racecourse/Normal | P28: =IF(J28="Afternoon",1,IF(J28="Evening",2,IF(J28="Floodlit",3,4))) -> 1 | Q28: {=SUMPRODUCT(($G$2:$G$2765=G28)*(P28>$P$2:$P$2765))+1} -> 1 | R28: =(Q28*100000)+#REF! -> #REF! | S28: {=SUMPRODUCT(($G$2:$G$2765=G28)*(R28>$R$2:$R$2765))+1} -> #REF! | T28: =_xlfn.CONCAT(IF(M28="Flat",UPPER(I28),I28)," ",IF(J28="Evening","†",IF(J28="Floodlit","#",""))) -> Wetherby | U28: 0 | V28: Midlands | W28: =YEAR(G28) -> 2023
A29: =IF(YEAR(G29)=2024,#REF!,"") | B29: =IF(YEAR(G29)=2025,#REF!,"") | C29: =J29&G29 -> Afternoon44941 | D29: =IF('by region'!$C$2="Any","Any",'Turf only'!V29)&M29&IF('by region'!$I$2="Any","Any",N29)&G29 -> AnyJumpAny44941 | E29: =IF(I29=#REF!,'Turf only'!G29,"") -> #REF! | F29: =G29&S29 -> #REF! | G29: 44941 | H29: Sunday | I29: Kelso | J29: Afternoon | K29: Independent | L29: North | M29: Jump | N29: Turf | O29: Racecourse/Normal | P29: =IF(J29="Afternoon",1,IF(J29="Evening",2,IF(J29="Floodlit",3,4))) -> 1 | Q29: {=SUMPRODUCT(($G$2:$G$2765=G29)*(P29>$P$2:$P$2765))+1} -> 1 | R29: =(Q29*100000)+#REF! -> #REF! | S29: {=SUMPRODUCT(($G$2:$G$2765=G29)*(R29>$R$2:$R$2765))+1} -> #REF! | T29: =_xlfn.CONCAT(IF(M29="Flat",UPPER(I29),I29)," ",IF(J29="Evening","†",IF(J29="Floodlit","#",""))) -> Kelso | U29: 0 | V29: Midlands | W29: =YEAR(G29) -> 2023
A30: =IF(YEAR(G30)=2024,#REF!,"") | B30: =IF(YEAR(G30)=2025,#REF!,"") | C30: =J30&G30 -> Afternoon44942 | D30: =IF('by region'!$C$2="Any","Any",'Turf only'!V30)&M30&IF('by region'!$I$2="Any","Any",N30)&G30 -> AnyJumpAny44942 | E30: =IF(I30=#REF!,'Turf only'!G30,"") -> #REF! | F30: =G30&S30 -> #REF! | G30: 44942 | H30: Monday | I30: Fontwell Park | J30: Afternoon | K30: ARC | L30: South | M30: Jump | N30: Turf | O30: Racecourse/Normal | P30: =IF(J30="Afternoon",1,IF(J30="Evening",2,IF(J30="Floodlit",3,4))) -> 1 | Q30: {=SUMPRODUCT(($G$2:$G$2765=G30)*(P30>$P$2:$P$2765))+1} -> 1 | R30: =(Q30*100000)+#REF! -> #REF! | S30: {=SUMPRODUCT(($G$2:$G$2765=G30)*(R30>$R$2:$R$2765))+1} -> #REF! | T30: =_xlfn.CONCAT(IF(M30="Flat",UPPER(I30),I30)," ",IF(J30="Evening","†",IF(J30="Floodlit","#",""))) -> Fontwell Park | U30: 0 | V30: North | W30: =YEAR(G30) -> 2023
A31: =IF(YEAR(G31)=2024,#REF!,"") | B31: =IF(YEAR(G31)=2025,#REF!,"") | C31: =J31&G31 -> Afternoon44942 | D31: =IF('by region'!$C$2="Any","Any",'Turf only'!V31)&M31&IF('by region'!$I$2="Any","Any",N31)&G31 -> AnyJumpAny44942 | E31: =IF(I31=#REF!,'Turf only'!G31,"") -> #REF! | F31: =G31&S31 -> #REF! | G31: 44942 | H31: Monday | I31: Hereford | J31: Afternoon | K31: ARC | L31: Midlands | M31: Jump | N31: Turf | O31: Racecourse/Normal | P31: =IF(J31="Afternoon",1,IF(J31="Evening",2,IF(J31="Floodlit",3,4))) -> 1 | Q31: {=SUMPRODUCT(($G$2:$G$2765=G31)*(P31>$P$2:$P$2765))+1} -> 1 | R31: =(Q31*100000)+#REF! -> #REF! | S31: {=SUMPRODUCT(($G$2:$G$2765=G31)*(R31>$R$2:$R$2765))+1} -> #REF! | T31: =_xlfn.CONCAT(IF(M31="Flat",UPPER(I31),I31)," ",IF(J31="Evening","†",IF(J31="Floodlit","#",""))) -> Hereford | U31: 0 | V31: NULL | W31: =YEAR(G31) -> 2023
A32: =IF(YEAR(G32)=2024,#REF!,"") | B32: =IF(YEAR(G32)=2025,#REF!,"") | C32: =J32&G32 -> Afternoon44943 | D32: =IF('by region'!$C$2="Any","Any",'Turf only'!V32)&M32&IF('by region'!$I$2="Any","Any",N32)&G32 -> AnyJumpAny44943 | E32: =IF(I32=#REF!,'Turf only'!G32,"") -> #REF! | F32: =G32&S32 -> #REF! | G32: 44943 | H32: Tuesday | I32: Chepstow | J32: Afternoon | K32: ARC | L32: South | M32: Jump | N32: Turf | O32: National/BHA | P32: =IF(J32="Afternoon",1,IF(J32="Evening",2,IF(J32="Floodlit",3,4))) -> 1 | Q32: {=SUMPRODUCT(($G$2:$G$2765=G32)*(P32>$P$2:$P$2765))+1} -> 1 | R32: =(Q32*100000)+#REF! -> #REF! | S32: {=SUMPRODUCT(($G$2:$G$2765=G32)*(R32>$R$2:$R$2765))+1} -> #REF! | T32: =_xlfn.CONCAT(IF(M32="Flat",UPPER(I32),I32)," ",IF(J32="Evening","†",IF(J32="Floodlit","#",""))) -> Chepstow | U32: 0 | V32: South | W32: =YEAR(G32) -> 2023
... A641: =IF(YEAR(G641)=2024,#REF!,"") | B641: =IF(YEAR(G641)=2025,#REF!,"") | C641: =J641&G641 -> Afternoon45129 | D641: =IF('by region'!$C$2="Any","Any",'Turf only'!V641)&M641&IF('by region'!$I$2="Any","Any",N641)&G641 -> AnyJumpAny45129 | E641: =IF(I641=#REF!,'Turf only'!G641,"") -> #REF! | F641: =G641&S641 -> #REF! | G641: 45129 | H641: Saturday | I641: Market Rasen | J641: Afternoon | K641: JCR | L641: Midlands | M641: Jump | N641: Turf | O641: Racecourse/Normal | P641: =IF(J641="Afternoon",1,IF(J641="Evening",2,IF(J641="Floodlit",3,4))) -> 1 | Q641: {=SUMPRODUCT(($G$2:$G$2765=G641)*(P641>$P$2:$P$2765))+1} -> 1 | R641: =(Q641*100000)+#REF! -> #REF! | S641: {=SUMPRODUCT(($G$2:$G$2765=G641)*(R641>$R$2:$R$2765))+1} -> #REF! | T641: =_xlfn.CONCAT(IF(M641="Flat",UPPER(I641),I641)," ",IF(J641="Evening","†",IF(J641="Floodlit","#",""))) -> Market Rasen | U641: 0 | V641: South | W641: =YEAR(G641) -> 2023
A642: =IF(YEAR(G642)=2024,#REF!,"") | B642: =IF(YEAR(G642)=2025,#REF!,"") | C642: =J642&G642 -> Afternoon45129 | D642: =IF('by region'!$C$2="Any","Any",'Turf only'!V642)&M642&IF('by region'!$I$2="Any","Any",N642)&G642 -> AnyFlatAny45129 | E642: =IF(I642=#REF!,'Turf only'!G642,"") -> #REF! | F642: =G642&S642 -> 451292 | G642: 45129 | H642: Saturday | I642: Newbury | J642: Afternoon | K642: Independent | L642: South | M642: Flat | N642: Turf | O642: Racecourse/Normal | P642: =IF(J642="Afternoon",1,IF(J642="Evening",2,IF(J642="Floodlit",3,4))) -> 1 | Q642: {=SUMPRODUCT(($G$2:$G$2765=G642)*(P642>$P$2:$P$2765))+1} -> 1 | R642: =(Q642*100000)+#REF! -> #REF! | S642: 2 | T642: =_xlfn.CONCAT(IF(M642="Flat",UPPER(I642),I642)," ",IF(J642="Evening","†",IF(J642="Floodlit","#",""))) -> NEWBURY | U642: 0 | V642: NULL | W642: =YEAR(G642) -> 2023
A643: =IF(YEAR(G643)=2024,#REF!,"") | B643: =IF(YEAR(G643)=2025,#REF!,"") | C643: =J643&G643 -> Afternoon45129 | D643: =IF('by region'!$C$2="Any","Any",'Turf only'!V643)&M643&IF('by region'!$I$2="Any","Any",N643)&G643 -> AnyFlatAny45129 | E643: =IF(I643=#REF!,'Turf only'!G643,"") -> #REF! | F643: =G643&S643 -> #REF! | G643: 45129 | H643: Saturday | I643: Newmarket | J643: Afternoon | K643: JCR | L643: Midlands | M643: Flat | N643: Turf | O643: Racecourse/Normal | P643: =IF(J643="Afternoon",1,IF(J643="Evening",2,IF(J643="Floodlit",3,4))) -> 1 | Q643: {=SUMPRODUCT(($G$2:$G$2765=G643)*(P643>$P$2:$P$2765))+1} -> 1 | R643: =(Q643*100000)+#REF! -> #REF! | S643: {=SUMPRODUCT(($G$2:$G$2765=G643)*(R643>$R$2:$R$2765))+1} -> #REF! | T643: =_xlfn.CONCAT(IF(M643="Flat",UPPER(I643),I643)," ",IF(J643="Evening","†",IF(J643="Floodlit","#",""))) -> NEWMARKET | U643: 0 | V643: North | W643: =YEAR(G643) -> 2023
A644: =IF(YEAR(G644)=2024,#REF!,"") | B644: =IF(YEAR(G644)=2025,#REF!,"") | C644: =J644&G644 -> Afternoon45129 | D644: =IF('by region'!$C$2="Any","Any",'Turf only'!V644)&M644&IF('by region'!$I$2="Any","Any",N644)&G644 -> AnyFlatAny45129 | E644: =IF(I644=#REF!,'Turf only'!G644,"") -> #REF! | F644: =G644&S644 -> #REF! | G644: 45129 | H644: Saturday | I644: Ripon | J644: Afternoon | K644: Independent | L644: North | M644: Flat | N644: Turf | O644: Racecourse/Normal | P644: =IF(J644="Afternoon",1,IF(J644="Evening",2,IF(J644="Floodlit",3,4))) -> 1 | Q644: {=SUMPRODUCT(($G$2:$G$2765=G644)*(P644>$P$2:$P$2765))+1} -> 1 | R644: =(Q644*100000)+#REF! -> #REF! | S644: {=SUMPRODUCT(($G$2:$G$2765=G644)*(R644>$R$2:$R$2765))+1} -> #REF! | T644: =_xlfn.CONCAT(IF(M644="Flat",UPPER(I644),I644)," ",IF(J644="Evening","†",IF(J644="Floodlit","#",""))) -> RIPON | U644: 0 | V644: Midlands | W644: =YEAR(G644) -> 2023
